Workbook

Sheet Bootstrap
A2: 45657 | B2: Instrument | C2: Par Rate / Price | D2: Maturity | E2: Annuity | F2: Discount Factor | H2: Zero Rate | J2: First futures accrual start date: | K2: 45644
D3: 45657 | E3: 0 | F3: 1 | M3: 1
B4: Cash rate 31-dec-2024 01-jan-2025 | C4: 0.0449 | D4: =D3+1 -> 45658 | E4: =E3 -> 0 | F4: =1/(1+C4*(D4-D3)/360) -> 0.99987529 | H4: =-LN(F4)/(($D4-$D$3)/365) -> 0.045520772 | J4: Actual Prior SOFR fixings | M4: =H4+0.0001 -> 0.045620772 | N4: =EXP(-M4*(D4-$D$3)/365) -> 0.99987502
B5: Overnight Futures for SRAZ4 | C5: 95.6575 | D5: 45735 | E5: =E4 -> 0 | F5: {=F4/(1+(((((1+(100-C5)/100*(D5-K2)/360)*F4)/(PRODUCT(1+K5:K17/360)))^(1/(D5-D4))-1)*360)*(D5-D4)/360)} -> 0.99075517 | H5: =-LN(F5)/(($D5-$D$3)/365) -> 0.043462263 | J5: 45656 | K5: 0.0437 | M5: =H5+0.0001 -> 0.043562263 | N5: =EXP(-M5*(D5-$D$3)/365) -> 0.990734
B6: Overnight Futures for SRAH5 | C6: 95.825 | D6: 45826 | E6: =E5 -> 0 | F6: =F5/(1+(100-C6)/100*(D6-D5)/360) -> 0.98040846 | H6: =-LN(F6)/(($D6-$D$3)/365) -> 0.042733075 | J6: =J5-1 -> 45655 | K6: 0.0446 | M6: =H6+0.0001 -> 0.042833075 | N6: =EXP(-M6*(D6-$D$3)/365) -> 0.98036307
B7: Overnight Futures for SRAM5 | C7: 95.955 | D7: 45917 | E7: =E6 -> 0 | F7: =F6/(1+(100-C7)/100*(D7-D6)/360) -> 0.97048538 | H7: =-LN(F7)/(($D7-$D$3)/365) -> 0.042057742 | J7: =J6-1 -> 45654 | K7: 0.0446 | M7: =H7+0.0001 -> 0.042157742 | N7: =EXP(-M7*(D7-$D$3)/365) -> 0.97041625
B8: Overnight Futures for SRAU5 | C8: 96.02 | D8: 46008 | E8: =E7 -> 0 | F8: =F7/(1+(100-C8)/100*(D8-D7)/360) -> 0.96081901 | H8: =-LN(F8)/(($D8-$D$3)/365) -> 0.041563439 | J8: =J7-1 -> 45653 | K8: 0.0446 | M8: =H8+0.0001 -> 0.041663439 | N8: =EXP(-M8*(D8-$D$3)/365) -> 0.96072662
B9: Swap rate 31-dec-2024 31-dec-2025 | C9: 0.04175995 | D9: =EDATE(D3,12) -> 46022 | E9: =E8 -> 0 | F9: =(1-C9*E9)/(1+C9*(D9-D3)/360) -> 0.9593799 | H9: =-LN(F9)/(($D9-$D$3)/365) -> 0.041468137 | J9: =J8-1 -> 45652 | K9: 0.0453 | M9: =H9+0.0001 -> 0.041568137 | N9: =EXP(-M9*(D9-$D$3)/365) -> 0.95928397
B10: Swap rate 31-dec-2024 31-dec-2026 | C10: 0.040844 | D10: =EDATE(D9,12) -> 46387 | E10: =E9+(D9-D3)/360*F9 -> 0.97270462 | F10: =(1-C10*E10)/(1+C10*(D10-D9)/360) -> 0.92208609 | H10: =-LN(F10)/(($D10-$D$3)/365) -> 0.040558344 | J10: =J9-1 -> 45651 | K10: 0.044 | M10: =H10+0.0001 -> 0.040658344 | N10: =EXP(-M10*(D10-$D$3)/365) -> 0.92190169
B11: Swap rate 31-dec-2024 31-dec-2027 | C11: 0.0406323 | D11: =EDATE(D10,12) -> 46752 | E11: =E10+(D10-D9)/360*F10 -> 1.9075975 | F11: =(1-C11*E11)/(1+C11*(D11-D10)/360) -> 0.88599011 | H11: =-LN(F11)/(($D11-$D$3)/365) -> 0.040349829 | J11: =J10-1 -> 45650 | K11: 0.044 | M11: =H11+0.0001 -> 0.040449829 | N11: =EXP(-M11*(D11-$D$3)/365) -> 0.88572436
B12: Swap rate 31-dec-2024 31-dec-2020 | C12: 0.04043345 | D12: =EDATE(D11,12) -> 47118 | E12: =E11+(D11-D10)/360*F11 -> 2.805893 | F12: =(1-C12*E12)/(1+C12*(D12-D11)/360) -> 0.85154338 | H12: =-LN(F12)/(($D12-$D$3)/365) -> 0.040148709 | J12: =J11-1 -> 45649 | K12: 0.0431 | M12: =H12+0.0001 -> 0.040248709 | N12: =EXP(-M12*(D12-$D$3)/365) -> 0.8512026
B13: Swap rate 31-dec-2024 31-dec-2031 | C13: 0.0403845 | D13: =EDATE(D12,12) -> 47483 | E13: =E12+(D12-D11)/360*F12 -> 3.6716288 | F13: =(1-C13*E13)/(1+C13*(D13-D12)/360) -> 0.81822074 | H13: =-LN(F13)/(($D13-$D$3)/365) -> 0.040102652 | J13: =J12-1 -> 45648 | K13: 0.043 | M13: =H13+0.0001 -> 0.040202652 | N13: =EXP(-M13*(D13-$D$3)/365) -> 0.8178115
B14: Swap rate 31-dec-2024 31-dec-2032 | C14: 0.0404111 | D14: =EDATE(D13,12) -> 47848 | E14: =E13+(D13-D12)/360*F13 -> 4.5012137 | F14: =(1-C14*E14)/(1+C14*(D14-D13)/360) -> 0.78590079 | H14: =-LN(F14)/(($D14-$D$3)/365) -> 0.040135793 | J14: =J13-1 -> 45647 | K14: 0.043 | M14: =H14+0.0001 -> 0.040235793 | N14: =EXP(-M14*(D14-$D$3)/365) -> 0.78542918
B15: Swap rate 31-dec-2024 31-dec-2033 | C15: 0.04047965 | D15: =EDATE(D14,12) -> 48213 | E15: =E14+(D14-D13)/360*F14 -> 5.2980298 | F15: =(1-C15*E15)/(1+C15*(D15-D14)/360) -> 0.7545687 | H15: =-LN(F15)/(($D15-$D$3)/365) -> 0.040214111 | J15: =J14-1 -> 45646 | K15: 0.043 | M15: =H15+0.0001 -> 0.040314111 | N15: =EXP(-M15*(D15-$D$3)/365) -> 0.75404048
B16: Swap rate 31-dec-2024 31-dec-2034 | C16: 0.04054495 | D16: =EDATE(D15,12) -> 48579 | E16: =E15+(D15-D14)/360*F15 -> 6.0630786 | F16: =(1-C16*E16)/(1+C16*(D16-D15)/360) -> 0.72431597 | H16: =-LN(F16)/(($D16-$D$3)/365) -> 0.04028835 | J16: =J15-1 -> 45645 | K16: 0.043 | M16: =H16+0.0001 -> 0.04038835 | N16: =EXP(-M16*(D16-$D$3)/365) -> 0.72373635
B17: Swap rate 31-dec-2024 31-dec-2035 | C17: 0.04061975 | D17: =EDATE(D16,12) -> 48944 | E17: =E16+(D16-D15)/360*F16 -> 6.7994665 | F17: =(1-C17*E17)/(1+C17*(D17-D16)/360) -> 0.69517725 | H17: =-LN(F17)/(($D17-$D$3)/365) -> 0.040374133 | J17: =J16-1 -> 45644 | K17: 0.0457 | M17: =H17+0.0001 -> 0.040474133 | N17: =EXP(-M17*(D17-$D$3)/365) -> 0.69455149
B18: Swap rate 31-dec-2024 31-dec-2036 | C18: 0.0407189 | D18: =EDATE(D17,12) -> 49309 | E18: =E17+(D17-D16)/360*F17 -> 7.504299 | F18: =(1-C18*E18)/(1+C18*(D18-D17)/360) -> 0.66690058 | H18: =-LN(F18)/(($D18-$D$3)/365) -> 0.040489244 | M18: =H18+0.0001 -> 0.040589244 | N18: =EXP(-M18*(D18-$D$3)/365) -> 0.66623365
B19: Interpolated Par Rate | C19: =($C$23-$C$18)/5+C18 -> 0.04081352 | D19: =EDATE(D18,12) -> 49674 | E19: =E18+(D18-D17)/360*F18 -> 8.1804621 | F19: =(1-C19*E19)/(1+C19*(D19-D18)/360) -> 0.63965729 | H19: =-LN(F19)/(($D19-$D$3)/365) -> 0.040600024 | M19: =H19+0.0001 -> 0.040700024 | N19: =EXP(-M19*(D19-$D$3)/365) -> 0.6389537
B20: Interpolated Par Rate | C20: =($C$23-$C$18)/5+C19 -> 0.04090814 | D20: =EDATE(D19,12) -> 50040 | E20: =E19+(D19-D18)/360*F19 -> 8.8290035 | F20: =(1-C20*E20)/(1+C20*(D20-D19)/360) -> 0.61331419 | H20: =-LN(F20)/(($D20-$D$3)/365) -> 0.040711943 | M20: =H20+0.0001 -> 0.040811943 | N20: =EXP(-M20*(D20-$D$3)/365) -> 0.61257815
B21: Interpolated Par Rate | C21: =($C$23-$C$18)/5+C20 -> 0.04100276 | D21: =EDATE(D20,12) -> 50405 | E21: =E20+(D20-D19)/360*F20 -> 9.4525396 | F21: =(1-C21*E21)/(1+C21*(D21-D20)/360) -> 0.5879763 | H21: =-LN(F21)/(($D21-$D$3)/365) -> 0.040825623 | M21: =H21+0.0001 -> 0.040925623 | N21: =EXP(-M21*(D21-$D$3)/365) -> 0.58721194
B22: Interpolated Par Rate | C22: =($C$23-$C$18)/5+C21 -> 0.04109738 | D22: =EDATE(D21,12) -> 50770 | E22: =E21+(D21-D20)/360*F21 -> 10.048682 | F22: =(1-C22*E22)/(1+C22*(D22-D21)/360) -> 0.56354365 | H22: =-LN(F22)/(($D22-$D$3)/365) -> 0.040940999 | M22: =H22+0.0001 -> 0.041040999 | N22: =EXP(-M22*(D22-$D$3)/365) -> 0.56275478
B23: Swap rate 31-dec-2024 31-dec-2039 | C23: 0.041192 | D23: =EDATE(D22,12) -> 51135 | E23: =E22+(D22-D21)/360*F22 -> 10.620053 | F23: =(1-C23*E23)/(1+C23*(D23-D22)/360) -> 0.53998672 | H23: =-LN(F23)/(($D23-$D$3)/365) -> 0.041058218 | M23: =H23+0.0001 -> 0.041158218 | N23: =EXP(-M23*(D23-$D$3)/365) -> 0.5391769
B24: Interpolated Par Rate | C24: =($C$28-$C$23)/5+C23 -> 0.0411581 | D24: =EDATE(D23,12) -> 51501 | E24: =E23+(D23-D22)/360*F23 -> 11.167539 | F24: =(1-C24*E24)/(1+C24*(D24-D23)/360) -> 0.51866235 | H24: =-LN(F24)/(($D24-$D$3)/365) -> 0.041003302 | M24: =H24+0.0001 -> 0.041103302 | N24: =EXP(-M24*(D24-$D$3)/365) -> 0.51783259
B25: Interpolated Par Rate | C25: =($C$28-$C$23)/5+C24 -> 0.0411242 | D25: =EDATE(D24,12) -> 51866 | E25: =E24+(D24-D23)/360*F24 -> 11.694846 | F25: =(1-C25*E25)/(1+C25*(D25-D24)/360) -> 0.49828273 | H25: =-LN(F25)/(($D25-$D$3)/365) -> 0.040949346 | M25: =H25+0.0001 -> 0.041049346 | N25: =EXP(-M25*(D25-$D$3)/365) -> 0.49743582
B26: Interpolated Par Rate | C26: =($C$28-$C$23)/5+C25 -> 0.0410903 | D26: =EDATE(D25,12) -> 52231 | E26: =E25+(D25-D24)/360*F25 -> 12.200049 | F26: =(1-C26*E26)/(1+C26*(D26-D25)/360) -> 0.47875106 | H26: =-LN(F26)/(($D26-$D$3)/365) -> 0.040895908 | M26: =H26+0.0001 -> 0.040995908 | N26: =EXP(-M26*(D26-$D$3)/365) -> 0.47788956
B27: Interpolated Par Rate | C27: =($C$28-$C$23)/5+C26 -> 0.0410564 | D27: =EDATE(D26,12) -> 52596 | E27: =E26+(D26-D25)/360*F26 -> 12.68545 | F27: =(1-C27*E27)/(1+C27*(D27-D26)/360) -> 0.46003154 | H27: =-LN(F27)/(($D27-$D$3)/365) -> 0.040842771 | M27: =H27+0.0001 -> 0.040942771 | N27: =EXP(-M27*(D27-$D$3)/365) -> 0.4591578
B28: Swap rate 31-dec-2024 31-dec-2044 | C28: 0.0410225 | D28: =EDATE(D27,12) -> 52962 | E28: =E27+(D27-D26)/360*F27 -> 13.151871 | F28: =(1-C28*E28)/(1+C28*(D28-D27)/360) -> 0.44204151 | H28: =-LN(F28)/(($D28-$D$3)/365) -> 0.040789636 | M28: =H28+0.0001 -> 0.040889636 | N28: =EXP(-M28*(D28-$D$3)/365) -> 0.44115771

Sheet Swap Cashflows
B2: USD SOFR Swap
C3: Fixed | D3: Floating
B4: Pay/Receive | C4: Pay | D4: Receive | H4: Present Value | I4: =I57+I33 -> -540990.89
B5: Notional | C5: 10000000 | D5: 10000000
B6: Rate | C6: 0.045 | D6: USD-SOFR-ON
B7: Accrual Convention | C7: Actual/360 | D7: Actual/360
B8: Payment Frequency | C8: Annual | D8: Annual
B9: Reset Frequency | C9: Annual | D9: Daily (Compounded)
B11: Fixed
B12: Effective Date | C12: Maturity Date | D12: Rate | E12: Accrual Fraction | F12: Notional | G12: Cashflow | H12: Discount Factor | I12: Present Value
B13: 45657 | C13: =EDATE(B13,12) -> 46022 | D13: =$C$6 -> 0.045 | E13: =_xlfn.DAYS(C13,B13)/360 -> 1.0138889 | F13: =$C$5 -> 10000000 | G13: =-D13*E13*F13 -> -456250 | H13: =Bootstrap!F9 -> 0.9593799 | I13: =G13*H13 -> -437717.08
B14: =C13 -> 46022 | C14: =EDATE(B14,12) -> 46387 | D14: =$C$6 -> 0.045 | E14: =_xlfn.DAYS(C14,B14)/360 -> 1.0138889 | F14: =$C$5 -> 10000000 | G14: =-D14*E14*F14 -> -456250 | H14: =Bootstrap!F10 -> 0.92208609 | I14: =G14*H14 -> -420701.78
B15: =C14 -> 46387 | C15: =EDATE(B15,12) -> 46752 | D15: =$C$6 -> 0.045 | E15: =_xlfn.DAYS(C15,B15)/360 -> 1.0138889 | F15: =$C$5 -> 10000000 | G15: =-D15*E15*F15 -> -456250 | H15: =Bootstrap!F11 -> 0.88599011 | I15: =G15*H15 -> -404232.99
B16: =C15 -> 46752 | C16: =EDATE(B16,12) -> 47118 | D16: =$C$6 -> 0.045 | E16: =_xlfn.DAYS(C16,B16)/360 -> 1.0166667 | F16: =$C$5 -> 10000000 | G16: =-D16*E16*F16 -> -457500 | H16: =Bootstrap!F12 -> 0.85154338 | I16: =G16*H16 -> -389581.1
B17: =C16 -> 47118 | C17: =EDATE(B17,12) -> 47483 | D17: =$C$6 -> 0.045 | E17: =_xlfn.DAYS(C17,B17)/360 -> 1.0138889 | F17: =$C$5 -> 10000000 | G17: =-D17*E17*F17 -> -456250 | H17: =Bootstrap!F13 -> 0.81822074 | I17: =G17*H17 -> -373313.21
B18: =C17 -> 47483 | C18: =EDATE(B18,12) -> 47848 | D18: =$C$6 -> 0.045 | E18: =_xlfn.DAYS(C18,B18)/360 -> 1.0138889 | F18: =$C$5 -> 10000000 | G18: =-D18*E18*F18 -> -456250 | H18: =Bootstrap!F14 -> 0.78590079 | I18: =G18*H18 -> -358567.24
B19: =C18 -> 47848 | C19: =EDATE(B19,12) -> 48213 | D19: =$C$6 -> 0.045 | E19: =_xlfn.DAYS(C19,B19)/360 -> 1.0138889 | F19: =$C$5 -> 10000000 | G19: =-D19*E19*F19 -> -456250 | H19: =Bootstrap!F15 -> 0.7545687 | I19: =G19*H19 -> -344271.97
B20: =C19 -> 48213 | C20: =EDATE(B20,12) -> 48579 | D20: =$C$6 -> 0.045 | E20: =_xlfn.DAYS(C20,B20)/360 -> 1.0166667 | F20: =$C$5 -> 10000000 | G20: =-D20*E20*F20 -> -457500 | H20: =Bootstrap!F16 -> 0.72431597 | I20: =G20*H20 -> -331374.56
B21: =C20 -> 48579 | C21: =EDATE(B21,12) -> 48944 | D21: =$C$6 -> 0.045 | E21: =_xlfn.DAYS(C21,B21)/360 -> 1.0138889 | F21: =$C$5 -> 10000000 | G21: =-D21*E21*F21 -> -456250 | H21: =Bootstrap!F17 -> 0.69517725 | I21: =G21*H21 -> -317174.62
B22: =C21 -> 48944 | C22: =EDATE(B22,12) -> 49309 | D22: =$C$6 -> 0.045 | E22: =_xlfn.DAYS(C22,B22)/360 -> 1.0138889 | F22: =$C$5 -> 10000000 | G22: =-D22*E22*F22 -> -456250 | H22: =Bootstrap!F18 -> 0.66690058 | I22: =G22*H22 -> -304273.39
B23: =C22 -> 49309 | C23: =EDATE(B23,12) -> 49674 | D23: =$C$6 -> 0.045 | E23: =_xlfn.DAYS(C23,B23)/360 -> 1.0138889 | F23: =$C$5 -> 10000000 | G23: =-D23*E23*F23 -> -456250 | H23: =Bootstrap!F19 -> 0.63965729 | I23: =G23*H23 -> -291843.64
B24: =C23 -> 49674 | C24: =EDATE(B24,12) -> 50040 | D24: =$C$6 -> 0.045 | E24: =_xlfn.DAYS(C24,B24)/360 -> 1.0166667 | F24: =$C$5 -> 10000000 | G24: =-D24*E24*F24 -> -457500 | H24: =Bootstrap!F20 -> 0.61331419 | I24: =G24*H24 -> -280591.24
B25: =C24 -> 50040 | C25: =EDATE(B25,12) -> 50405 | D25: =$C$6 -> 0.045 | E25: =_xlfn.DAYS(C25,B25)/360 -> 1.0138889 | F25: =$C$5 -> 10000000 | G25: =-D25*E25*F25 -> -456250 | H25: =Bootstrap!F21 -> 0.5879763 | I25: =G25*H25 -> -268264.18
... B32: =C31 -> 52596 | C32: =EDATE(B32,12) -> 52962 | D32: =$C$6 -> 0.045 | E32: =_xlfn.DAYS(C32,B32)/360 -> 1.0166667 | F32: =$C$5 -> 10000000 | G32: =-D32*E32*F32 -> -457500 | H32: =Bootstrap!F28 -> 0.44204151 | I32: =G32*H32 -> -202233.99
I33: =SUM(I13:I32) -> -6120575.8
B35: Floating
B36: Effective | C36: Maturity | D36: Rate | E36: Accrual Fraction | F36: Notional | G36: Cashflow | H36: Discount Factor | I36: Present Value
B37: =B13 -> 45657 | C37: =C13 -> 46022 | D37: =(Bootstrap!F3/Bootstrap!F9-1)*360/(C37-B37) -> 0.04175995 | E37: =_xlfn.DAYS(C37,B37)/360 -> 1.0138889 | F37: =$D$5 -> 10000000 | G37: =D37*E37*F37 -> 423399.49 | H37: =Bootstrap!F9 -> 0.9593799 | I37: =G37*H37 -> 406200.96
B38: =B14 -> 46022 | C38: =C14 -> 46387 | D38: =(Bootstrap!F9/Bootstrap!F10-1)*360/(C38-B38) -> 0.039891004 | E38: =_xlfn.DAYS(C38,B38)/360 -> 1.0138889 | F38: =$D$5 -> 10000000 | G38: =D38*E38*F38 -> 404450.46 | H38: =Bootstrap!F10 -> 0.92208609 | I38: =G38*H38 -> 372938.14
B39: =B15 -> 46387 | C39: =C15 -> 46752 | D39: =(Bootstrap!F10/Bootstrap!F11-1)*360/(C39-B39) -> 0.040182739 | E39: =_xlfn.DAYS(C39,B39)/360 -> 1.0138889 | F39: =$D$5 -> 10000000 | G39: =D39*E39*F39 -> 407408.33 | H39: =Bootstrap!F11 -> 0.88599011 | I39: =G39*H39 -> 360959.75
B40: =B16 -> 46752 | C40: =C16 -> 47118 | D40: =(Bootstrap!F11/Bootstrap!F12-1)*360/(C40-B40) -> 0.039788967 | E40: =_xlfn.DAYS(C40,B40)/360 -> 1.0166667 | F40: =$D$5 -> 10000000 | G40: =D40*E40*F40 -> 404521.17 | H40: =Bootstrap!F12 -> 0.85154338 | I40: =G40*H40 -> 344467.32
B41: =B17 -> 47118 | C41: =C17 -> 47483 | D41: =(Bootstrap!F12/Bootstrap!F13-1)*360/(C41-B41) -> 0.040167854 | E41: =_xlfn.DAYS(C41,B41)/360 -> 1.0138889 | F41: =$D$5 -> 10000000 | G41: =D41*E41*F41 -> 407257.41 | H41: =Bootstrap!F13 -> 0.81822074 | I41: =G41*H41 -> 333226.46
B42: =B18 -> 47483 | C42: =C18 -> 47848 | D42: =(Bootstrap!F13/Bootstrap!F14-1)*360/(C42-B42) -> 0.040561363 | E42: =_xlfn.DAYS(C42,B42)/360 -> 1.0138889 | F42: =$D$5 -> 10000000 | G42: =D42*E42*F42 -> 411247.16 | H42: =Bootstrap!F14 -> 0.78590079 | I42: =G42*H42 -> 323199.47
B43: =B19 -> 47848 | C43: =C19 -> 48213 | D43: =(Bootstrap!F14/Bootstrap!F15-1)*360/(C43-B43) -> 0.040954365 | E43: =_xlfn.DAYS(C43,B43)/360 -> 1.0138889 | F43: =$D$5 -> 10000000 | G43: =D43*E43*F43 -> 415231.75 | H43: =Bootstrap!F15 -> 0.7545687 | I43: =G43*H43 -> 313320.88
B44: =B20 -> 48213 | C44: =C20 -> 48579 | D44: =(Bootstrap!F15/Bootstrap!F16-1)*360/(C44-B44) -> 0.0410826 | E44: =_xlfn.DAYS(C44,B44)/360 -> 1.0166667 | F44: =$D$5 -> 10000000 | G44: =D44*E44*F44 -> 417673.1 | H44: =Bootstrap!F16 -> 0.72431597 | I44: =G44*H44 -> 302527.3
B45: =B21 -> 48579 | C45: =C21 -> 48944 | D45: =(Bootstrap!F16/Bootstrap!F17-1)*360/(C45-B45) -> 0.04134134 | E45: =_xlfn.DAYS(C45,B45)/360 -> 1.0138889 | F45: =$D$5 -> 10000000 | G45: =D45*E45*F45 -> 419155.25 | H45: =Bootstrap!F17 -> 0.69517725 | I45: =G45*H45 -> 291387.2
B46: =B22 -> 48944 | C46: =C22 -> 49309 | D46: =(Bootstrap!F17/Bootstrap!F18-1)*360/(C46-B46) -> 0.041819302 | E46: =_xlfn.DAYS(C46,B46)/360 -> 1.0138889 | F46: =$D$5 -> 10000000 | G46: =D46*E46*F46 -> 424001.26 | H46: =Bootstrap!F18 -> 0.66690058 | I46: =G46*H46 -> 282766.69
B47: =B23 -> 49309 | C47: =C23 -> 49674 | D47: =(Bootstrap!F18/Bootstrap!F19-1)*360/(C47-B47) -> 0.042007022 | E47: =_xlfn.DAYS(C47,B47)/360 -> 1.0138889 | F47: =$D$5 -> 10000000 | G47: =D47*E47*F47 -> 425904.53 | H47: =Bootstrap!F19 -> 0.63965729 | I47: =G47*H47 -> 272432.93
B48: =B24 -> 49674 | C48: =C24 -> 50040 | D48: =(Bootstrap!F19/Bootstrap!F20-1)*360/(C48-B48) -> 0.042247919 | E48: =_xlfn.DAYS(C48,B48)/360 -> 1.0166667 | F48: =$D$5 -> 10000000 | G48: =D48*E48*F48 -> 429520.51 | H48: =Bootstrap!F20 -> 0.61331419 | I48: =G48*H48 -> 263431.02
B49: =B25 -> 50040 | C49: =C25 -> 50405 | D49: =(Bootstrap!F20/Bootstrap!F21-1)*360/(C49-B49) -> 0.042503071 | E49: =_xlfn.DAYS(C49,B49)/360 -> 1.0138889 | F49: =$D$5 -> 10000000 | G49: =D49*E49*F49 -> 430933.91 | H49: =Bootstrap!F21 -> 0.5879763 | I49: =G49*H49 -> 253378.93
...

Sheet Risk Ladder
B3: Instrument | C3: Delta
B4: Cash rate 31-dec-2024 01-jan-2025 | C4: 0
B5: Overnight Futures for SRAZ4 | C5: 0
B6: Overnight Futures for SRAH5 | C6: 0
B7: Overnight Futures for SRAM5 | C7: 0
B8: Overnight Futures for SRAU5 | C8: 0
B9: Swap rate 31-dec-2024 31-dec-2025 | C9: 1.7405354
B10: Swap rate 31-dec-2024 31-dec-2026 | C10: 3.5579346
B11: Swap rate 31-dec-2024 31-dec-2027 | C11: 5.4501016
B12: Swap rate 31-dec-2024 31-dec-2020 | C12: 7.44583
B13: Swap rate 31-dec-2024 31-dec-2031 | C13: 9.4774473
B14: Swap rate 31-dec-2024 31-dec-2032 | C14: 11.611921
B15: Swap rate 31-dec-2024 31-dec-2033 | C15: 13.833182
... B20: Swap rate 31-dec-2024 31-dec-2044 | C20: 26.465661

Sheet CDS Bootstrap
B2: Valuation Date: | C2: 45657
C4: Spread | D4: Recovery | F4: Accrual Fraction | G4: Discount Factor | H4: PD_{i-1) | I4: PND_{i-1} | J4: Accumulated Value of the Premium Leg | K4: Accumulated Expected Discounted Loss | L4: Premium Leg Accrual | M4: Marginal PD | N4: PD
E5: =C2 -> 45657 | N5: 0
B6: 6M | C6: 0.00080586 | D6: 0.4 | E6: 45828 | F6: =YEARFRAC($C$2, E6, 2) -> 0.475 | G6: =EXP(LN(_xlfn.XLOOKUP(E6,Bootstrap!$D$4:$D$28,Bootstrap!$F$4:$F$28,,-1))+(E6-_xlfn.XLOOKUP(E6,Bootstrap!$D$4:$D$28,Bootstrap!$D$4:$D$28,,-1))/(_xlfn.XLOOKUP(E6,Bootstrap!$D$4:$D$28,Bootstrap!$D$4:$D$28,,1)-_xlfn.XLOOKUP(E6,Bootstrap!$D$4:$D$28,Bootstrap!$D$4:$D$28,,-1))*(LN(_xlfn.XLOOKUP(E6,Bootstrap!$D$4:$D$28,Bootstrap!$F$4:$F$28,,1))-LN(_xlfn.XLOOKUP(E6,Bootstrap!$D$4:$D$28,Bootstrap!$F$4:$F$28,,-1)))) -> 0.98018928 | H6: 0 | I6: =1-H6 -> 1 | J6: 0 | K6: 0 | L6: 0 | M6: =( C6*(J6 + 0.5*L6 + G6*F6*I6) - (1-$D$6)*K6 ) / ( G6 * ( (1-$D$6) + 0.5*C6*F6 ) ) -> 0.00063776906 | N6: =SUM($M$6:M6) -> 0.00063776906
B7: 1Y | C7: 0.00118372 | D7: 0.4 | E7: 46011 | F7: =YEARFRAC($C$2, E7, 2) -> 0.98333333 | G7: =EXP(LN(_xlfn.XLOOKUP(E7,Bootstrap!$D$4:$D$28,Bootstrap!$F$4:$F$28,,-1))+(E7-_xlfn.XLOOKUP(E7,Bootstrap!$D$4:$D$28,Bootstrap!$D$4:$D$28,,-1))/(_xlfn.XLOOKUP(E7,Bootstrap!$D$4:$D$28,Bootstrap!$D$4:$D$28,,1)-_xlfn.XLOOKUP(E7,Bootstrap!$D$4:$D$28,Bootstrap!$D$4:$D$28,,-1))*(LN(_xlfn.XLOOKUP(E7,Bootstrap!$D$4:$D$28,Bootstrap!$F$4:$F$28,,1))-LN(_xlfn.XLOOKUP(E7,Bootstrap!$D$4:$D$28,Bootstrap!$F$4:$F$28,,-1)))) -> 0.96051045 | H7: =H6+M6 -> 0.00063776906 | I7: =1-H7 -> 0.99936223 | J7: =J6+G6*F6*I6 -> 0.46558991 | K7: =K6+G6*M6 -> 0.0006251344 | L7: =L6+G6*F6*M6 -> 0.00029693884 | M7: =( C7*(J7 + 0.5*L7 + G7*F7*I7) - (1-$D$6)*K7 ) / ( G7 * ( (1-$D$6) + 0.5*C7*F7 ) ) -> 0.0022423537 | N7: =SUM($M$6:M7) -> 0.0028801227
B8: 2Y | C8: 0.00173483 | D8: 0.4 | E8: 46376 | F8: =YEARFRAC($C$2, E8, 2) -> 1.9972222 | G8: =EXP(LN(_xlfn.XLOOKUP(E8,Bootstrap!$D$4:$D$28,Bootstrap!$F$4:$F$28,,-1))+(E8-_xlfn.XLOOKUP(E8,Bootstrap!$D$4:$D$28,Bootstrap!$D$4:$D$28,,-1))/(_xlfn.XLOOKUP(E8,Bootstrap!$D$4:$D$28,Bootstrap!$D$4:$D$28,,1)-_xlfn.XLOOKUP(E8,Bootstrap!$D$4:$D$28,Bootstrap!$D$4:$D$28,,-1))*(LN(_xlfn.XLOOKUP(E8,Bootstrap!$D$4:$D$28,Bootstrap!$F$4:$F$28,,1))-LN(_xlfn.XLOOKUP(E8,Bootstrap!$D$4:$D$28,Bootstrap!$F$4:$F$28,,-1)))) -> 0.92318854 | H8: =H7+M7 -> 0.0028801227 | I8: =1-H8 -> 0.99711988 | J8: =J7+G7*F7*I7 -> 1.4094895 | K8: =K7+G7*M7 -> 0.0027789385 | L8: =L7+G7*F7*M7 -> 0.0024148462 | M8: =( C8*(J8 + 0.5*L8 + G8*F8*I8) - (1-$D$6)*K8 ) / ( G8 * ( (1-$D$6) + 0.5*C8*F8 ) ) -> 0.0071455552 | N8: =SUM($M$6:M8) -> 0.010025678
B9: 3Y | C9: 0.00242107 | D9: 0.4 | E9: 46741 | F9: =YEARFRAC($C$2, E9, 2) -> 3.0111111 | G9: =EXP(LN(_xlfn.XLOOKUP(E9,Bootstrap!$D$4:$D$28,Bootstrap!$F$4:$F$28,,-1))+(E9-_xlfn.XLOOKUP(E9,Bootstrap!$D$4:$D$28,Bootstrap!$D$4:$D$28,,-1))/(_xlfn.XLOOKUP(E9,Bootstrap!$D$4:$D$28,Bootstrap!$D$4:$D$28,,1)-_xlfn.XLOOKUP(E9,Bootstrap!$D$4:$D$28,Bootstrap!$D$4:$D$28,,-1))*(LN(_xlfn.XLOOKUP(E9,Bootstrap!$D$4:$D$28,Bootstrap!$F$4:$F$28,,1))-LN(_xlfn.XLOOKUP(E9,Bootstrap!$D$4:$D$28,Bootstrap!$F$4:$F$28,,-1)))) -> 0.887057 | H9: =H8+M8 -> 0.010025678 | I9: =1-H9 -> 0.98997432 | J9: =J8+G8*F8*I8 -> 3.2479917 | K9: =K8+G8*M8 -> 0.0093756332 | L9: =L8+G8*F8*M8 -> 0.015589911 | M9: =( C9*(J9 + 0.5*L9 + G9*F9*I9) - (1-$D$6)*K9 ) / ( G9 * ( (1-$D$6) + 0.5*C9*F9 ) ) -> 0.016170947 | N9: =SUM($M$6:M9) -> 0.026196625
B10: 4Y | C10: 0.00314214 | D10: 0.4 | E10: 47107 | F10: =YEARFRAC($C$2, E10, 2) -> 4.0277778 | G10: =EXP(LN(_xlfn.XLOOKUP(E10,Bootstrap!$D$4:$D$28,Bootstrap!$F$4:$F$28,,-1))+(E10-_xlfn.XLOOKUP(E10,Bootstrap!$D$4:$D$28,Bootstrap!$D$4:$D$28,,-1))/(_xlfn.XLOOKUP(E10,Bootstrap!$D$4:$D$28,Bootstrap!$D$4:$D$28,,1)-_xlfn.XLOOKUP(E10,Bootstrap!$D$4:$D$28,Bootstrap!$D$4:$D$28,,-1))*(LN(_xlfn.XLOOKUP(E10,Bootstrap!$D$4:$D$28,Bootstrap!$F$4:$F$28,,1))-LN(_xlfn.XLOOKUP(E10,Bootstrap!$D$4:$D$28,Bootstrap!$F$4:$F$28,,-1)))) -> 0.85255888 | H10: =H9+M9 -> 0.026196625 | I10: =1-H10 -> 0.97380337 | J10: =J9+G9*F9*I9 -> 5.8922401 | K10: =K9+G9*M9 -> 0.023720185 | L10: =L9+G9*F9*M9 -> 0.058782951 | M10: =( C10*(J10 + 0.5*L10 + G10*F10*I10) - (1-$D$6)*K10 ) / ( G10 * ( (1-$D$6) + 0.5*C10*F10 ) ) -> 0.028788558 | N10: =SUM($M$6:M10) -> 0.054985184
B11: 5Y | C11: 0.00385649 | D11: 0.4 | E11: 47472 | F11: =YEARFRAC($C$2, E11, 2) -> 5.0416667 | G11: =EXP(LN(_xlfn.XLOOKUP(E11,Bootstrap!$D$4:$D$28,Bootstrap!$F$4:$F$28,,-1))+(E11-_xlfn.XLOOKUP(E11,Bootstrap!$D$4:$D$28,Bootstrap!$D$4:$D$28,,-1))/(_xlfn.XLOOKUP(E11,Bootstrap!$D$4:$D$28,Bootstrap!$D$4:$D$28,,1)-_xlfn.XLOOKUP(E11,Bootstrap!$D$4:$D$28,Bootstrap!$D$4:$D$28,,-1))*(LN(_xlfn.XLOOKUP(E11,Bootstrap!$D$4:$D$28,Bootstrap!$F$4:$F$28,,1))-LN(_xlfn.XLOOKUP(E11,Bootstrap!$D$4:$D$28,Bootstrap!$F$4:$F$28,,-1)))) -> 0.81920566 | H11: =H10+M10 -> 0.054985184 | I11: =1-H11 -> 0.94501482 | J11: =J10+G10*F10*I10 -> 9.2362007 | K11: =K10+G10*M10 -> 0.048264126 | L11: =L10+G10*F10*M10 -> 0.15764049 | M11: =( C11*(J11 + 0.5*L11 + G11*F11*I11) - (1-$D$6)*K11 ) / ( G11 * ( (1-$D$6) + 0.5*C11*F11 ) ) -> 0.044079068 | N11: =SUM($M$6:M11) -> 0.099064252
B12: 7Y | C12: 0.00544672 | D12: 0.4 | E12: 48202 | F12: =YEARFRAC($C$2, E12, 2) -> 7.0694444 | G12: =EXP(LN(_xlfn.XLOOKUP(E12,Bootstrap!$D$4:$D$28,Bootstrap!$F$4:$F$28,,-1))+(E12-_xlfn.XLOOKUP(E12,Bootstrap!$D$4:$D$28,Bootstrap!$D$4:$D$28,,-1))/(_xlfn.XLOOKUP(E12,Bootstrap!$D$4:$D$28,Bootstrap!$D$4:$D$28,,1)-_xlfn.XLOOKUP(E12,Bootstrap!$D$4:$D$28,Bootstrap!$D$4:$D$28,,-1))*(LN(_xlfn.XLOOKUP(E12,Bootstrap!$D$4:$D$28,Bootstrap!$F$4:$F$28,,1))-LN(_xlfn.XLOOKUP(E12,Bootstrap!$D$4:$D$28,Bootstrap!$F$4:$F$28,,-1)))) -> 0.75549445 | H12: =H11+M11 -> 0.099064252 | I12: =1-H12 -> 0.90093575 | J12: =J11+G11*F11*I11 -> 13.139265 | K12: =K11+G11*M11 -> 0.084373948 | L12: =L11+G11*F11*M11 -> 0.33969418 | M12: =( C12*(J12 + 0.5*L12 + G12*F12*I12) - (1-$D$6)*K12 ) / ( G12 * ( (1-$D$6) + 0.5*C12*F12 ) ) -> 0.10275978 | N12: =SUM($M$6:M12) -> 0.20182403
B13: 10Y | C13: 0.00644184 | D13: 0.4 | E13: 49298 | F13: =YEARFRAC($C$2, E13, 2) -> 10.113889 | G13: =EXP(LN(_xlfn.XLOOKUP(E13,Bootstrap!$D$4:$D$28,Bootstrap!$F$4:$F$28,,-1))+(E13-_xlfn.XLOOKUP(E13,Bootstrap!$D$4:$D$28,Bootstrap!$D$4:$D$28,,-1))/(_xlfn.XLOOKUP(E13,Bootstrap!$D$4:$D$28,Bootstrap!$D$4:$D$28,,1)-_xlfn.XLOOKUP(E13,Bootstrap!$D$4:$D$28,Bootstrap!$D$4:$D$28,,-1))*(LN(_xlfn.XLOOKUP(E13,Bootstrap!$D$4:$D$28,Bootstrap!$F$4:$F$28,,1))-LN(_xlfn.XLOOKUP(E13,Bootstrap!$D$4:$D$28,Bootstrap!$F$4:$F$28,,-1)))) -> 0.66773571 | H13: =H12+M12 -> 0.20182403 | I13: =1-H13 -> 0.79817597 | J13: =J12+G12*F12*I12 -> 17.951096 | K13: =K12+G12*M12 -> 0.16200839 | L13: =L12+G12*F12*M12 -> 0.88852657 | M13: =( C13*(J13 + 0.5*L13 + G13*F13*I13) - (1-$D$6)*K13 ) / ( G13 * ( (1-$D$6) + 0.5*C13*F13 ) ) -> 0.13262288 | N13: =SUM($M$6:M13) -> 0.33444691
B14: 15Y | C14: 0.00744015 | D14: 0.4 | E14: 51124 | F14: =YEARFRAC($C$2, E14, 2) -> 15.186111 | G14: =EXP(LN(_xlfn.XLOOKUP(E14,Bootstrap!$D$4:$D$28,Bootstrap!$F$4:$F$28,,-1))+(E14-_xlfn.XLOOKUP(E14,Bootstrap!$D$4:$D$28,Bootstrap!$D$4:$D$28,,-1))/(_xlfn.XLOOKUP(E14,Bootstrap!$D$4:$D$28,Bootstrap!$D$4:$D$28,,1)-_xlfn.XLOOKUP(E14,Bootstrap!$D$4:$D$28,Bootstrap!$D$4:$D$28,,-1))*(LN(_xlfn.XLOOKUP(E14,Bootstrap!$D$4:$D$28,Bootstrap!$F$4:$F$28,,1))-LN(_xlfn.XLOOKUP(E14,Bootstrap!$D$4:$D$28,Bootstrap!$F$4:$F$28,,-1)))) -> 0.54068205 | H14: =H13+M13 -> 0.33444691 | I14: =1-H14 -> 0.66555309 | J14: =J13+G13*F13*I13 -> 23.341501 | K14: =K13+G13*M13 -> 0.25056542 | L14: =L13+G13*F13*M13 -> 1.7841825 | M14: =( C14*(J14 + 0.5*L14 + G14*F14*I14) - (1-$D$6)*K14 ) / ( G14 * ( (1-$D$6) + 0.5*C14*F14 ) ) -> 0.19895792 | N14: =SUM($M$6:M14) -> 0.53340483
B15: 20Y | C15: 0.00766223 | D15: 0.4 | E15: 52951 | F15: =YEARFRAC($C$2, E15, 2) -> 20.261111 | G15: =EXP(LN(_xlfn.XLOOKUP(E15,Bootstrap!$D$4:$D$28,Bootstrap!$F$4:$F$28,,-1))+(E15-_xlfn.XLOOKUP(E15,Bootstrap!$D$4:$D$28,Bootstrap!$D$4:$D$28,,-1))/(_xlfn.XLOOKUP(E15,Bootstrap!$D$4:$D$28,Bootstrap!$D$4:$D$28,,1)-_xlfn.XLOOKUP(E15,Bootstrap!$D$4:$D$28,Bootstrap!$D$4:$D$28,,-1))*(LN(_xlfn.XLOOKUP(E15,Bootstrap!$D$4:$D$28,Bootstrap!$F$4:$F$28,,1))-LN(_xlfn.XLOOKUP(E15,Bootstrap!$D$4:$D$28,Bootstrap!$F$4:$F$28,,-1)))) -> 0.4425718 | H15: =H14+M14 -> 0.53340483 | I15: =1-H15 -> 0.46659517 | J15: =J14+G14*F14*I14 -> 28.806263 | K15: =K14+G14*M14 -> 0.3581384 | L15: =L14+G14*F14*M14 -> 3.4177977 | M15: =( C15*(J15 + 0.5*L15 + G15*F15*I15) - (1-$D$6)*K15 ) / ( G15 * ( (1-$D$6) + 0.5*C15*F15 ) ) -> 0.17002386 | N15: =SUM($M$6:M15) -> 0.7034287

Sheet CDS Valuation
I2: =Linear('CDS Valuation'!E6,'CDS Bootstrap'!$E$5:$E$15,'CDS Bootstrap'!$N$5:$N$15) | K2: No Default | L2: Default | M2: =loglin(E5,Bootstrap!$D$3:$D$28,Bootstrap!$F$3:$F$28)
C3: Period # | D3: Period Start | E3: Period End | F3: Notional | G3: Fixed Rate | H3: Accrual Fraction | I3: Cumulative PD | J3: Recovery | K3: Fixed Cashflow | L3: Floating Cashflow | M3: Discount Factor | N3: Value
I4: 0
C5: 1 | D5: 45657 | E5: 45736 | F5: 10000000 | G5: 0.01 | H5: =(E5-D5)/360 -> 0.21944444 | I5: =IF(ISNUMBER(MATCH(E5,'CDS Bootstrap'!$E$5:$E$15,0)),_xlfn.XLOOKUP(E5,'CDS Bootstrap'!$E$5:$E$15,'CDS Bootstrap'!$N$5:$N$15),_xlfn.XLOOKUP(E5,'CDS Bootstrap'!$E$5:$E$15,'CDS Bootstrap'!$N$5:$N$15,,-1)+(E5-_xlfn.XLOOKUP(E5,'CDS Bootstrap'!$E$5:$E$15,'CDS Bootstrap'!$E$5:$E$15,,-1))/(_xlfn.XLOOKUP(E5,'CDS Bootstrap'!$E$5:$E$15,'CDS Bootstrap'!$E$5:$E$15,,1)-_xlfn.XLOOKUP(E5,'CDS Bootstrap'!$E$5:$E$15,'CDS Bootstrap'!$E$5:$E$15,,-1))*(_xlfn.XLOOKUP(E5,'CDS Bootstrap'!$E$5:$E$15,'CDS Bootstrap'!$N$5:$N$15,,1)-_xlfn.XLOOKUP(E5,'CDS Bootstrap'!$E$5:$E$15,'CDS Bootstrap'!$N$5:$N$15,,-1))) -> 0.00029464185 | J5: 0.4 | K5: =F5*G5*H5*(1-I5)+F5*G5*H5/2*(I5-I4) -> 21941.212 | L5: =F5*(1-J5)*(I5-I4) -> 1767.8511 | M5: =EXP(LN(_xlfn.XLOOKUP(E5,Bootstrap!$D$4:$D$28,Bootstrap!$F$4:$F$28,,-1))+(E5-_xlfn.XLOOKUP(E5,Bootstrap!$D$4:$D$28,Bootstrap!$D$4:$D$28,,-1))/(_xlfn.XLOOKUP(E5,Bootstrap!$D$4:$D$28,Bootstrap!$D$4:$D$28,,1)-_xlfn.XLOOKUP(E5,Bootstrap!$D$4:$D$28,Bootstrap!$D$4:$D$28,,-1))*(LN(_xlfn.XLOOKUP(E5,Bootstrap!$D$4:$D$28,Bootstrap!$F$4:$F$28,,1))-LN(_xlfn.XLOOKUP(E5,Bootstrap!$D$4:$D$28,Bootstrap!$F$4:$F$28,,-1)))) -> 0.99064088 | N5: =(L5-K5)*M5 -> -19984.556
C6: =C5+1 -> 2 | D6: =E5 -> 45736 | E6: =EDATE(D6,3) -> 45828 | F6: 10000000 | G6: 0.01 | H6: =(E6-D6)/360 -> 0.25555556 | I6: =IF(ISNUMBER(MATCH(E6,'CDS Bootstrap'!$E$5:$E$15,0)),_xlfn.XLOOKUP(E6,'CDS Bootstrap'!$E$5:$E$15,'CDS Bootstrap'!$N$5:$N$15),_xlfn.XLOOKUP(E6,'CDS Bootstrap'!$E$5:$E$15,'CDS Bootstrap'!$N$5:$N$15,,-1)+(E6-_xlfn.XLOOKUP(E6,'CDS Bootstrap'!$E$5:$E$15,'CDS Bootstrap'!$E$5:$E$15,,-1))/(_xlfn.XLOOKUP(E6,'CDS Bootstrap'!$E$5:$E$15,'CDS Bootstrap'!$E$5:$E$15,,1)-_xlfn.XLOOKUP(E6,'CDS Bootstrap'!$E$5:$E$15,'CDS Bootstrap'!$E$5:$E$15,,-1))*(_xlfn.XLOOKUP(E6,'CDS Bootstrap'!$E$5:$E$15,'CDS Bootstrap'!$N$5:$N$15,,1)-_xlfn.XLOOKUP(E6,'CDS Bootstrap'!$E$5:$E$15,'CDS Bootstrap'!$N$5:$N$15,,-1))) -> 0.00063776906 | J6: 0.4 | K6: =F6*G6*H6*(1-I6)+F6*G6*H6/2*(I6-I5) -> 25543.641 | L6: =F6*(1-J6)*(I6-I5) -> 2058.7633 | M6: =EXP(LN(_xlfn.XLOOKUP(E6,Bootstrap!$D$4:$D$28,Bootstrap!$F$4:$F$28,,-1))+(E6-_xlfn.XLOOKUP(E6,Bootstrap!$D$4:$D$28,Bootstrap!$D$4:$D$28,,-1))/(_xlfn.XLOOKUP(E6,Bootstrap!$D$4:$D$28,Bootstrap!$D$4:$D$28,,1)-_xlfn.XLOOKUP(E6,Bootstrap!$D$4:$D$28,Bootstrap!$D$4:$D$28,,-1))*(LN(_xlfn.XLOOKUP(E6,Bootstrap!$D$4:$D$28,Bootstrap!$F$4:$F$28,,1))-LN(_xlfn.XLOOKUP(E6,Bootstrap!$D$4:$D$28,Bootstrap!$F$4:$F$28,,-1)))) -> 0.98018928 | N6: =(L6-K6)*M6 -> -23019.626
C7: =C6+1 -> 3 | D7: =E6 -> 45828 | E7: =EDATE(D7,3) -> 45920 | F7: 10000000 | G7: 0.01 | H7: =(E7-D7)/360 -> 0.25555556 | I7: =IF(ISNUMBER(MATCH(E7,'CDS Bootstrap'!$E$5:$E$15,0)),_xlfn.XLOOKUP(E7,'CDS Bootstrap'!$E$5:$E$15,'CDS Bootstrap'!$N$5:$N$15),_xlfn.XLOOKUP(E7,'CDS Bootstrap'!$E$5:$E$15,'CDS Bootstrap'!$N$5:$N$15,,-1)+(E7-_xlfn.XLOOKUP(E7,'CDS Bootstrap'!$E$5:$E$15,'CDS Bootstrap'!$E$5:$E$15,,-1))/(_xlfn.XLOOKUP(E7,'CDS Bootstrap'!$E$5:$E$15,'CDS Bootstrap'!$E$5:$E$15,,1)-_xlfn.XLOOKUP(E7,'CDS Bootstrap'!$E$5:$E$15,'CDS Bootstrap'!$E$5:$E$15,,-1))*(_xlfn.XLOOKUP(E7,'CDS Bootstrap'!$E$5:$E$15,'CDS Bootstrap'!$N$5:$N$15,,1)-_xlfn.XLOOKUP(E7,'CDS Bootstrap'!$E$5:$E$15,'CDS Bootstrap'!$N$5:$N$15,,-1))) -> 0.0017650726 | J7: 0.4 | K7: =F7*G7*H7*(1-I7)+F7*G7*H7/2*(I7-I6) -> 25524.853 | L7: =F7*(1-J7)*(I7-I6) -> 6763.8209 | M7: =EXP(LN(_xlfn.XLOOKUP(E7,Bootstrap!$D$4:$D$28,Bootstrap!$F$4:$F$28,,-1))+(E7-_xlfn.XLOOKUP(E7,Bootstrap!$D$4:$D$28,Bootstrap!$D$4:$D$28,,-1))/(_xlfn.XLOOKUP(E7,Bootstrap!$D$4:$D$28,Bootstrap!$D$4:$D$28,,1)-_xlfn.XLOOKUP(E7,Bootstrap!$D$4:$D$28,Bootstrap!$D$4:$D$28,,-1))*(LN(_xlfn.XLOOKUP(E7,Bootstrap!$D$4:$D$28,Bootstrap!$F$4:$F$28,,1))-LN(_xlfn.XLOOKUP(E7,Bootstrap!$D$4:$D$28,Bootstrap!$F$4:$F$28,,-1)))) -> 0.97016516 | N7: =(L7-K7)*M7 -> -18201.299
C8: =C7+1 -> 4 | D8: =E7 -> 45920 | E8: =EDATE(D8,3) -> 46011 | F8: 10000000 | G8: 0.01 | H8: =(E8-D8)/360 -> 0.25277778 | I8: =IF(ISNUMBER(MATCH(E8,'CDS Bootstrap'!$E$5:$E$15,0)),_xlfn.XLOOKUP(E8,'CDS Bootstrap'!$E$5:$E$15,'CDS Bootstrap'!$N$5:$N$15),_xlfn.XLOOKUP(E8,'CDS Bootstrap'!$E$5:$E$15,'CDS Bootstrap'!$N$5:$N$15,,-1)+(E8-_xlfn.XLOOKUP(E8,'CDS Bootstrap'!$E$5:$E$15,'CDS Bootstrap'!$E$5:$E$15,,-1))/(_xlfn.XLOOKUP(E8,'CDS Bootstrap'!$E$5:$E$15,'CDS Bootstrap'!$E$5:$E$15,,1)-_xlfn.XLOOKUP(E8,'CDS Bootstrap'!$E$5:$E$15,'CDS Bootstrap'!$E$5:$E$15,,-1))*(_xlfn.XLOOKUP(E8,'CDS Bootstrap'!$E$5:$E$15,'CDS Bootstrap'!$N$5:$N$15,,1)-_xlfn.XLOOKUP(E8,'CDS Bootstrap'!$E$5:$E$15,'CDS Bootstrap'!$N$5:$N$15,,-1))) -> 0.0028801227 | J8: 0.4 | K8: =F8*G8*H8*(1-I8)+F8*G8*H8/2*(I8-I7) -> 25219.068 | L8: =F8*(1-J8)*(I8-I7) -> 6690.3012 | M8: =EXP(LN(_xlfn.XLOOKUP(E8,Bootstrap!$D$4:$D$28,Bootstrap!$F$4:$F$28,,-1))+(E8-_xlfn.XLOOKUP(E8,Bootstrap!$D$4:$D$28,Bootstrap!$D$4:$D$28,,-1))/(_xlfn.XLOOKUP(E8,Bootstrap!$D$4:$D$28,Bootstrap!$D$4:$D$28,,1)-_xlfn.XLOOKUP(E8,Bootstrap!$D$4:$D$28,Bootstrap!$D$4:$D$28,,-1))*(LN(_xlfn.XLOOKUP(E8,Bootstrap!$D$4:$D$28,Bootstrap!$F$4:$F$28,,1))-LN(_xlfn.XLOOKUP(E8,Bootstrap!$D$4:$D$28,Bootstrap!$F$4:$F$28,,-1)))) -> 0.96051045 | N8: =(L8-K8)*M8 -> -17797.074
C9: =C8+1 -> 5 | D9: =E8 -> 46011 | E9: =EDATE(D9,3) -> 46101 | F9: 10000000 | G9: 0.01 | H9: =(E9-D9)/360 -> 0.25 | I9: =IF(ISNUMBER(MATCH(E9,'CDS Bootstrap'!$E$5:$E$15,0)),_xlfn.XLOOKUP(E9,'CDS Bootstrap'!$E$5:$E$15,'CDS Bootstrap'!$N$5:$N$15),_xlfn.XLOOKUP(E9,'CDS Bootstrap'!$E$5:$E$15,'CDS Bootstrap'!$N$5:$N$15,,-1)+(E9-_xlfn.XLOOKUP(E9,'CDS Bootstrap'!$E$5:$E$15,'CDS Bootstrap'!$E$5:$E$15,,-1))/(_xlfn.XLOOKUP(E9,'CDS Bootstrap'!$E$5:$E$15,'CDS Bootstrap'!$E$5:$E$15,,1)-_xlfn.XLOOKUP(E9,'CDS Bootstrap'!$E$5:$E$15,'CDS Bootstrap'!$E$5:$E$15,,-1))*(_xlfn.XLOOKUP(E9,'CDS Bootstrap'!$E$5:$E$15,'CDS Bootstrap'!$N$5:$N$15,,1)-_xlfn.XLOOKUP(E9,'CDS Bootstrap'!$E$5:$E$15,'CDS Bootstrap'!$N$5:$N$15,,-1))) -> 0.0046420405 | J9: 0.4 | K9: =F9*G9*H9*(1-I9)+F9*G9*H9/2*(I9-I8) -> 24905.973 | L9: =F9*(1-J9)*(I9-I8) -> 10571.506 | M9: =EXP(LN(_xlfn.XLOOKUP(E9,Bootstrap!$D$4:$D$28,Bootstrap!$F$4:$F$28,,-1))+(E9-_xlfn.XLOOKUP(E9,Bootstrap!$D$4:$D$28,Bootstrap!$D$4:$D$28,,-1))/(_xlfn.XLOOKUP(E9,Bootstrap!$D$4:$D$28,Bootstrap!$D$4:$D$28,,1)-_xlfn.XLOOKUP(E9,Bootstrap!$D$4:$D$28,Bootstrap!$D$4:$D$28,,-1))*(LN(_xlfn.XLOOKUP(E9,Bootstrap!$D$4:$D$28,Bootstrap!$F$4:$F$28,,1))-LN(_xlfn.XLOOKUP(E9,Bootstrap!$D$4:$D$28,Bootstrap!$F$4:$F$28,,-1)))) -> 0.95118224 | N9: =(L9-K9)*M9 -> -13634.69
C10: =C9+1 -> 6 | D10: =E9 -> 46101 | E10: =EDATE(D10,3) -> 46193 | F10: 10000000 | G10: 0.01 | H10: =(E10-D10)/360 -> 0.25555556 | I10: =IF(ISNUMBER(MATCH(E10,'CDS Bootstrap'!$E$5:$E$15,0)),_xlfn.XLOOKUP(E10,'CDS Bootstrap'!$E$5:$E$15,'CDS Bootstrap'!$N$5:$N$15),_xlfn.XLOOKUP(E10,'CDS Bootstrap'!$E$5:$E$15,'CDS Bootstrap'!$N$5:$N$15,,-1)+(E10-_xlfn.XLOOKUP(E10,'CDS Bootstrap'!$E$5:$E$15,'CDS Bootstrap'!$E$5:$E$15,,-1))/(_xlfn.XLOOKUP(E10,'CDS Bootstrap'!$E$5:$E$15,'CDS Bootstrap'!$E$5:$E$15,,1)-_xlfn.XLOOKUP(E10,'CDS Bootstrap'!$E$5:$E$15,'CDS Bootstrap'!$E$5:$E$15,,-1))*(_xlfn.XLOOKUP(E10,'CDS Bootstrap'!$E$5:$E$15,'CDS Bootstrap'!$N$5:$N$15,,1)-_xlfn.XLOOKUP(E10,'CDS Bootstrap'!$E$5:$E$15,'CDS Bootstrap'!$N$5:$N$15,,-1))) -> 0.0064431119 | J10: 0.4 | K10: =F10*G10*H10*(1-I10)+F10*G10*H10/2*(I10-I9) -> 25413.912 | L10: =F10*(1-J10)*(I10-I9) -> 10806.429 | M10: =EXP(LN(_xlfn.XLOOKUP(E10,Bootstrap!$D$4:$D$28,Bootstrap!$F$4:$F$28,,-1))+(E10-_xlfn.XLOOKUP(E10,Bootstrap!$D$4:$D$28,Bootstrap!$D$4:$D$28,,-1))/(_xlfn.XLOOKUP(E10,Bootstrap!$D$4:$D$28,Bootstrap!$D$4:$D$28,,1)-_xlfn.XLOOKUP(E10,Bootstrap!$D$4:$D$28,Bootstrap!$D$4:$D$28,,-1))*(LN(_xlfn.XLOOKUP(E10,Bootstrap!$D$4:$D$28,Bootstrap!$F$4:$F$28,,1))-LN(_xlfn.XLOOKUP(E10,Bootstrap!$D$4:$D$28,Bootstrap!$F$4:$F$28,,-1)))) -> 0.94172384 | N10: =(L10-K10)*M10 -> -13756.215
C11: =C10+1 -> 7 | D11: =E10 -> 46193 | E11: =EDATE(D11,3) -> 46285 | F11: 10000000 | G11: 0.01 | H11: =(E11-D11)/360 -> 0.25555556 | I11: =IF(ISNUMBER(MATCH(E11,'CDS Bootstrap'!$E$5:$E$15,0)),_xlfn.XLOOKUP(E11,'CDS Bootstrap'!$E$5:$E$15,'CDS Bootstrap'!$N$5:$N$15),_xlfn.XLOOKUP(E11,'CDS Bootstrap'!$E$5:$E$15,'CDS Bootstrap'!$N$5:$N$15,,-1)+(E11-_xlfn.XLOOKUP(E11,'CDS Bootstrap'!$E$5:$E$15,'CDS Bootstrap'!$E$5:$E$15,,-1))/(_xlfn.XLOOKUP(E11,'CDS Bootstrap'!$E$5:$E$15,'CDS Bootstrap'!$E$5:$E$15,,1)-_xlfn.XLOOKUP(E11,'CDS Bootstrap'!$E$5:$E$15,'CDS Bootstrap'!$E$5:$E$15,,-1))*(_xlfn.XLOOKUP(E11,'CDS Bootstrap'!$E$5:$E$15,'CDS Bootstrap'!$N$5:$N$15,,1)-_xlfn.XLOOKUP(E11,'CDS Bootstrap'!$E$5:$E$15,'CDS Bootstrap'!$N$5:$N$15,,-1))) -> 0.0082441834 | J11: 0.4 | K11: =F11*G11*H11*(1-I11)+F11*G11*H11/2*(I11-I10) -> 25367.885 | L11: =F11*(1-J11)*(I11-I10) -> 10806.429 | M11: =EXP(LN(_xlfn.XLOOKUP(E11,Bootstrap!$D$4:$D$28,Bootstrap!$F$4:$F$28,,-1))+(E11-_xlfn.XLOOKUP(E11,Bootstrap!$D$4:$D$28,Bootstrap!$D$4:$D$28,,-1))/(_xlfn.XLOOKUP(E11,Bootstrap!$D$4:$D$28,Bootstrap!$D$4:$D$28,,1)-_xlfn.XLOOKUP(E11,Bootstrap!$D$4:$D$28,Bootstrap!$D$4:$D$28,,-1))*(LN(_xlfn.XLOOKUP(E11,Bootstrap!$D$4:$D$28,Bootstrap!$F$4:$F$28,,1))-LN(_xlfn.XLOOKUP(E11,Bootstrap!$D$4:$D$28,Bootstrap!$F$4:$F$28,,-1)))) -> 0.93235949 | N11: =(L11-K11)*M11 -> -13576.512
C12: =C11+1 -> 8 | D12: =E11 -> 46285 | E12: =EDATE(D12,3) -> 46376 | F12: 10000000 | G12: 0.01 | H12: =(E12-D12)/360 -> 0.25277778 | I12: =IF(ISNUMBER(MATCH(E12,'CDS Bootstrap'!$E$5:$E$15,0)),_xlfn.XLOOKUP(E12,'CDS Bootstrap'!$E$5:$E$15,'CDS Bootstrap'!$N$5:$N$15),_xlfn.XLOOKUP(E12,'CDS Bootstrap'!$E$5:$E$15,'CDS Bootstrap'!$N$5:$N$15,,-1)+(E12-_xlfn.XLOOKUP(E12,'CDS Bootstrap'!$E$5:$E$15,'CDS Bootstrap'!$E$5:$E$15,,-1))/(_xlfn.XLOOKUP(E12,'CDS Bootstrap'!$E$5:$E$15,'CDS Bootstrap'!$E$5:$E$15,,1)-_xlfn.XLOOKUP(E12,'CDS Bootstrap'!$E$5:$E$15,'CDS Bootstrap'!$E$5:$E$15,,-1))*(_xlfn.XLOOKUP(E12,'CDS Bootstrap'!$E$5:$E$15,'CDS Bootstrap'!$N$5:$N$15,,1)-_xlfn.XLOOKUP(E12,'CDS Bootstrap'!$E$5:$E$15,'CDS Bootstrap'!$N$5:$N$15,,-1))) -> 0.010025678 | J12: 0.4 | K12: =F12*G12*H12*(1-I12)+F12*G12*H12/2*(I12-I11) -> 25046.867 | L12: =F12*(1-J12)*(I12-I11) -> 10688.968 | M12: =EXP(LN(_xlfn.XLOOKUP(E12,Bootstrap!$D$4:$D$28,Bootstrap!$F$4:$F$28,,-1))+(E12-_xlfn.XLOOKUP(E12,Bootstrap!$D$4:$D$28,Bootstrap!$D$4:$D$28,,-1))/(_xlfn.XLOOKUP(E12,Bootstrap!$D$4:$D$28,Bootstrap!$D$4:$D$28,,1)-_xlfn.XLOOKUP(E12,Bootstrap!$D$4:$D$28,Bootstrap!$D$4:$D$28,,-1))*(LN(_xlfn.XLOOKUP(E12,Bootstrap!$D$4:$D$28,Bootstrap!$F$4:$F$28,,1))-LN(_xlfn.XLOOKUP(E12,Bootstrap!$D$4:$D$28,Bootstrap!$F$4:$F$28,,-1)))) -> 0.92318854 | N12: =(L12-K12)*M12 -> -13255.048
C13: =C12+1 -> 9 | D13: =E12 -> 46376 | E13: =EDATE(D13,3) -> 46466 | F13: 10000000 | G13: 0.01 | H13: =(E13-D13)/360 -> 0.25 | I13: =IF(ISNUMBER(MATCH(E13,'CDS Bootstrap'!$E$5:$E$15,0)),_xlfn.XLOOKUP(E13,'CDS Bootstrap'!$E$5:$E$15,'CDS Bootstrap'!$N$5:$N$15),_xlfn.XLOOKUP(E13,'CDS Bootstrap'!$E$5:$E$15,'CDS Bootstrap'!$N$5:$N$15,,-1)+(E13-_xlfn.XLOOKUP(E13,'CDS Bootstrap'!$E$5:$E$15,'CDS Bootstrap'!$E$5:$E$15,,-1))/(_xlfn.XLOOKUP(E13,'CDS Bootstrap'!$E$5:$E$15,'CDS Bootstrap'!$E$5:$E$15,,1)-_xlfn.XLOOKUP(E13,'CDS Bootstrap'!$E$5:$E$15,'CDS Bootstrap'!$E$5:$E$15,,-1))*(_xlfn.XLOOKUP(E13,'CDS Bootstrap'!$E$5:$E$15,'CDS Bootstrap'!$N$5:$N$15,,1)-_xlfn.XLOOKUP(E13,'CDS Bootstrap'!$E$5:$E$15,'CDS Bootstrap'!$N$5:$N$15,,-1))) -> 0.014013035 | J13: 0.4 | K13: =F13*G13*H13*(1-I13)+F13*G13*H13/2*(I13-I12) -> 24699.516 | L13: =F13*(1-J13)*(I13-I12) -> 23924.141 | M13: =EXP(LN(_xlfn.XLOOKUP(E13,Bootstrap!$D$4:$D$28,Bootstrap!$F$4:$F$28,,-1))+(E13-_xlfn.XLOOKUP(E13,Bootstrap!$D$4:$D$28,Bootstrap!$D$4:$D$28,,-1))/(_xlfn.XLOOKUP(E13,Bootstrap!$D$4:$D$28,Bootstrap!$D$4:$D$28,,1)-_xlfn.XLOOKUP(E13,Bootstrap!$D$4:$D$28,Bootstrap!$D$4:$D$28,,-1))*(LN(_xlfn.XLOOKUP(E13,Bootstrap!$D$4:$D$28,Bootstrap!$F$4:$F$28,,1))-LN(_xlfn.XLOOKUP(E13,Bootstrap!$D$4:$D$28,Bootstrap!$F$4:$F$28,,-1)))) -> 0.91415085 | N13: =(L13-K13)*M13 -> -708.8097
C14: =C13+1 -> 10 | D14: =E13 -> 46466 | E14: =EDATE(D14,3) -> 46558 | F14: 10000000 | G14: 0.01 | H14: =(E14-D14)/360 -> 0.25555556 | I14: =IF(ISNUMBER(MATCH(E14,'CDS Bootstrap'!$E$5:$E$15,0)),_xlfn.XLOOKUP(E14,'CDS Bootstrap'!$E$5:$E$15,'CDS Bootstrap'!$N$5:$N$15),_xlfn.XLOOKUP(E14,'CDS Bootstrap'!$E$5:$E$15,'CDS Bootstrap'!$N$5:$N$15,,-1)+(E14-_xlfn.XLOOKUP(E14,'CDS Bootstrap'!$E$5:$E$15,'CDS Bootstrap'!$E$5:$E$15,,-1))/(_xlfn.XLOOKUP(E14,'CDS Bootstrap'!$E$5:$E$15,'CDS Bootstrap'!$E$5:$E$15,,1)-_xlfn.XLOOKUP(E14,'CDS Bootstrap'!$E$5:$E$15,'CDS Bootstrap'!$E$5:$E$15,,-1))*(_xlfn.XLOOKUP(E14,'CDS Bootstrap'!$E$5:$E$15,'CDS Bootstrap'!$N$5:$N$15,,1)-_xlfn.XLOOKUP(E14,'CDS Bootstrap'!$E$5:$E$15,'CDS Bootstrap'!$N$5:$N$15,,-1))) -> 0.018089 | J14: 0.4 | K14: =F14*G14*H14*(1-I14)+F14*G14*H14/2*(I14-I13) -> 25145.363 | L14: =F14*(1-J14)*(I14-I13) -> 24455.789 | M14: =EXP(LN(_xlfn.XLOOKUP(E14,Bootstrap!$D$4:$D$28,Bootstrap!$F$4:$F$28,,-1))+(E14-_xlfn.XLOOKUP(E14,Bootstrap!$D$4:$D$28,Bootstrap!$D$4:$D$28,,-1))/(_xlfn.XLOOKUP(E14,Bootstrap!$D$4:$D$28,Bootstrap!$D$4:$D$28,,1)-_xlfn.XLOOKUP(E14,Bootstrap!$D$4:$D$28,Bootstrap!$D$4:$D$28,,-1))*(LN(_xlfn.XLOOKUP(E14,Bootstrap!$D$4:$D$28,Bootstrap!$F$4:$F$28,,1))-LN(_xlfn.XLOOKUP(E14,Bootstrap!$D$4:$D$28,Bootstrap!$F$4:$F$28,,-1)))) -> 0.90499584 | N14: =(L14-K14)*M14 -> -624.06179
C15: =C14+1 -> 11 | D15: =E14 -> 46558 | E15: =EDATE(D15,3) -> 46650 | F15: 10000000 | G15: 0.01 | H15: =(E15-D15)/360 -> 0.25555556 | I15: =IF(ISNUMBER(MATCH(E15,'CDS Bootstrap'!$E$5:$E$15,0)),_xlfn.XLOOKUP(E15,'CDS Bootstrap'!$E$5:$E$15,'CDS Bootstrap'!$N$5:$N$15),_xlfn.XLOOKUP(E15,'CDS Bootstrap'!$E$5:$E$15,'CDS Bootstrap'!$N$5:$N$15,,-1)+(E15-_xlfn.XLOOKUP(E15,'CDS Bootstrap'!$E$5:$E$15,'CDS Bootstrap'!$E$5:$E$15,,-1))/(_xlfn.XLOOKUP(E15,'CDS Bootstrap'!$E$5:$E$15,'CDS Bootstrap'!$E$5:$E$15,,1)-_xlfn.XLOOKUP(E15,'CDS Bootstrap'!$E$5:$E$15,'CDS Bootstrap'!$E$5:$E$15,,-1))*(_xlfn.XLOOKUP(E15,'CDS Bootstrap'!$E$5:$E$15,'CDS Bootstrap'!$N$5:$N$15,,1)-_xlfn.XLOOKUP(E15,'CDS Bootstrap'!$E$5:$E$15,'CDS Bootstrap'!$N$5:$N$15,,-1))) -> 0.022164964 | J15: 0.4 | K15: =F15*G15*H15*(1-I15)+F15*G15*H15/2*(I15-I14) -> 25041.199 | L15: =F15*(1-J15)*(I15-I14) -> 24455.789 | M15: =EXP(LN(_xlfn.XLOOKUP(E15,Bootstrap!$D$4:$D$28,Bootstrap!$F$4:$F$28,,-1))+(E15-_xlfn.XLOOKUP(E15,Bootstrap!$D$4:$D$28,Bootstrap!$D$4:$D$28,,-1))/(_xlfn.XLOOKUP(E15,Bootstrap!$D$4:$D$28,Bootstrap!$D$4:$D$28,,1)-_xlfn.XLOOKUP(E15,Bootstrap!$D$4:$D$28,Bootstrap!$D$4:$D$28,,-1))*(LN(_xlfn.XLOOKUP(E15,Bootstrap!$D$4:$D$28,Bootstrap!$F$4:$F$28,,1))-LN(_xlfn.XLOOKUP(E15,Bootstrap!$D$4:$D$28,Bootstrap!$F$4:$F$28,,-1)))) -> 0.89593252 | N15: =(L15-K15)*M15 -> -524.48845
C16: =C15+1 -> 12 | D16: =E15 -> 46650 | E16: =EDATE(D16,3) -> 46741 | F16: 10000000 | G16: 0.01 | H16: =(E16-D16)/360 -> 0.25277778 | I16: =IF(ISNUMBER(MATCH(E16,'CDS Bootstrap'!$E$5:$E$15,0)),_xlfn.XLOOKUP(E16,'CDS Bootstrap'!$E$5:$E$15,'CDS Bootstrap'!$N$5:$N$15),_xlfn.XLOOKUP(E16,'CDS Bootstrap'!$E$5:$E$15,'CDS Bootstrap'!$N$5:$N$15,,-1)+(E16-_xlfn.XLOOKUP(E16,'CDS Bootstrap'!$E$5:$E$15,'CDS Bootstrap'!$E$5:$E$15,,-1))/(_xlfn.XLOOKUP(E16,'CDS Bootstrap'!$E$5:$E$15,'CDS Bootstrap'!$E$5:$E$15,,1)-_xlfn.XLOOKUP(E16,'CDS Bootstrap'!$E$5:$E$15,'CDS Bootstrap'!$E$5:$E$15,,-1))*(_xlfn.XLOOKUP(E16,'CDS Bootstrap'!$E$5:$E$15,'CDS Bootstrap'!$N$5:$N$15,,1)-_xlfn.XLOOKUP(E16,'CDS Bootstrap'!$E$5:$E$15,'CDS Bootstrap'!$N$5:$N$15,,-1))) -> 0.026196625 | J16: 0.4 | K16: =F16*G16*H16*(1-I16)+F16*G16*H16/2*(I16-I15) -> 24666.541 | L16: =F16*(1-J16)*(I16-I15) -> 24189.965 | M16: =EXP(LN(_xlfn.XLOOKUP(E16,Bootstrap!$D$4:$D$28,Bootstrap!$F$4:$F$28,,-1))+(E16-_xlfn.XLOOKUP(E16,Bootstrap!$D$4:$D$28,Bootstrap!$D$4:$D$28,,-1))/(_xlfn.XLOOKUP(E16,Bootstrap!$D$4:$D$28,Bootstrap!$D$4:$D$28,,1)-_xlfn.XLOOKUP(E16,Bootstrap!$D$4:$D$28,Bootstrap!$D$4:$D$28,,-1))*(LN(_xlfn.XLOOKUP(E16,Bootstrap!$D$4:$D$28,Bootstrap!$F$4:$F$28,,1))-LN(_xlfn.XLOOKUP(E16,Bootstrap!$D$4:$D$28,Bootstrap!$F$4:$F$28,,-1)))) -> 0.887057 | N16: =(L16-K16)*M16 -> -422.75019
C17: =C16+1 -> 13 | D17: =E16 -> 46741 | E17: =EDATE(D17,3) -> 46832 | F17: 10000000 | G17: 0.01 | H17: =(E17-D17)/360 -> 0.25277778 | I17: =IF(ISNUMBER(MATCH(E17,'CDS Bootstrap'!$E$5:$E$15,0)),_xlfn.XLOOKUP(E17,'CDS Bootstrap'!$E$5:$E$15,'CDS Bootstrap'!$N$5:$N$15),_xlfn.XLOOKUP(E17,'CDS Bootstrap'!$E$5:$E$15,'CDS Bootstrap'!$N$5:$N$15,,-1)+(E17-_xlfn.XLOOKUP(E17,'CDS Bootstrap'!$E$5:$E$15,'CDS Bootstrap'!$E$5:$E$15,,-1))/(_xlfn.XLOOKUP(E17,'CDS Bootstrap'!$E$5:$E$15,'CDS Bootstrap'!$E$5:$E$15,,1)-_xlfn.XLOOKUP(E17,'CDS Bootstrap'!$E$5:$E$15,'CDS Bootstrap'!$E$5:$E$15,,-1))*(_xlfn.XLOOKUP(E17,'CDS Bootstrap'!$E$5:$E$15,'CDS Bootstrap'!$N$5:$N$15,,1)-_xlfn.XLOOKUP(E17,'CDS Bootstrap'!$E$5:$E$15,'CDS Bootstrap'!$N$5:$N$15,,-1))) -> 0.033354436 | J17: 0.4 | K17: =F17*G17*H17*(1-I17)+F17*G17*H17/2*(I17-I16) -> 24525.119 | L17: =F17*(1-J17)*(I17-I16) -> 42946.866 | M17: =EXP(LN(_xlfn.XLOOKUP(E17,Bootstrap!$D$4:$D$28,Bootstrap!$F$4:$F$28,,-1))+(E17-_xlfn.XLOOKUP(E17,Bootstrap!$D$4:$D$28,Bootstrap!$D$4:$D$28,,-1))/(_xlfn.XLOOKUP(E17,Bootstrap!$D$4:$D$28,Bootstrap!$D$4:$D$28,,1)-_xlfn.XLOOKUP(E17,Bootstrap!$D$4:$D$28,Bootstrap!$D$4:$D$28,,-1))*(LN(_xlfn.XLOOKUP(E17,Bootstrap!$D$4:$D$28,Bootstrap!$F$4:$F$28,,1))-LN(_xlfn.XLOOKUP(E17,Bootstrap!$D$4:$D$28,Bootstrap!$F$4:$F$28,,-1)))) -> 0.87834368 | N17: =(L17-K17)*M17 -> 16180.625
... C32: =C31+1 -> 28 | D32: =E31 -> 48111 | E32: =EDATE(D32,3) -> 48202 | F32: 10000000 | G32: 0.01 | H32: =(E32-D32)/360 -> 0.25277778 | I32: =IF(ISNUMBER(MATCH(E32,'CDS Bootstrap'!$E$5:$E$15,0)),_xlfn.XLOOKUP(E32,'CDS Bootstrap'!$E$5:$E$15,'CDS Bootstrap'!$N$5:$N$15),_xlfn.XLOOKUP(E32,'CDS Bootstrap'!$E$5:$E$15,'CDS Bootstrap'!$N$5:$N$15,,-1)+(E32-_xlfn.XLOOKUP(E32,'CDS Bootstrap'!$E$5:$E$15,'CDS Bootstrap'!$E$5:$E$15,,-1))/(_xlfn.XLOOKUP(E32,'CDS Bootstrap'!$E$5:$E$15,'CDS Bootstrap'!$E$5:$E$15,,1)-_xlfn.XLOOKUP(E32,'CDS Bootstrap'!$E$5:$E$15,'CDS Bootstrap'!$E$5:$E$15,,-1))*(_xlfn.XLOOKUP(E32,'CDS Bootstrap'!$E$5:$E$15,'CDS Bootstrap'!$N$5:$N$15,,1)-_xlfn.XLOOKUP(E32,'CDS Bootstrap'!$E$5:$E$15,'CDS Bootstrap'!$N$5:$N$15,,-1))) -> 0.20182403 | J32: 0.4 | K32: =F32*G32*H32*(1-I32)+F32*G32*H32/2*(I32-I31) -> 20338.016 | L32: =F32*(1-J32)*(I32-I31) -> 76858.686 | M32: =EXP(LN(_xlfn.XLOOKUP(E32,Bootstrap!$D$4:$D$28,Bootstrap!$F$4:$F$28,,-1))+(E32-_xlfn.XLOOKUP(E32,Bootstrap!$D$4:$D$28,Bootstrap!$D$4:$D$28,,-1))/(_xlfn.XLOOKUP(E32,Bootstrap!$D$4:$D$28,Bootstrap!$D$4:$D$28,,1)-_xlfn.XLOOKUP(E32,Bootstrap!$D$4:$D$28,Bootstrap!$D$4:$D$28,,-1))*(LN(_xlfn.XLOOKUP(E32,Bootstrap!$D$4:$D$28,Bootstrap!$F$4:$F$28,,1))-LN(_xlfn.XLOOKUP(E32,Bootstrap!$D$4:$D$28,Bootstrap!$F$4:$F$28,,-1)))) -> 0.75549445 | N32: =(L32-K32)*M32 -> 42701.052
N33: =SUM(N5:N32) -> 419442.51
