Workbook

Sheet 1_Raw_Data
A1: Market Risk - Daily Time Series | Raw Data | Jan 2 - Mar 12, 2026 | 48 Observations | 6 Risk Factors
A2: Date | B2: USD 2Y (%) | C2: USD 5Y (%) | D2: USD 10Y (%) | E2: CORP BBB Spread (bps) | F2: SPX (pts) | G2: EURUSD | H2: DQ Flag | I2: DQ Category
A3: 46024 | B3: 4.35 | C3: 4.18 | D3: 4.05 | E3: 165 | F3: 4750 | G3: 1.094
A4: 46027 | B4: 4.33 | C4: 4.17 | D4: 4.06 | E4: 166 | F4: 4762 | G4: 1.0928
A5: 46028 | B5: 4.31 | C5: 4.16 | D5: 4.05 | E5: 168 | F5: 4748 | G5: 1.0909
A6: 46029 | B6: 4.34 | C6: 4.19 | D6: 4.07 | E6: 169 | F6: 4775 | G6: 1.0915
A7: 46030 | B7: 4.36 | C7: 4.21 | D7: 4.08 | E7: 171 | F7: 4790 | G7: 1.0932
A8: 46031 | B8: 4.36 | C8: 4.21 | D8: 4.08 | E8: 171 | F8: 4790 | G8: 1.0932 | H8: STALE | I8: Stale Values
A9: 46034 | B9: 4.36 | C9: 4.21 | D9: 4.08 | E9: 171 | F9: 4790 | G9: 1.0932 | H9: STALE | I9: Stale Values
A10: 46035 | B10: 4.29 | C10: 4.14 | D10: 4.02 | E10: 173 | F10: 4736 | G10: 1.0897
A11: 46036 | B11: 4.28 | C11: 4.13 | D11: 4.01 | E11: 174 | F11: 4722 | G11: 1.0888
A12: 46037 | B12: 4.3 | C12: 4.15 | D12: 4.03 | E12: 176 | F12: 4741 | G12: 1.0896
A13: 46038 | B13: 4.32 | C13: 4.16 | D13: 4.04 | E13: 177 | F13: 4755 | G13: 1.0904
A14: 46042 | B14: 4.34 | C14: 4.18 | D14: 4.05 | E14: 179 | F14: 4768 | G14: 1.0911
A15: 46043 | B15: 4.33 | C15: 4.17 | D15: 4.05 | E15: 181 | F15: 4759 | G15: 1.0899
A16: 46044 | B16: 4.31 | C16: 4.16 | D16: 4.04 | E16: 182 | F16: 4744 | G16: 1.088
A17: 46045 | B17: 4.3 | C17: 4.15 | D17: 4.04 | E17: 183 | F17: 4728 | G17: 1.0872
A18: 46048 | B18: 4.28 | C18: 4.13 | D18: 4.03 | E18: 185 | F18: 4705 | G18: 1.0855
A19: 46049 | B19: 4.29 | C19: 4.14 | D19: 4.03 | E19: 186 | F19: 4718 | G19: 1.086
A20: 46050 | B20: 4.27 | C20: 4.12 | D20: 4.02 | E20: 187 | F20: 4699 | G20: 1.0846
A21: 46051 | B21: 4.26 | C21: 4.11 | D21: 4.02 | E21: 188 | F21: 4687 | G21: 1.0839
... A35: 46072 | B35: 4.32 | C35: 4.17 | D35: 4.05 | E35: 207 | F35: 4755 | G35: 1.089
A36: 46073 | B36: 4.1 | C36: 3.95 | D36: 3.9 | E36: 210 | F36: 4680 | G36: 1.0878 | H36: DISCONTINUITY | I36: Outlier / Discontinuity
A37: 46076 | B37: 4.12 | C37: 3.98 | D37: 3.92 | E37: 212 | F37: 4692 | G37: 1.0884
A38: 46077 | B38: 4.13 | C38: 3.99 | D38: 3.93 | F38: 4701 | G38: 1.0889 | H38: MISSING | I38: Missing Value
A39: 46078 | B39: 4.14 | C39: 3.6 | D39: 3.94 | E39: 215 | F39: 4715 | G39: 1.0896 | H39: SPIKE + TENOR CROSS | I39: Outlier / Spike + Tenor Crossing
A40: 46079 | B40: 4.15 | C40: 4.01 | D40: 3.95 | E40: 216 | F40: 4722 | G40: 1.0903
A41: 46080 | B41: 4.16 | C41: 4.02 | D41: 3.96 | E41: 217 | F41: 4734 | G41: 1.0912
A42: 46083 | B42: 4.18 | C42: 4.04 | D42: 3.97 | E42: 218 | F42: 4746 | G42: 1.092
A43: 46084 | B43: 4.19 | C43: 4.05 | D43: 3.98 | E43: -25 | F43: 4760 | G43: 1.0929 | H43: NEGATIVE SPREAD | I43: Outlier / Negative Spread
A44: 46085 | B44: 4.2 | C44: 4.06 | D44: 3.99 | E44: 219 | F44: 4772 | G44: 1.0937
A45: 46086 | B45: 4.22 | C45: 4.08 | D45: 4 | E45: 220 | F45: 4788 | G45: 1.0949
A46: 46087 | B46: 4.23 | C46: 4.09 | D46: 4.01 | E46: 221 | F46: 4795 | G46: 1.25 | H46: SPIKE | I46: Outlier / Spike
A47: 46090 | B47: 4.24 | C47: 4.1 | D47: 4.02 | E47: 222 | F47: 4802 | G47: 1.0962
A48: 46091 | B48: 4.25 | C48: 4.11 | D48: 4.02 | E48: 223 | F48: 4810 | G48: 1.0955
A49: 46092 | B49: 4.26 | C49: 4.12 | D49: 4.03 | E49: 224 | F49: 4822 | G49: 1.096
A50: 46093 | B50: 4.27 | C50: 4.13 | D50: 4.04 | E50: 225 | F50: 4835 | G50: 1.0971
A53: Color Key: | B53: Stale | C53: Missing | D53: Discontinuity | E53: Spike / Tenor Crossing | F53: Negative Spread

Sheet 2_DQ_Detection
A1: DQ Detection | Issues Identified and Documented
A2: # | B2: Date(s) | C2: Risk Factor(s) | D2: DQ Category | E2: Flag | F2: Statistical Evidence | G2: Market / Economic Rationale | H2: Impact on VaR / ES | I2: Detection Method
A3: 1 | B3: Jan 9 & Jan 12, 2026 | C3: All 6 Risk Factors | D3: Stale Values | E3: Stale Values | F3: All 6 RFs on Jan 9 and Jan 12 are identical to Jan 8. USD 2Y: 4.36 unchanged (Δ = 0.00). USD 5Y: 4.21, USD 10Y: 4.08, CORP: 171, SPX: 4,790, EURUSD: 1.0932. Probability of a full-panel freeze across 6 independent RFs on 2 separate business days ≈ 0. | G3: Jan 10-11 are weekends (not in dataset). Jan 9 and Jan 12 are consecutive business days. No market event would freeze all 6 unrelated RFs simultaneously. Indicates vendor feed outage - data was not updated and prior day values were re-fed. | H3: Stale IR rates freeze duration / DV01 risk at Jan 8 levels. Stale SPX understates equity vol. VaR computed on these dates uses flat P&L scenarios - understates true risk. | I3: Stale check: 3+ consecutive identical observations across all RFs
A4: 2 | B4: ='1_Raw_Data'!A36 -> 46073 | C4: USD 2Y, USD 5Y, USD 10Y | D4: Outlier / Discontinuity | E4: Discontinuity | F4: USD 2Y: 4.32 → 4.10 (Δ = −22 bps, one day). USD 5Y: 4.17 → 3.95 (Δ = −22 bps). USD 10Y: 4.05 → 3.90 (Δ = −15 bps). Partial reversal by Feb 23: USD 2Y recovers to 4.12. CORP BBB, SPX, EURUSD on Feb 20 show no anomaly. | G4: A genuine 20+ bps parallel IR shift followed by immediate partial reversal is economically implausible without a macro catalyst. No central bank action or crisis event occurred. CORP, SPX, EURUSD are unaffected - if a real rate shock had occurred, credit spreads and equities would have reacted. Indicates a vendor curve-fixing error (wrong settlement date or stale snapshot published). | H4: Incorrect rate levels distort DV01-based sensitivity. Any ES scenario generated with Feb 20 data produces a synthetic shock not reflective of realized market conditions. Contaminates the full lookback window of the HS model. | I4: Day-over-day change > 3σ across all IR tenors simultaneously; partial reversal within 3 days
A5: 3 | B5: ='1_Raw_Data'!A38 -> 46077 | C5: CORP BBB Spread | D5: Missing Value | E5: Missing Value | F5: CORP BBB Spread is null / blank on Feb 24. Surrounding clean values: Feb 23 = 212 bps, Feb 25 = 215 bps. Missing % for CORP column = 1/48 = 2.08% - breaches <0.5% threshold. | G5: Single-day gap in credit spread data. All other 5 RFs present on Feb 24. Indicates a one-day feed interruption for the CORP BBB time series specifically. The surrounding trend is smooth and monotone (steady widening), confirming the gap is a sourcing failure. | H5: Credit spread exposure cannot be computed for Feb 24. Any HS scenario window including this date will have an incomplete credit risk picture. If excluded, the lookback shrinks by 1 day; if left null, the risk engine may error. | I5: Null / blank check on daily CORP BBB column
A6: 4 | B6: ='1_Raw_Data'!A39 -> 46078 | C6: USD 5Y | D6: Outlier / Spike | E6: Spike | F6: USD 5Y: 3.99 → 3.60 → 4.01 (Feb 24/25/26). Single-day move: −39 bps. Adjacent tenors on the same date: USD 2Y +1 bp, USD 10Y +1 bp. Z-score = (3.60 − 4.10) / 0.094 ≈ −5.3σ (vs. full sample mean/std). | G6: A -39 bps move in 5Y yields while 2Y and 10Y are flat is structurally impossible in a functioning market - a 5Y dislocation of this magnitude would immediately propagate to adjacent tenors via arbitrage. The value fully reverts the next day, confirming it is a data entry error, not a real rate move. | H6: IR VaR for any instrument with 5Y duration would be massively overstated. DV01 hedges calibrated to this date would be mis-sized. Additionally, this spike causes a tenor crossing (see Issue #5). | I6: Z-score |z| > 3σ; single-day spike with full next-day reversal; no corroboration in adjacent tenors
A7: 5 | B7: ='1_Raw_Data'!A39 -> 46078 | C7: USD 5Y vs USD 10Y | D7: Tenor Crossing | E7: Tenor Crossing | F7: On Feb 25 (raw data): USD 5Y = 3.60 < USD 10Y = 3.94. 5Y-10Y inversion = −34 bps. No other date in the dataset has 5Y < 10Y. Normal spread (5Y − 10Y) across all other dates: +0.10 to +0.13. | G7: A 5Y rate sitting 34 bps below 10Y is a structural market impossibility in this context - it would imply extreme near-term rate cut expectations not supported by any macro data. This is a direct consequence of the USD 5Y spike (#4): the 5Y level is wrong, not the 10Y. | H7: Yield curve used in HS scenario generation is structurally broken for Feb 25. Scenario P&Ls for all instruments spanning the 5-10Y segment are unreliable. Risk engine may produce internally inconsistent pricing. | I7: Cross-tenor consistency check: 5Y yield < 10Y yield (monotonicity violation)
A8: 6 | B8: ='1_Raw_Data'!A43 -> 46084 | C8: CORP BBB Spread | D8: Outlier / Negative Spread | E8: Negative Spread | F8: CORP BBB Spread = −25 bps on Mar 3. Surrounding values: Mar 2 = 218 bps, Mar 4 = 219 bps. Z-score = (−25 − 189.8) / 36.5 ≈ −5.9σ. Domain rule: a credit spread cannot be negative. | G8: A BBB corporate spread below zero is economically impossible - it implies investors demand a lower yield on a sub-investment-grade corporate bond than on risk-free sovereign debt. The surrounding values (218-219 bps) and the monotone trend confirm this is a data entry error (likely a sign flip or missing digit: −25 instead of 215 or 225). | H8: Credit VaR computed with a −25 bps spread would produce an impossible scenario. A long credit position would show a massive artificial gain; a short position would show an artificial loss. The error renders the entire Mar 3 credit scenario unusable. | I8: Domain validity check: spread < 0 is economically impossible; |z| > 3σ
A9: 7 | B9: ='1_Raw_Data'!A46 -> 46087 | C9: EURUSD | D9: Outlier / Spike | E9: Spike | F9: EURUSD: 1.0949 → 1.2500 → 1.0962 (Mar 5/6/9). Single-day move: +14.6%. Mean = 1.0922, Std = 0.0234 (full sample). Z-score = (1.2500 − 1.0922) / 0.0234 ≈ +6.7σ. Full next-day reversal. | G9: EURUSD has never moved 14% in a single trading session under normal conditions. The largest single-day EUR/USD moves in history (e.g., SNB floor removal, 2015) were ~15% - such an event would dominate every news source globally. The immediate full reversal the next day confirms this is a keying/decimal error (e.g., 1.2500 instead of 1.0500). | H9: FX VaR for any EUR/USD exposure would be dominated by this single scenario. A 14.6% move entered into a 250-day HS window inflates the VaR estimate for the entire window, making it uninformative and likely triggering false regulatory capital charges. | I9: Z-score |z| > 6σ; day-over-day move > 10%; full next-day reversal
A12: DQ Summary Statistics
A13: Total observations | B13: =COUNT('1_Raw_Data'!A3:A1000) -> 48
A14: Total cells (6 risk factors x obs) | B14: =B13*6 -> 288
A15: Missing cells | B15: {=SUMPRODUCT(('1_Raw_Data'!B3:G50="")*('1_Raw_Data'!A3:A50<>""))} -> 1
A16: Missing % of total cells | B16: =B15/B14 -> 0.0034722222
A17: Stale cell-observations (rows x 6 RFs) | B17: =COUNTIF('1_Raw_Data'!H3:H1000,"STALE")*6 -> 12
A18: Stale % of total cells | B18: =B17/B14 -> 0.041666667
A19: Outlier / spike / discontinuity flags | B19: =COUNTA('1_Raw_Data'!H3:H1000)-COUNTIF('1_Raw_Data'!H3:H1000,"STALE") -> 5
A20: Distinct DQ issues identified | B20: =COUNTA(A3:A9) -> 7
A21: DQ categories covered | B21: {=SUMPRODUCT(('1_Raw_Data'!I3:I50<>"")/COUNTIF('1_Raw_Data'!I3:I50,'1_Raw_Data'!I3:I50&""))} -> 6

Sheet 3_Remediation
A1: Remediation | Linear Interpolation & Forward Fill
A2: Issue # | B2: Date(s) | C2: Risk Factor | D2: DQ Category | E2: Remediation Method | F2: Formula / Logic | G2: Remediated Value | H2: Rationale - Why This Method
A3: 1 | B3: ='1_Raw_Data'!A8 -> 46031 | C3: All 6 RFs | D3: Stale | E3: Linear Interpolation | F3: Jan8 + (Jan13 - Jan8) × 1/3 [step 1 of 3] | G3: ='4_Clean_Data_Assumptions'!B8 -> 4.3366667 | H3: Linear interp between Jan 8 (last clean, step 0) and Jan 13 (next clean, step 3). Jan 9 = step 1/3. Produces a smooth, market-consistent path. Preferred over forward fill for stale data because it corrects the flat period rather than extending it.
A4: 1 | B4: ='1_Raw_Data'!A9 -> 46034 | C4: All 6 RFs | D4: Stale | E4: Linear Interpolation | F4: Jan8 + (Jan13 - Jan8) × 2/3 [step 2 of 3] | G4: ='4_Clean_Data_Assumptions'!B9 -> 4.3133333 | H4: Jan 12 = step 2/3 of the same interpolation path. Both stale dates use the same clean anchors (Jan 8 and Jan 13).
A5: 2 | B5: ='1_Raw_Data'!A36 -> 46073 | C5: USD 2Y / 5Y / 10Y only | D5: Discontinuity | E5: Linear Interpolation | F5: Feb19 + (Feb23 - Feb19) × 1/4 [step 1 of 4] | G5: ='4_Clean_Data_Assumptions'!B36 -> 4.27 | H5: IR tenors only remediated. Feb 20 = step 1/4 between Feb 19 (row 35) and Feb 23 (row 37). CORP BBB (210), SPX (4,680), EURUSD (1.0878) on Feb 20 are clean and retained as-is.
A6: 3 | B6: ='1_Raw_Data'!A38 -> 46077 | C6: CORP BBB Spread | D6: Missing | E6: Linear Interpolation | F6: (Feb23_CORP + Feb25_CORP) / 2 | G6: ='4_Clean_Data_Assumptions'!E38 -> 213.5 | H6: Single-day gap. Feb 23 = 212 bps, Feb 25 = 215 bps. Linear interp (midpoint) gives 213.5 bps. Trend is smooth and monotone - interpolation is the most accurate fill.
A7: 4 | B7: ='1_Raw_Data'!A39 -> 46078 | C7: USD 5Y | D7: Spike + Tenor Crossing | E7: Linear Interpolation | F7: (Feb24_5Y + Feb26_5Y) / 2 | G7: ='4_Clean_Data_Assumptions'!C39 -> 4 | H7: Feb 24 = 3.99%, Feb 26 = 4.01%. Interpolated = 4.00%. Correcting the 5Y spike also resolves the tenor crossing: post-remediation USD 5Y (4.00%) > USD 10Y (3.94%), restoring monotone curve.
A8: 5 | B8: ='1_Raw_Data'!A39 -> 46078 | C8: USD 5Y vs USD 10Y | D8: Tenor Crossing | E8: N/A — Resolved via Issue #4 | F8: No separate formula needed | G8: N/A | H8: Tenor crossing on Feb 25 (USD 5Y = 3.60% < USD 10Y = 3.94%) is a direct consequence of the USD 5Y spike (Issue #4). Correcting the spike via interpolation to 4.00% automatically restores the yield curve monotonicity: USD 5Y (4.00%) > USD 10Y (3.94%). No separate remediation step required.
A9: 6 | B9: ='1_Raw_Data'!A43 -> 46084 | C9: CORP BBB Spread | D9: Outlier / Negative Spread | E9: Forward Fill | F9: Forward fill: carry Mar 2 CORP value forward | G9: ='4_Clean_Data_Assumptions'!E43 -> 218 | H9: Forward fill from Mar 2 (218 bps). Applied for a domain-validity error (negative spread) rather than interpolation because: (a) the error is an impossible value - any computed midpoint would be unreliable; (b) the prior clean value (218) is stable and consistent with the trend; (c) forward fill is the standard method for clear sign/magnitude errors in production.
A10: 7 | B10: ='1_Raw_Data'!A46 -> 46087 | C10: EURUSD | D10: Spike / Outlier | E10: Linear Interpolation | F10: (Mar5_EURUSD + Mar9_EURUSD) / 2 | G10: ='4_Clean_Data_Assumptions'!G46 -> 1.0956 | H10: Mar 5 = 1.0949, Mar 9 = 1.0962. Interpolated = 1.0956. Full next-day reversal confirms error is isolated to Mar 6. Clean anchors available on both sides - interpolation is preferred over forward fill.
A13: Remediation Method Summary
A14: Method | B14: Applied To | C14: Issues Covered | D14: When to Use
A15: Linear Interpolation | B15: Jan 9, Jan 12 (Stale); Feb 20 IR tenors (Discontinuity); Feb 24 CORP (Missing); Feb 25 USD 5Y (Spike); Mar 6 EURUSD (Spike) | C15: 6 of 7 issues | D15: Clean anchor observations available on BOTH sides of the gap. Smooth trend between anchors. Produces a market-consistent path without introducing artificial flatness.
A16: Forward Fill | B16: Mar 3 CORP BBB Spread (Negative Spread) | C16: 1 of 7 issues | D16: Domain-validity error (impossible value) where the error itself makes interpolation unreliable. Prior clean observation is stable and the best available anchor. Also appropriate when next clean observation is not yet available (real-time production).

Sheet 4_Clean_Data_Assumptions
A1: Clean / Remediated Time Series | Formulas reference Sheet 1_Raw_Data | Remediated cells highlighted
A2: Date | B2: USD 2Y (%) | C2: USD 5Y (%) | D2: USD 10Y (%) | E2: CORP BBB (bps) | F2: SPX (pts) | G2: EURUSD | H2: Remediation Applied | I2: Method
A3: ='1_Raw_Data'!A3 -> 46024 | B3: ='1_Raw_Data'!B3 -> 4.35 | C3: ='1_Raw_Data'!C3 -> 4.18 | D3: ='1_Raw_Data'!D3 -> 4.05 | E3: ='1_Raw_Data'!E3 -> 165 | F3: ='1_Raw_Data'!F3 -> 4750 | G3: ='1_Raw_Data'!G3 -> 1.094 | H3: - | I3: -
A4: ='1_Raw_Data'!A4 -> 46027 | B4: ='1_Raw_Data'!B4 -> 4.33 | C4: ='1_Raw_Data'!C4 -> 4.17 | D4: ='1_Raw_Data'!D4 -> 4.06 | E4: ='1_Raw_Data'!E4 -> 166 | F4: ='1_Raw_Data'!F4 -> 4762 | G4: ='1_Raw_Data'!G4 -> 1.0928 | H4: - | I4: -
A5: ='1_Raw_Data'!A5 -> 46028 | B5: ='1_Raw_Data'!B5 -> 4.31 | C5: ='1_Raw_Data'!C5 -> 4.16 | D5: ='1_Raw_Data'!D5 -> 4.05 | E5: ='1_Raw_Data'!E5 -> 168 | F5: ='1_Raw_Data'!F5 -> 4748 | G5: ='1_Raw_Data'!G5 -> 1.0909 | H5: - | I5: -
A6: ='1_Raw_Data'!A6 -> 46029 | B6: ='1_Raw_Data'!B6 -> 4.34 | C6: ='1_Raw_Data'!C6 -> 4.19 | D6: ='1_Raw_Data'!D6 -> 4.07 | E6: ='1_Raw_Data'!E6 -> 169 | F6: ='1_Raw_Data'!F6 -> 4775 | G6: ='1_Raw_Data'!G6 -> 1.0915 | H6: - | I6: -
A7: ='1_Raw_Data'!A7 -> 46030 | B7: ='1_Raw_Data'!B7 -> 4.36 | C7: ='1_Raw_Data'!C7 -> 4.21 | D7: ='1_Raw_Data'!D7 -> 4.08 | E7: ='1_Raw_Data'!E7 -> 171 | F7: ='1_Raw_Data'!F7 -> 4790 | G7: ='1_Raw_Data'!G7 -> 1.0932 | H7: - | I7: -
A8: ='1_Raw_Data'!A8 -> 46031 | B8: ='1_Raw_Data'!B7+('1_Raw_Data'!B10-'1_Raw_Data'!B7)*(1/3) -> 4.3366667 | C8: ='1_Raw_Data'!C7+('1_Raw_Data'!C10-'1_Raw_Data'!C7)*(1/3) -> 4.1866667 | D8: ='1_Raw_Data'!D7+('1_Raw_Data'!D10-'1_Raw_Data'!D7)*(1/3) -> 4.06 | E8: ='1_Raw_Data'!E7+('1_Raw_Data'!E10-'1_Raw_Data'!E7)*(1/3) -> 171.66667 | F8: ='1_Raw_Data'!F7+('1_Raw_Data'!F10-'1_Raw_Data'!F7)*(1/3) -> 4772 | G8: ='1_Raw_Data'!G7+('1_Raw_Data'!G10-'1_Raw_Data'!G7)*(1/3) -> 1.0920333 | H8: INTERP - Stale: all 6 RFs, linear interp Jan 8→Jan 13 (step 1/3) | I8: Linear Interpolation
A9: ='1_Raw_Data'!A9 -> 46034 | B9: ='1_Raw_Data'!B7+('1_Raw_Data'!B10-'1_Raw_Data'!B7)*(2/3) -> 4.3133333 | C9: ='1_Raw_Data'!C7+('1_Raw_Data'!C10-'1_Raw_Data'!C7)*(2/3) -> 4.1633333 | D9: ='1_Raw_Data'!D7+('1_Raw_Data'!D10-'1_Raw_Data'!D7)*(2/3) -> 4.04 | E9: ='1_Raw_Data'!E7+('1_Raw_Data'!E10-'1_Raw_Data'!E7)*(2/3) -> 172.33333 | F9: ='1_Raw_Data'!F7+('1_Raw_Data'!F10-'1_Raw_Data'!F7)*(2/3) -> 4754 | G9: ='1_Raw_Data'!G7+('1_Raw_Data'!G10-'1_Raw_Data'!G7)*(2/3) -> 1.0908667 | H9: INTERP - Stale: all 6 RFs, linear interp Jan 8→Jan 13 (step 2/3) | I9: Linear Interpolation
A10: ='1_Raw_Data'!A10 -> 46035 | B10: ='1_Raw_Data'!B10 -> 4.29 | C10: ='1_Raw_Data'!C10 -> 4.14 | D10: ='1_Raw_Data'!D10 -> 4.02 | E10: ='1_Raw_Data'!E10 -> 173 | F10: ='1_Raw_Data'!F10 -> 4736 | G10: ='1_Raw_Data'!G10 -> 1.0897 | H10: - | I10: -
A11: ='1_Raw_Data'!A11 -> 46036 | B11: ='1_Raw_Data'!B11 -> 4.28 | C11: ='1_Raw_Data'!C11 -> 4.13 | D11: ='1_Raw_Data'!D11 -> 4.01 | E11: ='1_Raw_Data'!E11 -> 174 | F11: ='1_Raw_Data'!F11 -> 4722 | G11: ='1_Raw_Data'!G11 -> 1.0888 | H11: - | I11: -
A12: ='1_Raw_Data'!A12 -> 46037 | B12: ='1_Raw_Data'!B12 -> 4.3 | C12: ='1_Raw_Data'!C12 -> 4.15 | D12: ='1_Raw_Data'!D12 -> 4.03 | E12: ='1_Raw_Data'!E12 -> 176 | F12: ='1_Raw_Data'!F12 -> 4741 | G12: ='1_Raw_Data'!G12 -> 1.0896 | H12: - | I12: -
A13: ='1_Raw_Data'!A13 -> 46038 | B13: ='1_Raw_Data'!B13 -> 4.32 | C13: ='1_Raw_Data'!C13 -> 4.16 | D13: ='1_Raw_Data'!D13 -> 4.04 | E13: ='1_Raw_Data'!E13 -> 177 | F13: ='1_Raw_Data'!F13 -> 4755 | G13: ='1_Raw_Data'!G13 -> 1.0904 | H13: - | I13: -
A14: ='1_Raw_Data'!A14 -> 46042 | B14: ='1_Raw_Data'!B14 -> 4.34 | C14: ='1_Raw_Data'!C14 -> 4.18 | D14: ='1_Raw_Data'!D14 -> 4.05 | E14: ='1_Raw_Data'!E14 -> 179 | F14: ='1_Raw_Data'!F14 -> 4768 | G14: ='1_Raw_Data'!G14 -> 1.0911 | H14: - | I14: -
A15: ='1_Raw_Data'!A15 -> 46043 | B15: ='1_Raw_Data'!B15 -> 4.33 | C15: ='1_Raw_Data'!C15 -> 4.17 | D15: ='1_Raw_Data'!D15 -> 4.05 | E15: ='1_Raw_Data'!E15 -> 181 | F15: ='1_Raw_Data'!F15 -> 4759 | G15: ='1_Raw_Data'!G15 -> 1.0899 | H15: - | I15: -
A16: ='1_Raw_Data'!A16 -> 46044 | B16: ='1_Raw_Data'!B16 -> 4.31 | C16: ='1_Raw_Data'!C16 -> 4.16 | D16: ='1_Raw_Data'!D16 -> 4.04 | E16: ='1_Raw_Data'!E16 -> 182 | F16: ='1_Raw_Data'!F16 -> 4744 | G16: ='1_Raw_Data'!G16 -> 1.088 | H16: - | I16: -
A17: ='1_Raw_Data'!A17 -> 46045 | B17: ='1_Raw_Data'!B17 -> 4.3 | C17: ='1_Raw_Data'!C17 -> 4.15 | D17: ='1_Raw_Data'!D17 -> 4.04 | E17: ='1_Raw_Data'!E17 -> 183 | F17: ='1_Raw_Data'!F17 -> 4728 | G17: ='1_Raw_Data'!G17 -> 1.0872 | H17: - | I17: -
A18: ='1_Raw_Data'!A18 -> 46048 | B18: ='1_Raw_Data'!B18 -> 4.28 | C18: ='1_Raw_Data'!C18 -> 4.13 | D18: ='1_Raw_Data'!D18 -> 4.03 | E18: ='1_Raw_Data'!E18 -> 185 | F18: ='1_Raw_Data'!F18 -> 4705 | G18: ='1_Raw_Data'!G18 -> 1.0855 | H18: - | I18: -
A19: ='1_Raw_Data'!A19 -> 46049 | B19: ='1_Raw_Data'!B19 -> 4.29 | C19: ='1_Raw_Data'!C19 -> 4.14 | D19: ='1_Raw_Data'!D19 -> 4.03 | E19: ='1_Raw_Data'!E19 -> 186 | F19: ='1_Raw_Data'!F19 -> 4718 | G19: ='1_Raw_Data'!G19 -> 1.086 | H19: - | I19: -
A20: ='1_Raw_Data'!A20 -> 46050 | B20: ='1_Raw_Data'!B20 -> 4.27 | C20: ='1_Raw_Data'!C20 -> 4.12 | D20: ='1_Raw_Data'!D20 -> 4.02 | E20: ='1_Raw_Data'!E20 -> 187 | F20: ='1_Raw_Data'!F20 -> 4699 | G20: ='1_Raw_Data'!G20 -> 1.0846 | H20: - | I20: -
A21: ='1_Raw_Data'!A21 -> 46051 | B21: ='1_Raw_Data'!B21 -> 4.26 | C21: ='1_Raw_Data'!C21 -> 4.11 | D21: ='1_Raw_Data'!D21 -> 4.02 | E21: ='1_Raw_Data'!E21 -> 188 | F21: ='1_Raw_Data'!F21 -> 4687 | G21: ='1_Raw_Data'!G21 -> 1.0839 | H21: - | I21: -
... A35: ='1_Raw_Data'!A35 -> 46072 | B35: ='1_Raw_Data'!B35 -> 4.32 | C35: ='1_Raw_Data'!C35 -> 4.17 | D35: ='1_Raw_Data'!D35 -> 4.05 | E35: ='1_Raw_Data'!E35 -> 207 | F35: ='1_Raw_Data'!F35 -> 4755 | G35: ='1_Raw_Data'!G35 -> 1.089 | H35: - | I35: -
A36: ='1_Raw_Data'!A36 -> 46073 | B36: ='1_Raw_Data'!B35+('1_Raw_Data'!B37-'1_Raw_Data'!B35)*(1/4) -> 4.27 | C36: ='1_Raw_Data'!C35+('1_Raw_Data'!C37-'1_Raw_Data'!C35)*(1/4) -> 4.1225 | D36: ='1_Raw_Data'!D35+('1_Raw_Data'!D37-'1_Raw_Data'!D35)*(1/4) -> 4.0175 | E36: ='1_Raw_Data'!E36 -> 210 | F36: ='1_Raw_Data'!F36 -> 4680 | G36: ='1_Raw_Data'!G36 -> 1.0878 | H36: INTERP - Discontinuity: USD 2Y/5Y/10Y only, linear interp Feb 19→Feb 23 (step 1/4) | I36: Linear Interpolation
A37: ='1_Raw_Data'!A37 -> 46076 | B37: ='1_Raw_Data'!B37 -> 4.12 | C37: ='1_Raw_Data'!C37 -> 3.98 | D37: ='1_Raw_Data'!D37 -> 3.92 | E37: ='1_Raw_Data'!E37 -> 212 | F37: ='1_Raw_Data'!F37 -> 4692 | G37: ='1_Raw_Data'!G37 -> 1.0884 | H37: - | I37: -
A38: ='1_Raw_Data'!A38 -> 46077 | B38: ='1_Raw_Data'!B38 -> 4.13 | C38: ='1_Raw_Data'!C38 -> 3.99 | D38: ='1_Raw_Data'!D38 -> 3.93 | E38: =('1_Raw_Data'!E37+'1_Raw_Data'!E39)/2 -> 213.5 | F38: ='1_Raw_Data'!F38 -> 4701 | G38: ='1_Raw_Data'!G38 -> 1.0889 | H38: INTERP - Missing: CORP BBB = (Feb 23 + Feb 25) / 2 | I38: Linear Interpolation
A39: ='1_Raw_Data'!A39 -> 46078 | B39: ='1_Raw_Data'!B39 -> 4.14 | C39: =('1_Raw_Data'!C38+'1_Raw_Data'!C40)/2 -> 4 | D39: ='1_Raw_Data'!D39 -> 3.94 | E39: ='1_Raw_Data'!E39 -> 215 | F39: ='1_Raw_Data'!F39 -> 4715 | G39: ='1_Raw_Data'!G39 -> 1.0896 | H39: INTERP - Spike+Tenor Cross: USD 5Y = (Feb 24 + Feb 26) / 2; resolves tenor crossing | I39: Linear Interpolation
A40: ='1_Raw_Data'!A40 -> 46079 | B40: ='1_Raw_Data'!B40 -> 4.15 | C40: ='1_Raw_Data'!C40 -> 4.01 | D40: ='1_Raw_Data'!D40 -> 3.95 | E40: ='1_Raw_Data'!E40 -> 216 | F40: ='1_Raw_Data'!F40 -> 4722 | G40: ='1_Raw_Data'!G40 -> 1.0903 | H40: - | I40: -
A41: ='1_Raw_Data'!A41 -> 46080 | B41: ='1_Raw_Data'!B41 -> 4.16 | C41: ='1_Raw_Data'!C41 -> 4.02 | D41: ='1_Raw_Data'!D41 -> 3.96 | E41: ='1_Raw_Data'!E41 -> 217 | F41: ='1_Raw_Data'!F41 -> 4734 | G41: ='1_Raw_Data'!G41 -> 1.0912 | H41: - | I41: -
A42: ='1_Raw_Data'!A42 -> 46083 | B42: ='1_Raw_Data'!B42 -> 4.18 | C42: ='1_Raw_Data'!C42 -> 4.04 | D42: ='1_Raw_Data'!D42 -> 3.97 | E42: ='1_Raw_Data'!E42 -> 218 | F42: ='1_Raw_Data'!F42 -> 4746 | G42: ='1_Raw_Data'!G42 -> 1.092 | H42: - | I42: -
A43: ='1_Raw_Data'!A43 -> 46084 | B43: ='1_Raw_Data'!B43 -> 4.19 | C43: ='1_Raw_Data'!C43 -> 4.05 | D43: ='1_Raw_Data'!D43 -> 3.98 | E43: ='1_Raw_Data'!E42 -> 218 | F43: ='1_Raw_Data'!F43 -> 4760 | G43: ='1_Raw_Data'!G43 -> 1.0929 | H43: FFILL - Negative Spread: CORP BBB forward filled from Mar 2 (218 bps) | I43: Forward Fill
A44: ='1_Raw_Data'!A44 -> 46085 | B44: ='1_Raw_Data'!B44 -> 4.2 | C44: ='1_Raw_Data'!C44 -> 4.06 | D44: ='1_Raw_Data'!D44 -> 3.99 | E44: ='1_Raw_Data'!E44 -> 219 | F44: ='1_Raw_Data'!F44 -> 4772 | G44: ='1_Raw_Data'!G44 -> 1.0937 | H44: - | I44: -
A45: ='1_Raw_Data'!A45 -> 46086 | B45: ='1_Raw_Data'!B45 -> 4.22 | C45: ='1_Raw_Data'!C45 -> 4.08 | D45: ='1_Raw_Data'!D45 -> 4 | E45: ='1_Raw_Data'!E45 -> 220 | F45: ='1_Raw_Data'!F45 -> 4788 | G45: ='1_Raw_Data'!G45 -> 1.0949 | H45: - | I45: -
A46: ='1_Raw_Data'!A46 -> 46087 | B46: ='1_Raw_Data'!B46 -> 4.23 | C46: ='1_Raw_Data'!C46 -> 4.09 | D46: ='1_Raw_Data'!D46 -> 4.01 | E46: ='1_Raw_Data'!E46 -> 221 | F46: ='1_Raw_Data'!F46 -> 4795 | G46: =ROUND(('1_Raw_Data'!G45+'1_Raw_Data'!G47)/2,4) -> 1.0956 | H46: INTERP - Spike: EURUSD = (Mar 5 + Mar 9) / 2 | I46: Linear Interpolation
A47: ='1_Raw_Data'!A47 -> 46090 | B47: ='1_Raw_Data'!B47 -> 4.24 | C47: ='1_Raw_Data'!C47 -> 4.1 | D47: ='1_Raw_Data'!D47 -> 4.02 | E47: ='1_Raw_Data'!E47 -> 222 | F47: ='1_Raw_Data'!F47 -> 4802 | G47: ='1_Raw_Data'!G47 -> 1.0962 | H47: - | I47: -
A48: ='1_Raw_Data'!A48 -> 46091 | B48: ='1_Raw_Data'!B48 -> 4.25 | C48: ='1_Raw_Data'!C48 -> 4.11 | D48: ='1_Raw_Data'!D48 -> 4.02 | E48: ='1_Raw_Data'!E48 -> 223 | F48: ='1_Raw_Data'!F48 -> 4810 | G48: ='1_Raw_Data'!G48 -> 1.0955 | H48: - | I48: -
A49: ='1_Raw_Data'!A49 -> 46092 | B49: ='1_Raw_Data'!B49 -> 4.26 | C49: ='1_Raw_Data'!C49 -> 4.12 | D49: ='1_Raw_Data'!D49 -> 4.03 | E49: ='1_Raw_Data'!E49 -> 224 | F49: ='1_Raw_Data'!F49 -> 4822 | G49: ='1_Raw_Data'!G49 -> 1.096 | H49: - | I49: -
A50: ='1_Raw_Data'!A50 -> 46093 | B50: ='1_Raw_Data'!B50 -> 4.27 | C50: ='1_Raw_Data'!C50 -> 4.13 | D50: ='1_Raw_Data'!D50 -> 4.04 | E50: ='1_Raw_Data'!E50 -> 225 | F50: ='1_Raw_Data'!F50 -> 4835 | G50: ='1_Raw_Data'!G50 -> 1.0971 | H50: - | I50: -
A53: Assumptions
A54: # | B54: Assumption
A55: 1 | B55: Business day calendar: Jan 10-11 are weekend days and are absent from the dataset. Jan 9 and Jan 12 are the two consecutive stale business days following Jan 8.
...
