Workbook

Sheet Summary
B2: DATA QUALITY ANALYSIS - RISK FACTOR TIME SERIES
B3: Market Risk Management - Class 8 Assignment
B6: Risk Factors Analyzed: | E6: RF1: BAMLC0A4CBBBEY (Credit Spread) | RF2: S&P 500 (Equity) | RF3: EUR/USD (FX)
B7: Analysis Periods: | E7: Year 2020 | Year 2021 | Year 2025
B8: Methodologies: | E8: Standard Z-Score | Robust Z-Score | EWMA Z-Score (N=30, λ=0.9)
B9: Outlier Threshold: | E9: Z > 3.0 (flagged) | Z > 6.0 (high confidence)
B10: Return Conventions: | E10: Credit Spread: Absolute Returns (x100 bps) | Equity & FX: Log Returns
B12: SUMMARY STATISTICS
B13: Risk Factor | C13: Year | D13: Total Obs | E13: Missing | F13: Stale | G13: Z>3 Outliers | H13: Rob Z>3 Outliers | I13: Max Z-Score | J13: Max Robust Z | K13: Max EWMA Z
B14: RF1: Credit Spread | C14: 2020 | D14: =COUNTA('RF1 CreditSpread'!C9:C263) -> 249 | E14: =COUNTIF('RF1 CreditSpread'!K9:K263,"MISSING") -> 5 | F14: =COUNTIF('RF1 CreditSpread'!L9:L263,"STALE") -> 18 | G14: =COUNTIF('RF1 CreditSpread'!H9:H263,"OUTLIER") -> 14 | H14: =COUNTIF('RF1 CreditSpread'!I9:I263,"OUTLIER") -> 62 | I14: =ROUND(MAX('RF1 CreditSpread'!E9:E263),2) -> 7.99 | J14: =ROUND(MAX('RF1 CreditSpread'!F9:F263),2) -> 28.67 | K14: =ROUND(MAX('RF1 CreditSpread'!G9:G263),2) -> 2.54
B15: RF1: Credit Spread | C15: 2021 | D15: =COUNTA('RF1 CreditSpread'!C266:C521) -> 249 | E15: =COUNTIF('RF1 CreditSpread'!K266:K521,"MISSING") -> 4 | F15: =COUNTIF('RF1 CreditSpread'!L266:L521,"STALE") -> 31 | G15: =COUNTIF('RF1 CreditSpread'!H266:H521,"OUTLIER") -> 0 | H15: =COUNTIF('RF1 CreditSpread'!I266:I521,"OUTLIER") -> 1 | I15: =ROUND(MAX('RF1 CreditSpread'!E266:E521),2) -> 1.11 | J15: =ROUND(MAX('RF1 CreditSpread'!F266:F521),2) -> 4.05 | K15: =ROUND(MAX('RF1 CreditSpread'!G266:G521),2) -> 2.5
B16: RF1: Credit Spread | C16: 2025 | D16: =COUNTA('RF1 CreditSpread'!C524:C786) -> 243 | E16: =COUNTIF('RF1 CreditSpread'!K524:K786,"MISSING") -> 17 | F16: =COUNTIF('RF1 CreditSpread'!L524:L786,"STALE") -> 48 | G16: =COUNTIF('RF1 CreditSpread'!H524:H786,"OUTLIER") -> 2 | H16: =COUNTIF('RF1 CreditSpread'!I524:I786,"OUTLIER") -> 15 | I16: =ROUND(MAX('RF1 CreditSpread'!E524:E786),2) -> 10.72 | J16: =ROUND(MAX('RF1 CreditSpread'!F524:F786),2) -> 38.45 | K16: =ROUND(MAX('RF1 CreditSpread'!G524:G786),2) -> 3.05
B17: RF2: S&P 500 | C17: 2020 | D17: =COUNTA('RF2 SP500'!C9:C267) -> 254 | E17: =COUNTIF('RF2 SP500'!K9:K267,"MISSING") -> 4 | F17: =COUNTIF('RF2 SP500'!L9:L267,"STALE") -> 0 | G17: =COUNTIF('RF2 SP500'!H9:H267,"OUTLIER") -> 11 | H17: =COUNTIF('RF2 SP500'!I9:I267,"OUTLIER") -> 31 | I17: =ROUND(MAX('RF2 SP500'!E9:E267),2) -> 7.69 | J17: =ROUND(MAX('RF2 SP500'!F9:F267),2) -> 13.43 | K17: =ROUND(MAX('RF2 SP500'!G9:G267),2) -> 2.71
B18: RF2: S&P 500 | C18: 2021 | D18: =COUNTA('RF2 SP500'!C270:C526) -> 251 | E18: =COUNTIF('RF2 SP500'!K270:K526,"MISSING") -> 3 | F18: =COUNTIF('RF2 SP500'!L270:L526,"STALE") -> 0 | G18: =COUNTIF('RF2 SP500'!H270:H526,"OUTLIER") -> 0 | H18: =COUNTIF('RF2 SP500'!I270:I526,"OUTLIER") -> 3 | I18: =ROUND(MAX('RF2 SP500'!E270:E526),2) -> 2.16 | J18: =ROUND(MAX('RF2 SP500'!F270:F526),2) -> 3.72 | K18: =ROUND(MAX('RF2 SP500'!G270:G526),2) -> 2.84
B19: RF2: S&P 500 | C19: 2025 | D19: =COUNTA('RF2 SP500'!C529:C787) -> 243 | E19: =COUNTIF('RF2 SP500'!K529:K787,"MISSING") -> 13 | F19: =COUNTIF('RF2 SP500'!L529:L787,"STALE") -> 0 | G19: =COUNTIF('RF2 SP500'!H529:H787,"OUTLIER") -> 5 | H19: =COUNTIF('RF2 SP500'!I529:I787,"OUTLIER") -> 12 | I19: =ROUND(MAX('RF2 SP500'!E529:E787),2) -> 5.98 | J19: =ROUND(MAX('RF2 SP500'!F529:F787),2) -> 10.6 | K19: =ROUND(MAX('RF2 SP500'!G529:G787),2) -> 2.85
B20: RF3: EUR/USD | C20: 2020 | D20: =COUNTA('RF3 EURUSD'!C10:C264) -> 248 | E20: =COUNTIF('RF3 EURUSD'!K10:K264,"MISSING") -> 7 | F20: =COUNTIF('RF3 EURUSD'!L10:L264,"STALE") -> 5 | G20: =COUNTIF('RF3 EURUSD'!H10:H264,"OUTLIER") -> 3 | H20: =COUNTIF('RF3 EURUSD'!I10:I264,"OUTLIER") -> 20 | I20: =ROUND(MAX('RF3 EURUSD'!E10:E264),2) -> 4.71 | J20: =ROUND(MAX('RF3 EURUSD'!F10:F264),2) -> 7.91 | K20: =ROUND(MAX('RF3 EURUSD'!G10:G264),2) -> 2.35
B21: RF3: EUR/USD | C21: 2021 | D21: =COUNTA('RF3 EURUSD'!C269:C522) -> 248 | E21: =COUNTIF('RF3 EURUSD'!K268:K522,"MISSING") -> 4 | F21: =COUNTIF('RF3 EURUSD'!L269:L522,"STALE") -> 4 | G21: =COUNTIF('RF3 EURUSD'!H269:H522,"OUTLIER") -> 0 | H21: =COUNTIF('RF3 EURUSD'!I269:I522,"OUTLIER") -> 2 | I21: =ROUND(MAX('RF3 EURUSD'!E269:E522),2) -> 2.15 | J21: =ROUND(MAX('RF3 EURUSD'!F269:F522),2) -> 3.57 | K21: =ROUND(MAX('RF3 EURUSD'!G269:G522),2) -> 2.55
B22: RF3: EUR/USD | C22: 2025 | D22: =COUNTA('RF3 EURUSD'!C528:C785) -> 244 | E22: =COUNTIF('RF3 EURUSD'!K527:K785,"MISSING") -> 12 | F22: =COUNTIF('RF3 EURUSD'!L528:L785,"STALE") -> 25 | G22: =COUNTIF('RF3 EURUSD'!H528:H785,"OUTLIER") -> 4 | H22: =COUNTIF('RF3 EURUSD'!I528:I785,"OUTLIER") -> 12 | I22: =ROUND(MAX('RF3 EURUSD'!E528:E785),2) -> 12.76 | J22: =ROUND(MAX('RF3 EURUSD'!F528:F785),2) -> 21.48 | K22: =ROUND(MAX('RF3 EURUSD'!G528:G785),2) -> 3.13
B25: METHODOLOGY & RETURN TYPE JUSTIFICATION
B26: RETURN TYPE SELECTION
B27: Risk Factor | C27: Return Type | D27: Justification
B28: RF1: BAMLC0A4CBBBEY Credit Spread | C28: Absolute Returns (×100 bps) | D28: Credit spreads are bounded below by zero and can cross zero or mean-revert. Log returns at low spread levels amplify shocks and can produce negative simulated spreads. Absolute changes capture the economic meaning of bps widening regardless of spread level. Market convention for spread instruments uses absolute returns.
B29: RF2: S&P 500 Index | C29: Log Returns (ln-relatives) | D29: Equity indices are multiplicative - a 10% move is proportionally equivalent at 3,000 or 7,000. Log returns ensure non-negativity of simulated levels and are consistent with lognormal/GBM assumptions. They handle large moves without producing negative scenario values.
B30: RF3: EUR/USD FX Rate | C30: Log Returns (ln-relatives) | D30: FX rates follow multiplicative dynamics, so proportional shocks are more meaningful than absolute ones. Log returns prevent simulated rates from going negative. For major FX pairs, log returns are closer to i.i.d. normal than absolute changes in practice.
B32: Z-SCORE METHODS
B33: Method | C33: Properties & Use Case
B34: Standard Z-Score | C34: Simple and widely used. Assumes constant volatility. Can over-flag in volatile regimes (e.g. COVID-19 March 2020). Threshold: Z > 3 = outlier; Z > 6 = high confidence.
B35: Robust Z-Score | C35: Less sensitive to outliers since median and MAD are not affected by extreme values. Flags two consecutive large Z-scores rather than single-day spikes. Preferred for heavy-tailed or clustered return series.
B36: EWMA Z-Score | C36: Time-varying volatility with decay lambda=0.9, lookback N=30. Reduces false flags during already-volatile periods since the denominator rises with the regime. Reported for the five worst Z-score points per year.
B38: DATA QUALITY TAXONOMY
B39: Issue Type | C39: Detection Method | F39: Remediation Approach
B40: Missing Data | C40: NULL/NaN values. Causes: market holidays, system failures, instrument not yet listed. | F40: For 1-2 day gaps: forward fill or linear interpolation. For scheduled market holidays: carry-forward is standard. Document all fills.
B41: Stale Data | C41: 2+ consecutive observations with zero absolute change. Stale data dampens measured volatility and understates VaR. | F41: For isolated 1-day stale points: accept if consistent with low liquidity. For clusters of 2+ days: apply Brownian Bridge between last valid and next valid point. Flag in VaR documentation.
B42: Outliers | C42: Z or Robust Z > 3.0. May be data errors or genuine market events (e.g. COVID-19 March 2020). | F42: Cross-check against alternative sources. For confirmed market events (e.g. COVID): retain and flag as stress period. For data errors: replace using Brownian Bridge or cohort model. High-exposure outliers go to specialist review.
B45: REMEDIATION PLAN: DATA QUALITY ISSUES & PROPOSED FIXES
B46: # | C46: Risk Factor | D46: Year | E46: Issue Type | F46: Description | L46: Priority
B47: 1 | C47: RF1: Credit Spread (BAMLC0A4CBBBEY) | D47: 2020 | E47: Missing Data | F47: 3 missing observations on US market holidays: 2020-01-01 (New Year), 2020-11-27 (Thanksgiving Friday), 2020-12-25 (Christmas). FRED returns NA on these dates by construction. | L47: Low
B48: 2 | C48: RF1: Credit Spread (BAMLC0A4CBBBEY) | D48: 2020 | E48: Stale Data | F48: 48 stale observations in 2020 (zero absolute return). Credit spread indices only update when trades occur; stale prices on low-liquidity days are expected for BAMLC0A4CBBBEY. Clusters concentrated in Jan-Feb and Nov-Dec 2020. | L48: Medium
B49: 3 | C49: RF1: Credit Spread (BAMLC0A4CBBBEY) | D49: 2020 | E49: Outliers | F49: 11 observations exceed Z=3 in 2020, concentrated in March 2020 (COVID-19 credit spread spike). Max Z-score: 10.13 on 2020-03-20 (spread reached 6.91%). Robust Z flags 24 observations (max RobZ=18.55). | L49: High
B50: 4 | C50: RF1: Credit Spread (BAMLC0A4CBBBEY) | D50: 2021 | E50: Stale Data | F50: 44 stale observations in 2021. Same pattern as 2020: index stale on low-activity days around holidays and low-volume periods in summer and December. | L50: Medium
...

Sheet RF1 CreditSpread
B1: RF1: BAMLC0A4CBBBEY (Credit Spread)
B2: Return Type: Absolute (×100 bps) | Z-Score Threshold: 3.0 | EWMA Parameters: N=30, λ=0.9
B4: GLOBAL STATISTICS (Full Series) | E4: Mean Return | F4: Std Dev (σ) | G4: Median Return | H4: Scaled MAD (σ̂) | I4: Cutoff (c) | M4: MAD Helper (|r - median|)
E5: =AVERAGE(D9:D263,D266:D521,D524:D786) -> 0.2291372 | F5: =STDEV(D9:D263,D266:D521,D524:D786) -> 10.614336 | G5: =MEDIAN(D9:D263,D266:D521,D524:D786) -> 0 | H5: =_xlfn.AGGREGATE(16,6,M9:M786,0.5)/0.6745 -> 2.9651594 | I5: 3
B7: ="YEAR 2020 | Observations: "&COUNTA(C9:C263)&" | Missing: "&COUNTIF(K9:K263,"MISSING")&" | Stale: "&COUNTIF(L9:L263,"STALE")&" | Z>3 Outliers: "&COUNTIF(H9:H263,"OUTLIER")&" | Robust Z>3: "&COUNTIF(I9:I263,"OUTLIER") -> YEAR 2020 | Observations: 249 | Missing: 5 | Stale: 18 | Z>3 Outliers: 14 | Robust Z>3: 62
B8: Date | C8: Level | D8: Return | E8: Z-Score | F8: Robust Z | G8: EWMA Z | H8: Z>3 Flag | I8: RobZ>3 | J8: EWMA>3 | K8: Missing? | L8: Stale? | M8: |r - median|
B9: 43831 | E9: =IF(D9="","",ABS(D9-$E$5)/$F$5) | F9: =IF(D9="","",ABS(D9-$G$5)/$H$5) | G9: =IF(D9="","",ABS(D9-$E$5)/$F$5) | H9: =IF(E9="","",IF(E9>$I$5,"OUTLIER","")) | I9: =IF(F9="","",IF(F9>$I$5,"OUTLIER","")) | J9: =IF(G9="","",IF(G9>$I$5,"OUTLIER","")) | K9: =IF(C9="","MISSING","") -> MISSING | M9: =IF(D9="","",ABS(D9-G$5))
B10: 43832 | C10: 3.17 | D10: =IF(OR(C10="",C9=""),"",(C10-C9)*100) | E10: =IF(D10="","",ABS(D10-$E$5)/$F$5) | F10: =IF(D10="","",ABS(D10-$G$5)/$H$5) | G10: =IF(D10="","",ABS(D10-$E$5)/SQRT(0.9*(IF(G9="",($F$5)^2,(ABS(D9-$E$5)/MAX(G9,0.0000000001))^2))+0.1*(D10-$E$5)^2)) | H10: =IF(E10="","",IF(E10>$I$5,"OUTLIER","")) | I10: =IF(F10="","",IF(F10>$I$5,"OUTLIER","")) | J10: =IF(G10="","",IF(G10>$I$5,"OUTLIER","")) | K10: =IF(C10="","MISSING","") | L10: =IF(AND(C10<>"",C9<>"",C10=C9),"STALE","") | M10: =IF(D10="","",ABS(D10-G$5))
B11: 43833 | C11: 3.11 | D11: =IF(OR(C11="",C10=""),"",(C11-C10)*100) -> -6 | E11: =IF(D11="","",ABS(D11-$E$5)/$F$5) -> 0.58686073 | F11: =IF(D11="","",ABS(D11-$G$5)/$H$5) -> 2.0235 | G11: =IF(D11="","",ABS(D11-$E$5)/SQRT(0.9*(IF(G10="",($F$5)^2,(ABS(D10-$E$5)/MAX(G10,0.0000000001))^2))+0.1*(D11-$E$5)^2)) -> 0.60709857 | H11: =IF(E11="","",IF(E11>$I$5,"OUTLIER","")) | I11: =IF(F11="","",IF(F11>$I$5,"OUTLIER","")) | J11: =IF(G11="","",IF(G11>$I$5,"OUTLIER","")) | K11: =IF(C11="","MISSING","") | L11: =IF(AND(C11<>"",C10<>"",C11=C10),"STALE","") | M11: =IF(D11="","",ABS(D11-G$5)) -> 6
B12: 43836 | C12: 3.14 | D12: =IF(OR(C12="",C11=""),"",(C12-C11)*100) -> 3 | E12: =IF(D12="","",ABS(D12-$E$5)/$F$5) -> 0.26104909 | F12: =IF(D12="","",ABS(D12-$G$5)/$H$5) -> 1.01175 | G12: =IF(D12="","",ABS(D12-$E$5)/SQRT(0.9*(IF(G11="",($F$5)^2,(ABS(D11-$E$5)/MAX(G11,0.0000000001))^2))+0.1*(D12-$E$5)^2)) -> 0.28351276 | H12: =IF(E12="","",IF(E12>$I$5,"OUTLIER","")) | I12: =IF(F12="","",IF(F12>$I$5,"OUTLIER","")) | J12: =IF(G12="","",IF(G12>$I$5,"OUTLIER","")) | K12: =IF(C12="","MISSING","") | L12: =IF(AND(C12<>"",C11<>"",C12=C11),"STALE","") | M12: =IF(D12="","",ABS(D12-G$5)) -> 3
B13: 43837 | C13: 3.15 | D13: =IF(OR(C13="",C12=""),"",(C13-C12)*100) -> 1 | E13: =IF(D13="","",ABS(D13-$E$5)/$F$5) -> 0.072624682 | F13: =IF(D13="","",ABS(D13-$G$5)/$H$5) -> 0.33725 | G13: =IF(D13="","",ABS(D13-$E$5)/SQRT(0.9*(IF(G12="",($F$5)^2,(ABS(D12-$E$5)/MAX(G12,0.0000000001))^2))+0.1*(D13-$E$5)^2)) -> 0.083111932 | H13: =IF(E13="","",IF(E13>$I$5,"OUTLIER","")) | I13: =IF(F13="","",IF(F13>$I$5,"OUTLIER","")) | J13: =IF(G13="","",IF(G13>$I$5,"OUTLIER","")) | K13: =IF(C13="","MISSING","") | L13: =IF(AND(C13<>"",C12<>"",C13=C12),"STALE","") | M13: =IF(D13="","",ABS(D13-G$5)) -> 1
B14: 43838 | C14: 3.19 | D14: =IF(OR(C14="",C13=""),"",(C14-C13)*100) -> 4 | E14: =IF(D14="","",ABS(D14-$E$5)/$F$5) -> 0.35526129 | F14: =IF(D14="","",ABS(D14-$G$5)/$H$5) -> 1.349 | G14: =IF(D14="","",ABS(D14-$E$5)/SQRT(0.9*(IF(G13="",($F$5)^2,(ABS(D13-$E$5)/MAX(G13,0.0000000001))^2))+0.1*(D14-$E$5)^2)) -> 0.42467221 | H14: =IF(E14="","",IF(E14>$I$5,"OUTLIER","")) | I14: =IF(F14="","",IF(F14>$I$5,"OUTLIER","")) | J14: =IF(G14="","",IF(G14>$I$5,"OUTLIER","")) | K14: =IF(C14="","MISSING","") | L14: =IF(AND(C14<>"",C13<>"",C14=C13),"STALE","") | M14: =IF(D14="","",ABS(D14-G$5)) -> 4
B15: 43839 | C15: 3.16 | D15: =IF(OR(C15="",C14=""),"",(C15-C14)*100) -> -3 | E15: =IF(D15="","",ABS(D15-$E$5)/$F$5) -> 0.30422413 | F15: =IF(D15="","",ABS(D15-$G$5)/$H$5) -> 1.01175 | G15: =IF(D15="","",ABS(D15-$E$5)/SQRT(0.9*(IF(G14="",($F$5)^2,(ABS(D14-$E$5)/MAX(G14,0.0000000001))^2))+0.1*(D15-$E$5)^2)) -> 0.38054909 | H15: =IF(E15="","",IF(E15>$I$5,"OUTLIER","")) | I15: =IF(F15="","",IF(F15>$I$5,"OUTLIER","")) | J15: =IF(G15="","",IF(G15>$I$5,"OUTLIER","")) | K15: =IF(C15="","MISSING","") | L15: =IF(AND(C15<>"",C14<>"",C15=C14),"STALE","") | M15: =IF(D15="","",ABS(D15-G$5)) -> 3
B16: 43840 | C16: 3.13 | D16: =IF(OR(C16="",C15=""),"",(C16-C15)*100) -> -3 | E16: =IF(D16="","",ABS(D16-$E$5)/$F$5) -> 0.30422413 | F16: =IF(D16="","",ABS(D16-$G$5)/$H$5) -> 1.01175 | G16: =IF(D16="","",ABS(D16-$E$5)/SQRT(0.9*(IF(G15="",($F$5)^2,(ABS(D15-$E$5)/MAX(G15,0.0000000001))^2))+0.1*(D16-$E$5)^2)) -> 0.39794511 | H16: =IF(E16="","",IF(E16>$I$5,"OUTLIER","")) | I16: =IF(F16="","",IF(F16>$I$5,"OUTLIER","")) | J16: =IF(G16="","",IF(G16>$I$5,"OUTLIER","")) | K16: =IF(C16="","MISSING","") | L16: =IF(AND(C16<>"",C15<>"",C16=C15),"STALE","") | M16: =IF(D16="","",ABS(D16-G$5)) -> 3
B17: 43843 | C17: 3.14 | D17: =IF(OR(C17="",C16=""),"",(C17-C16)*100) -> 1 | E17: =IF(D17="","",ABS(D17-$E$5)/$F$5) -> 0.072624682 | F17: =IF(D17="","",ABS(D17-$G$5)/$H$5) -> 0.33725 | G17: =IF(D17="","",ABS(D17-$E$5)/SQRT(0.9*(IF(G16="",($F$5)^2,(ABS(D16-$E$5)/MAX(G16,0.0000000001))^2))+0.1*(D17-$E$5)^2)) -> 0.10008635 | H17: =IF(E17="","",IF(E17>$I$5,"OUTLIER","")) | I17: =IF(F17="","",IF(F17>$I$5,"OUTLIER","")) | J17: =IF(G17="","",IF(G17>$I$5,"OUTLIER","")) | K17: =IF(C17="","MISSING","") | L17: =IF(AND(C17<>"",C16<>"",C17=C16),"STALE","") | M17: =IF(D17="","",ABS(D17-G$5)) -> 1
B18: 43844 | C18: 3.12 | D18: =IF(OR(C18="",C17=""),"",(C18-C17)*100) -> -2 | E18: =IF(D18="","",ABS(D18-$E$5)/$F$5) -> 0.21001192 | F18: =IF(D18="","",ABS(D18-$G$5)/$H$5) -> 0.6745 | G18: =IF(D18="","",ABS(D18-$E$5)/SQRT(0.9*(IF(G17="",($F$5)^2,(ABS(D17-$E$5)/MAX(G17,0.0000000001))^2))+0.1*(D18-$E$5)^2)) -> 0.3036698 | H18: =IF(E18="","",IF(E18>$I$5,"OUTLIER","")) | I18: =IF(F18="","",IF(F18>$I$5,"OUTLIER","")) | J18: =IF(G18="","",IF(G18>$I$5,"OUTLIER","")) | K18: =IF(C18="","MISSING","") | L18: =IF(AND(C18<>"",C17<>"",C18=C17),"STALE","") | M18: =IF(D18="","",ABS(D18-G$5)) -> 2
B19: 43845 | C19: 3.09 | D19: =IF(OR(C19="",C18=""),"",(C19-C18)*100) -> -3 | E19: =IF(D19="","",ABS(D19-$E$5)/$F$5) -> 0.30422413 | F19: =IF(D19="","",ABS(D19-$G$5)/$H$5) -> 1.01175 | G19: =IF(D19="","",ABS(D19-$E$5)/SQRT(0.9*(IF(G18="",($F$5)^2,(ABS(D18-$E$5)/MAX(G18,0.0000000001))^2))+0.1*(D19-$E$5)^2)) -> 0.45878651 | H19: =IF(E19="","",IF(E19>$I$5,"OUTLIER","")) | I19: =IF(F19="","",IF(F19>$I$5,"OUTLIER","")) | J19: =IF(G19="","",IF(G19>$I$5,"OUTLIER","")) | K19: =IF(C19="","MISSING","") | L19: =IF(AND(C19<>"",C18<>"",C19=C18),"STALE","") | M19: =IF(D19="","",ABS(D19-G$5)) -> 3
B20: 43846 | C20: 3.1 | D20: =IF(OR(C20="",C19=""),"",(C20-C19)*100) -> 1 | E20: =IF(D20="","",ABS(D20-$E$5)/$F$5) -> 0.072624682 | F20: =IF(D20="","",ABS(D20-$G$5)/$H$5) -> 0.33725 | G20: =IF(D20="","",ABS(D20-$E$5)/SQRT(0.9*(IF(G19="",($F$5)^2,(ABS(D19-$E$5)/MAX(G19,0.0000000001))^2))+0.1*(D20-$E$5)^2)) -> 0.11536943 | H20: =IF(E20="","",IF(E20>$I$5,"OUTLIER","")) | I20: =IF(F20="","",IF(F20>$I$5,"OUTLIER","")) | J20: =IF(G20="","",IF(G20>$I$5,"OUTLIER","")) | K20: =IF(C20="","MISSING","") | L20: =IF(AND(C20<>"",C19<>"",C20=C19),"STALE","") | M20: =IF(D20="","",ABS(D20-G$5)) -> 1
B21: 43847 | C21: 3.1 | D21: =IF(OR(C21="",C20=""),"",(C21-C20)*100) -> 0 | E21: =IF(D21="","",ABS(D21-$E$5)/$F$5) -> 0.02158752 | F21: =IF(D21="","",ABS(D21-$G$5)/$H$5) -> 0 | G21: =IF(D21="","",ABS(D21-$E$5)/SQRT(0.9*(IF(G20="",($F$5)^2,(ABS(D20-$E$5)/MAX(G20,0.0000000001))^2))+0.1*(D21-$E$5)^2)) -> 0.03614595 | H21: =IF(E21="","",IF(E21>$I$5,"OUTLIER","")) | I21: =IF(F21="","",IF(F21>$I$5,"OUTLIER","")) | J21: =IF(G21="","",IF(G21>$I$5,"OUTLIER","")) | K21: =IF(C21="","MISSING","") | L21: =IF(AND(C21<>"",C20<>"",C21=C20),"STALE","") -> STALE | M21: =IF(D21="","",ABS(D21-G$5)) -> 0
... B227: 44145 | C227: 2.95 | D227: =IF(OR(C227="",C226=""),"",(C227-C226)*100) -> -3 | E227: =IF(D227="","",ABS(D227-$E$5)/$F$5) -> 0.30422413 | F227: =IF(D227="","",ABS(D227-$G$5)/$H$5) -> 1.01175 | G227: =IF(D227="","",ABS(D227-$E$5)/SQRT(0.9*(IF(G226="",($F$5)^2,(ABS(D226-$E$5)/MAX(G226,0.0000000001))^2))+0.1*(D227-$E$5)^2)) -> 0.36548246 | H227: =IF(E227="","",IF(E227>$I$5,"OUTLIER","")) | I227: =IF(F227="","",IF(F227>$I$5,"OUTLIER","")) | J227: =IF(G227="","",IF(G227>$I$5,"OUTLIER","")) | K227: =IF(C227="","MISSING","") | L227: =IF(AND(C227<>"",C226<>"",C227=C226),"STALE","") | M227: =IF(D227="","",ABS(D227-G$5)) -> 3
B228: 44146 | D228: =IF(OR(C228="",C227=""),"",(C228-C227)*100) | E228: =IF(D228="","",ABS(D228-$E$5)/$F$5) | F228: =IF(D228="","",ABS(D228-$G$5)/$H$5) | G228: =IF(D228="","",ABS(D228-$E$5)/SQRT(0.9*(IF(G227="",($F$5)^2,(ABS(D227-$E$5)/MAX(G227,0.0000000001))^2))+0.1*(D228-$E$5)^2)) | H228: =IF(E228="","",IF(E228>$I$5,"OUTLIER","")) | I228: =IF(F228="","",IF(F228>$I$5,"OUTLIER","")) | J228: =IF(G228="","",IF(G228>$I$5,"OUTLIER","")) | K228: =IF(C228="","MISSING","") -> MISSING | L228: =IF(AND(C228<>"",C227<>"",C228=C227),"STALE","") | M228: =IF(D228="","",ABS(D228-G$5))
B229: 44147 | C229: 2.95 | D229: =IF(OR(C229="",C228=""),"",(C229-C228)*100) | E229: =IF(D229="","",ABS(D229-$E$5)/$F$5) | F229: =IF(D229="","",ABS(D229-$G$5)/$H$5) | G229: =IF(D229="","",ABS(D229-$E$5)/SQRT(0.9*(IF(G228="",($F$5)^2,(ABS(D228-$E$5)/MAX(G228,0.0000000001))^2))+0.1*(D229-$E$5)^2)) | H229: =IF(E229="","",IF(E229>$I$5,"OUTLIER","")) | I229: =IF(F229="","",IF(F229>$I$5,"OUTLIER","")) | J229: =IF(G229="","",IF(G229>$I$5,"OUTLIER","")) | K229: =IF(C229="","MISSING","") | L229: =IF(AND(C229<>"",C228<>"",C229=C228),"STALE","") | M229: =IF(D229="","",ABS(D229-G$5))
B230: 44148 | C230: 2.93 | D230: =IF(OR(C230="",C229=""),"",(C230-C229)*100) -> -2 | E230: =IF(D230="","",ABS(D230-$E$5)/$F$5) -> 0.21001192 | F230: =IF(D230="","",ABS(D230-$G$5)/$H$5) -> 0.6745 | G230: =IF(D230="","",ABS(D230-$E$5)/SQRT(0.9*(IF(G229="",($F$5)^2,(ABS(D229-$E$5)/MAX(G229,0.0000000001))^2))+0.1*(D230-$E$5)^2)) -> 0.22083157 | H230: =IF(E230="","",IF(E230>$I$5,"OUTLIER","")) | I230: =IF(F230="","",IF(F230>$I$5,"OUTLIER","")) | J230: =IF(G230="","",IF(G230>$I$5,"OUTLIER","")) | K230: =IF(C230="","MISSING","") | L230: =IF(AND(C230<>"",C229<>"",C230=C229),"STALE","") | M230: =IF(D230="","",ABS(D230-G$5)) -> 2
B231: 44151 | C231: 2.91 | D231: =IF(OR(C231="",C230=""),"",(C231-C230)*100) -> -2 | E231: =IF(D231="","",ABS(D231-$E$5)/$F$5) -> 0.21001192 | F231: =IF(D231="","",ABS(D231-$G$5)/$H$5) -> 0.6745 | G231: =IF(D231="","",ABS(D231-$E$5)/SQRT(0.9*(IF(G230="",($F$5)^2,(ABS(D230-$E$5)/MAX(G230,0.0000000001))^2))+0.1*(D231-$E$5)^2)) -> 0.23214881 | H231: =IF(E231="","",IF(E231>$I$5,"OUTLIER","")) | I231: =IF(F231="","",IF(F231>$I$5,"OUTLIER","")) | J231: =IF(G231="","",IF(G231>$I$5,"OUTLIER","")) | K231: =IF(C231="","MISSING","") | L231: =IF(AND(C231<>"",C230<>"",C231=C230),"STALE","") | M231: =IF(D231="","",ABS(D231-G$5)) -> 2
B232: 44152 | C232: 2.94 | D232: =IF(OR(C232="",C231=""),"",(C232-C231)*100) -> 3 | E232: =IF(D232="","",ABS(D232-$E$5)/$F$5) -> 0.26104909 | F232: =IF(D232="","",ABS(D232-$G$5)/$H$5) -> 1.01175 | G232: =IF(D232="","",ABS(D232-$E$5)/SQRT(0.9*(IF(G231="",($F$5)^2,(ABS(D231-$E$5)/MAX(G231,0.0000000001))^2))+0.1*(D232-$E$5)^2)) -> 0.30277748 | H232: =IF(E232="","",IF(E232>$I$5,"OUTLIER","")) | I232: =IF(F232="","",IF(F232>$I$5,"OUTLIER","")) | J232: =IF(G232="","",IF(G232>$I$5,"OUTLIER","")) | K232: =IF(C232="","MISSING","") | L232: =IF(AND(C232<>"",C231<>"",C232=C231),"STALE","") | M232: =IF(D232="","",ABS(D232-G$5)) -> 3
B233: 44153 | C233: 2.97 | D233: =IF(OR(C233="",C232=""),"",(C233-C232)*100) -> 3 | E233: =IF(D233="","",ABS(D233-$E$5)/$F$5) -> 0.26104909 | F233: =IF(D233="","",ABS(D233-$G$5)/$H$5) -> 1.01175 | G233: =IF(D233="","",ABS(D233-$E$5)/SQRT(0.9*(IF(G232="",($F$5)^2,(ABS(D232-$E$5)/MAX(G232,0.0000000001))^2))+0.1*(D233-$E$5)^2)) -> 0.31754234 | H233: =IF(E233="","",IF(E233>$I$5,"OUTLIER","")) | I233: =IF(F233="","",IF(F233>$I$5,"OUTLIER","")) | J233: =IF(G233="","",IF(G233>$I$5,"OUTLIER","")) | K233: =IF(C233="","MISSING","") | L233: =IF(AND(C233<>"",C232<>"",C233=C232),"STALE","") | M233: =IF(D233="","",ABS(D233-G$5)) -> 3
B234: 44154 | C234: 2.98 | D234: =IF(OR(C234="",C233=""),"",(C234-C233)*100) -> 1 | E234: =IF(D234="","",ABS(D234-$E$5)/$F$5) -> 0.072624682 | F234: =IF(D234="","",ABS(D234-$G$5)/$H$5) -> 0.33725 | G234: =IF(D234="","",ABS(D234-$E$5)/SQRT(0.9*(IF(G233="",($F$5)^2,(ABS(D233-$E$5)/MAX(G233,0.0000000001))^2))+0.1*(D234-$E$5)^2)) -> 0.093079542 | H234: =IF(E234="","",IF(E234>$I$5,"OUTLIER","")) | I234: =IF(F234="","",IF(F234>$I$5,"OUTLIER","")) | J234: =IF(G234="","",IF(G234>$I$5,"OUTLIER","")) | K234: =IF(C234="","MISSING","") | L234: =IF(AND(C234<>"",C233<>"",C234=C233),"STALE","") | M234: =IF(D234="","",ABS(D234-G$5)) -> 1
B235: 44155 | C235: 3.03 | D235: =IF(OR(C235="",C234=""),"",(C235-C234)*100) -> 5 | E235: =IF(D235="","",ABS(D235-$E$5)/$F$5) -> 0.44947349 | F235: =IF(D235="","",ABS(D235-$G$5)/$H$5) -> 1.68625 | G235: =IF(D235="","",ABS(D235-$E$5)/SQRT(0.9*(IF(G234="",($F$5)^2,(ABS(D234-$E$5)/MAX(G234,0.0000000001))^2))+0.1*(D235-$E$5)^2)) -> 0.59633471 | H235: =IF(E235="","",IF(E235>$I$5,"OUTLIER","")) | I235: =IF(F235="","",IF(F235>$I$5,"OUTLIER","")) | J235: =IF(G235="","",IF(G235>$I$5,"OUTLIER","")) | K235: =IF(C235="","MISSING","") | L235: =IF(AND(C235<>"",C234<>"",C235=C234),"STALE","") | M235: =IF(D235="","",ABS(D235-G$5)) -> 5
B236: 44158 | C236: 2.97 | D236: =IF(OR(C236="",C235=""),"",(C236-C235)*100) -> -6 | E236: =IF(D236="","",ABS(D236-$E$5)/$F$5) -> 0.58686073 | F236: =IF(D236="","",ABS(D236-$G$5)/$H$5) -> 2.0235 | G236: =IF(D236="","",ABS(D236-$E$5)/SQRT(0.9*(IF(G235="",($F$5)^2,(ABS(D235-$E$5)/MAX(G235,0.0000000001))^2))+0.1*(D236-$E$5)^2)) -> 0.79440948 | H236: =IF(E236="","",IF(E236>$I$5,"OUTLIER","")) | I236: =IF(F236="","",IF(F236>$I$5,"OUTLIER","")) | J236: =IF(G236="","",IF(G236>$I$5,"OUTLIER","")) | K236: =IF(C236="","MISSING","") | L236: =IF(AND(C236<>"",C235<>"",C236=C235),"STALE","") | M236: =IF(D236="","",ABS(D236-G$5)) -> 6
B237: 44159 | C237: 2.89 | D237: =IF(OR(C237="",C236=""),"",(C237-C236)*100) -> -8 | E237: =IF(D237="","",ABS(D237-$E$5)/$F$5) -> 0.77528514 | F237: =IF(D237="","",ABS(D237-$G$5)/$H$5) -> 2.698 | G237: =IF(D237="","",ABS(D237-$E$5)/SQRT(0.9*(IF(G236="",($F$5)^2,(ABS(D236-$E$5)/MAX(G236,0.0000000001))^2))+0.1*(D237-$E$5)^2)) -> 1.0441917 | H237: =IF(E237="","",IF(E237>$I$5,"OUTLIER","")) | I237: =IF(F237="","",IF(F237>$I$5,"OUTLIER","")) | J237: =IF(G237="","",IF(G237>$I$5,"OUTLIER","")) | K237: =IF(C237="","MISSING","") | L237: =IF(AND(C237<>"",C236<>"",C237=C236),"STALE","") | M237: =IF(D237="","",ABS(D237-G$5)) -> 8
B238: 44160 | C238: 2.87 | D238: =IF(OR(C238="",C237=""),"",(C238-C237)*100) -> -2 | E238: =IF(D238="","",ABS(D238-$E$5)/$F$5) -> 0.21001192 | F238: =IF(D238="","",ABS(D238-$G$5)/$H$5) -> 0.6745 | G238: =IF(D238="","",ABS(D238-$E$5)/SQRT(0.9*(IF(G237="",($F$5)^2,(ABS(D237-$E$5)/MAX(G237,0.0000000001))^2))+0.1*(D238-$E$5)^2)) -> 0.2968381 | H238: =IF(E238="","",IF(E238>$I$5,"OUTLIER","")) | I238: =IF(F238="","",IF(F238>$I$5,"OUTLIER","")) | J238: =IF(G238="","",IF(G238>$I$5,"OUTLIER","")) | K238: =IF(C238="","MISSING","") | L238: =IF(AND(C238<>"",C237<>"",C238=C237),"STALE","") | M238: =IF(D238="","",ABS(D238-G$5)) -> 2
B239: 44162 | D239: =IF(OR(C239="",C238=""),"",(C239-C238)*100) | E239: =IF(D239="","",ABS(D239-$E$5)/$F$5) | F239: =IF(D239="","",ABS(D239-$G$5)/$H$5) | G239: =IF(D239="","",ABS(D239-$E$5)/SQRT(0.9*(IF(G238="",($F$5)^2,(ABS(D238-$E$5)/MAX(G238,0.0000000001))^2))+0.1*(D239-$E$5)^2)) | H239: =IF(E239="","",IF(E239>$I$5,"OUTLIER","")) | I239: =IF(F239="","",IF(F239>$I$5,"OUTLIER","")) | J239: =IF(G239="","",IF(G239>$I$5,"OUTLIER","")) | K239: =IF(C239="","MISSING","") -> MISSING | L239: =IF(AND(C239<>"",C238<>"",C239=C238),"STALE","") | M239: =IF(D239="","",ABS(D239-G$5))
B240: 44165 | C240: 2.87 | D240: =IF(OR(C240="",C239=""),"",(C240-C239)*100) | E240: =IF(D240="","",ABS(D240-$E$5)/$F$5) | F240: =IF(D240="","",ABS(D240-$G$5)/$H$5) | G240: =IF(D240="","",ABS(D240-$E$5)/SQRT(0.9*(IF(G239="",($F$5)^2,(ABS(D239-$E$5)/MAX(G239,0.0000000001))^2))+0.1*(D240-$E$5)^2)) | H240: =IF(E240="","",IF(E240>$I$5,"OUTLIER","")) | I240: =IF(F240="","",IF(F240>$I$5,"OUTLIER","")) | J240: =IF(G240="","",IF(G240>$I$5,"OUTLIER","")) | K240: =IF(C240="","MISSING","") | L240: =IF(AND(C240<>"",C239<>"",C240=C239),"STALE","") | M240: =IF(D240="","",ABS(D240-G$5))
B241: 44166 | C241: 2.83 | D241: =IF(OR(C241="",C240=""),"",(C241-C240)*100) -> -4 | E241: =IF(D241="","",ABS(D241-$E$5)/$F$5) -> 0.39843633 | F241: =IF(D241="","",ABS(D241-$G$5)/$H$5) -> 1.349 | G241: =IF(D241="","",ABS(D241-$E$5)/SQRT(0.9*(IF(G240="",($F$5)^2,(ABS(D240-$E$5)/MAX(G240,0.0000000001))^2))+0.1*(D241-$E$5)^2)) -> 0.41633296 | H241: =IF(E241="","",IF(E241>$I$5,"OUTLIER","")) | I241: =IF(F241="","",IF(F241>$I$5,"OUTLIER","")) | J241: =IF(G241="","",IF(G241>$I$5,"OUTLIER","")) | K241: =IF(C241="","MISSING","") | L241: =IF(AND(C241<>"",C240<>"",C241=C240),"STALE","") | M241: =IF(D241="","",ABS(D241-G$5)) -> 4
B242: 44167 | C242: 2.82 | D242: =IF(OR(C242="",C241=""),"",(C242-C241)*100) -> -1 | E242: =IF(D242="","",ABS(D242-$E$5)/$F$5) -> 0.11579972 | F242: =IF(D242="","",ABS(D242-$G$5)/$H$5) -> 0.33725 | G242: =IF(D242="","",ABS(D242-$E$5)/SQRT(0.9*(IF(G241="",($F$5)^2,(ABS(D241-$E$5)/MAX(G241,0.0000000001))^2))+0.1*(D242-$E$5)^2)) -> 0.12744276 | H242: =IF(E242="","",IF(E242>$I$5,"OUTLIER","")) | I242: =IF(F242="","",IF(F242>$I$5,"OUTLIER","")) | J242: =IF(G242="","",IF(G242>$I$5,"OUTLIER","")) | K242: =IF(C242="","MISSING","") | L242: =IF(AND(C242<>"",C241<>"",C242=C241),"STALE","") | M242: =IF(D242="","",ABS(D242-G$5)) -> 1
B243: 44168 | C243: 2.82 | D243: =IF(OR(C243="",C242=""),"",(C243-C242)*100) -> 0 | E243: =IF(D243="","",ABS(D243-$E$5)/$F$5) -> 0.02158752 | F243: =IF(D243="","",ABS(D243-$G$5)/$H$5) -> 0 | G243: =IF(D243="","",ABS(D243-$E$5)/SQRT(0.9*(IF(G242="",($F$5)^2,(ABS(D242-$E$5)/MAX(G242,0.0000000001))^2))+0.1*(D243-$E$5)^2)) -> 0.025042375 | H243: =IF(E243="","",IF(E243>$I$5,"OUTLIER","")) | I243: =IF(F243="","",IF(F243>$I$5,"OUTLIER","")) | J243: =IF(G243="","",IF(G243>$I$5,"OUTLIER","")) | K243: =IF(C243="","MISSING","") | L243: =IF(AND(C243<>"",C242<>"",C243=C242),"STALE","") -> STALE | M243: =IF(D243="","",ABS(D243-G$5)) -> 0
B244: 44169 | C244: 2.8 | D244: =IF(OR(C244="",C243=""),"",(C244-C243)*100) -> -2 | E244: =IF(D244="","",ABS(D244-$E$5)/$F$5) -> 0.21001192 | F244: =IF(D244="","",ABS(D244-$G$5)/$H$5) -> 0.6745 | G244: =IF(D244="","",ABS(D244-$E$5)/SQRT(0.9*(IF(G243="",($F$5)^2,(ABS(D243-$E$5)/MAX(G243,0.0000000001))^2))+0.1*(D244-$E$5)^2)) -> 0.25595768 | H244: =IF(E244="","",IF(E244>$I$5,"OUTLIER","")) | I244: =IF(F244="","",IF(F244>$I$5,"OUTLIER","")) | J244: =IF(G244="","",IF(G244>$I$5,"OUTLIER","")) | K244: =IF(C244="","MISSING","") | L244: =IF(AND(C244<>"",C243<>"",C244=C243),"STALE","") | M244: =IF(D244="","",ABS(D244-G$5)) -> 2
B245: 44172 | C245: 2.78 | D245: =IF(OR(C245="",C244=""),"",(C245-C244)*100) -> -2 | E245: =IF(D245="","",ABS(D245-$E$5)/$F$5) -> 0.21001192 | F245: =IF(D245="","",ABS(D245-$G$5)/$H$5) -> 0.6745 | G245: =IF(D245="","",ABS(D245-$E$5)/SQRT(0.9*(IF(G244="",($F$5)^2,(ABS(D244-$E$5)/MAX(G244,0.0000000001))^2))+0.1*(D245-$E$5)^2)) -> 0.26882641 | H245: =IF(E245="","",IF(E245>$I$5,"OUTLIER","")) | I245: =IF(F245="","",IF(F245>$I$5,"OUTLIER","")) | J245: =IF(G245="","",IF(G245>$I$5,"OUTLIER","")) | K245: =IF(C245="","MISSING","") | L245: =IF(AND(C245<>"",C244<>"",C245=C244),"STALE","") | M245: =IF(D245="","",ABS(D245-G$5)) -> 2
B246: 44173 | C246: 2.77 | D246: =IF(OR(C246="",C245=""),"",(C246-C245)*100) -> -1 | E246: =IF(D246="","",ABS(D246-$E$5)/$F$5) -> 0.11579972 | F246: =IF(D246="","",ABS(D246-$G$5)/$H$5) -> 0.33725 | G246: =IF(D246="","",ABS(D246-$E$5)/SQRT(0.9*(IF(G245="",($F$5)^2,(ABS(D245-$E$5)/MAX(G245,0.0000000001))^2))+0.1*(D246-$E$5)^2)) -> 0.15605754 | H246: =IF(E246="","",IF(E246>$I$5,"OUTLIER","")) | I246: =IF(F246="","",IF(F246>$I$5,"OUTLIER","")) | J246: =IF(G246="","",IF(G246>$I$5,"OUTLIER","")) | K246: =IF(C246="","MISSING","") | L246: =IF(AND(C246<>"",C245<>"",C246=C245),"STALE","") | M246: =IF(D246="","",ABS(D246-G$5)) -> 1
B247: 44174 | C247: 2.79 | D247: =IF(OR(C247="",C246=""),"",(C247-C246)*100) -> 2 | E247: =IF(D247="","",ABS(D247-$E$5)/$F$5) -> 0.16683688 | F247: =IF(D247="","",ABS(D247-$G$5)/$H$5) -> 0.6745 | G247: =IF(D247="","",ABS(D247-$E$5)/SQRT(0.9*(IF(G246="",($F$5)^2,(ABS(D246-$E$5)/MAX(G246,0.0000000001))^2))+0.1*(D247-$E$5)^2)) -> 0.23633703 | H247: =IF(E247="","",IF(E247>$I$5,"OUTLIER","")) | I247: =IF(F247="","",IF(F247>$I$5,"OUTLIER","")) | J247: =IF(G247="","",IF(G247>$I$5,"OUTLIER","")) | K247: =IF(C247="","MISSING","") | L247: =IF(AND(C247<>"",C246<>"",C247=C246),"STALE","") | M247: =IF(D247="","",ABS(D247-G$5)) -> 2
...

Sheet RF2 SP500
B1: RF2: S&P 500 (Equity Index)
B2: Return Type: Log Returns | Z-Score Threshold: 3.0 | EWMA Parameters: N=30, λ=0.9
B4: GLOBAL STATISTICS (Full Series) | E4: Mean Return | F4: Std Dev (σ) | G4: Median Return | H4: Scaled MAD (σ̂) | I4: Cutoff (c) | M4: MAD Helper (|r - median|)
E5: =AVERAGE(D9:D267,D270:D526,D529:D787) -> 0.00077454385 | F5: =STDEV(D9:D267,D270:D526,D529:D787) -> 0.016711235 | G5: =MEDIAN(D9:D267,D270:D526,D529:D787) -> 0 | H5: =_xlfn.AGGREGATE(16,6,M9:M787,0.5)/0.6745 -> 0.0095020868 | I5: 3
B7: ="YEAR 2020 | Observations: "&COUNTA(C9:C267)&" | Missing: "&COUNTIF(K9:K267,"MISSING")&" | Stale: "&COUNTIF(L9:L267,"STALE")&" | Z>3 Outliers: "&COUNTIF(H9:H267,"OUTLIER")&" | Robust Z>3: "&COUNTIF(I9:I267,"OUTLIER") -> YEAR 2020 | Observations: 254 | Missing: 4 | Stale: 0 | Z>3 Outliers: 11 | Robust Z>3: 31
B8: Date | C8: Level | D8: Return | E8: Z-Score | F8: Robust Z | G8: EWMA Z | H8: Z>3 Flag | I8: RobZ>3 | J8: EWMA>3 | K8: Missing? | L8: Stale? | M8: |r - median|
B9: 43831 | E9: =IF(D9="","",ABS(D9-$E$5)/$F$5) | F9: =IF(D9="","",ABS(D9-$G$5)/$H$5) | G9: =IF(D9="","",ABS(D9-$E$5)/$F$5) | H9: =IF(E9="","",IF(E9>$I$5,"OUTLIER","")) | I9: =IF(F9="","",IF(F9>$I$5,"OUTLIER","")) | J9: =IF(G9="","",IF(G9>$I$5,"OUTLIER","")) | K9: =IF(C9="","MISSING","") -> MISSING | M9: =IF(D9="","",ABS(D9-G$5))
B10: 43832 | C10: 3257.85 | D10: =IF(OR(C10="",C9=""),"",LN(C10/C9)) | E10: =IF(D10="","",ABS(D10-$E$5)/$F$5) | F10: =IF(D10="","",ABS(D10-$G$5)/$H$5) | G10: =IF(D10="","",ABS(D10-$E$5)/SQRT(0.9*(IF(G9="",($F$5)^2,(ABS(D9-$E$5)/MAX(G9,0.0000000001))^2))+0.1*(D10-$E$5)^2)) | H10: =IF(E10="","",IF(E10>$I$5,"OUTLIER","")) | I10: =IF(F10="","",IF(F10>$I$5,"OUTLIER","")) | J10: =IF(G10="","",IF(G10>$I$5,"OUTLIER","")) | K10: =IF(C10="","MISSING","") | M10: =IF(D10="","",ABS(D10-G$5))
B11: 43833 | C11: 3234.85 | D11: =IF(OR(C11="",C10=""),"",LN(C11/C10)) -> -0.0070849096 | E11: =IF(D11="","",ABS(D11-$E$5)/$F$5) -> 0.47030956 | F11: =IF(D11="","",ABS(D11-$G$5)/$H$5) -> 0.74561617 | G11: =IF(D11="","",ABS(D11-$E$5)/SQRT(0.9*(IF(G10="",($F$5)^2,(ABS(D10-$E$5)/MAX(G10,0.0000000001))^2))+0.1*(D11-$E$5)^2)) -> 0.48976788 | H11: =IF(E11="","",IF(E11>$I$5,"OUTLIER","")) | I11: =IF(F11="","",IF(F11>$I$5,"OUTLIER","")) | J11: =IF(G11="","",IF(G11>$I$5,"OUTLIER","")) | K11: =IF(C11="","MISSING","") | M11: =IF(D11="","",ABS(D11-G$5)) -> 0.0070849096
B12: 43836 | C12: 3246.28 | D12: =IF(OR(C12="",C11=""),"",LN(C12/C11)) -> 0.0035271664 | E12: =IF(D12="","",ABS(D12-$E$5)/$F$5) -> 0.16471689 | F12: =IF(D12="","",ABS(D12-$G$5)/$H$5) -> 0.37119913 | G12: =IF(D12="","",ABS(D12-$E$5)/SQRT(0.9*(IF(G11="",($F$5)^2,(ABS(D11-$E$5)/MAX(G11,0.0000000001))^2))+0.1*(D12-$E$5)^2)) -> 0.18051554 | H12: =IF(E12="","",IF(E12>$I$5,"OUTLIER","")) | I12: =IF(F12="","",IF(F12>$I$5,"OUTLIER","")) | J12: =IF(G12="","",IF(G12>$I$5,"OUTLIER","")) | K12: =IF(C12="","MISSING","") | M12: =IF(D12="","",ABS(D12-G$5)) -> 0.0035271664
B13: 43837 | C13: 3237.18 | D13: =IF(OR(C13="",C12=""),"",LN(C13/C12)) -> -0.0028071449 | E13: =IF(D13="","",ABS(D13-$E$5)/$F$5) -> 0.2143282 | F13: =IF(D13="","",ABS(D13-$G$5)/$H$5) -> 0.29542405 | G13: =IF(D13="","",ABS(D13-$E$5)/SQRT(0.9*(IF(G12="",($F$5)^2,(ABS(D12-$E$5)/MAX(G12,0.0000000001))^2))+0.1*(D13-$E$5)^2)) -> 0.24683541 | H13: =IF(E13="","",IF(E13>$I$5,"OUTLIER","")) | I13: =IF(F13="","",IF(F13>$I$5,"OUTLIER","")) | J13: =IF(G13="","",IF(G13>$I$5,"OUTLIER","")) | K13: =IF(C13="","MISSING","") | M13: =IF(D13="","",ABS(D13-G$5)) -> 0.0028071449
B14: 43838 | C14: 3253.05 | D14: =IF(OR(C14="",C13=""),"",LN(C14/C13)) -> 0.0048904374 | E14: =IF(D14="","",ABS(D14-$E$5)/$F$5) -> 0.246295 | F14: =IF(D14="","",ABS(D14-$G$5)/$H$5) -> 0.51466983 | G14: =IF(D14="","",ABS(D14-$E$5)/SQRT(0.9*(IF(G13="",($F$5)^2,(ABS(D13-$E$5)/MAX(G13,0.0000000001))^2))+0.1*(D14-$E$5)^2)) -> 0.29766644 | H14: =IF(E14="","",IF(E14>$I$5,"OUTLIER","")) | I14: =IF(F14="","",IF(F14>$I$5,"OUTLIER","")) | J14: =IF(G14="","",IF(G14>$I$5,"OUTLIER","")) | K14: =IF(C14="","MISSING","") | M14: =IF(D14="","",ABS(D14-G$5)) -> 0.0048904374
B15: 43839 | C15: 3274.7 | D15: =IF(OR(C15="",C14=""),"",LN(C15/C14)) -> 0.006633244 | E15: =IF(D15="","",ABS(D15-$E$5)/$F$5) -> 0.35058452 | F15: =IF(D15="","",ABS(D15-$G$5)/$H$5) -> 0.69808287 | G15: =IF(D15="","",ABS(D15-$E$5)/SQRT(0.9*(IF(G14="",($F$5)^2,(ABS(D14-$E$5)/MAX(G14,0.0000000001))^2))+0.1*(D15-$E$5)^2)) -> 0.44223879 | H15: =IF(E15="","",IF(E15>$I$5,"OUTLIER","")) | I15: =IF(F15="","",IF(F15>$I$5,"OUTLIER","")) | J15: =IF(G15="","",IF(G15>$I$5,"OUTLIER","")) | K15: =IF(C15="","MISSING","") | M15: =IF(D15="","",ABS(D15-G$5)) -> 0.006633244
B16: 43840 | C16: 3265.35 | D16: =IF(OR(C16="",C15=""),"",LN(C16/C15)) -> -0.0028593073 | E16: =IF(D16="","",ABS(D16-$E$5)/$F$5) -> 0.21744959 | F16: =IF(D16="","",ABS(D16-$G$5)/$H$5) -> 0.30091362 | G16: =IF(D16="","",ABS(D16-$E$5)/SQRT(0.9*(IF(G15="",($F$5)^2,(ABS(D15-$E$5)/MAX(G15,0.0000000001))^2))+0.1*(D16-$E$5)^2)) -> 0.28793446 | H16: =IF(E16="","",IF(E16>$I$5,"OUTLIER","")) | I16: =IF(F16="","",IF(F16>$I$5,"OUTLIER","")) | J16: =IF(G16="","",IF(G16>$I$5,"OUTLIER","")) | K16: =IF(C16="","MISSING","") | M16: =IF(D16="","",ABS(D16-G$5)) -> 0.0028593073
B17: 43843 | C17: 3288.13 | D17: =IF(OR(C17="",C16=""),"",LN(C17/C16)) -> 0.0069520596 | E17: =IF(D17="","",ABS(D17-$E$5)/$F$5) -> 0.36966244 | F17: =IF(D17="","",ABS(D17-$G$5)/$H$5) -> 0.73163504 | G17: =IF(D17="","",ABS(D17-$E$5)/SQRT(0.9*(IF(G16="",($F$5)^2,(ABS(D16-$E$5)/MAX(G16,0.0000000001))^2))+0.1*(D17-$E$5)^2)) -> 0.50922987 | H17: =IF(E17="","",IF(E17>$I$5,"OUTLIER","")) | I17: =IF(F17="","",IF(F17>$I$5,"OUTLIER","")) | J17: =IF(G17="","",IF(G17>$I$5,"OUTLIER","")) | K17: =IF(C17="","MISSING","") | M17: =IF(D17="","",ABS(D17-G$5)) -> 0.0069520596
B18: 43844 | C18: 3283.15 | D18: =IF(OR(C18="",C17=""),"",LN(C18/C17)) -> -0.0015156867 | E18: =IF(D18="","",ABS(D18-$E$5)/$F$5) -> 0.13704736 | F18: =IF(D18="","",ABS(D18-$G$5)/$H$5) -> 0.15951093 | G18: =IF(D18="","",ABS(D18-$E$5)/SQRT(0.9*(IF(G17="",($F$5)^2,(ABS(D17-$E$5)/MAX(G17,0.0000000001))^2))+0.1*(D18-$E$5)^2)) -> 0.19860936 | H18: =IF(E18="","",IF(E18>$I$5,"OUTLIER","")) | I18: =IF(F18="","",IF(F18>$I$5,"OUTLIER","")) | J18: =IF(G18="","",IF(G18>$I$5,"OUTLIER","")) | K18: =IF(C18="","MISSING","") | M18: =IF(D18="","",ABS(D18-G$5)) -> 0.0015156867
B19: 43845 | C19: 3289.29 | D19: =IF(OR(C19="",C18=""),"",LN(C19/C18)) -> 0.0018684086 | E19: =IF(D19="","",ABS(D19-$E$5)/$F$5) -> 0.06545685 | F19: =IF(D19="","",ABS(D19-$G$5)/$H$5) -> 0.1966314 | G19: =IF(D19="","",ABS(D19-$E$5)/SQRT(0.9*(IF(G18="",($F$5)^2,(ABS(D18-$E$5)/MAX(G18,0.0000000001))^2))+0.1*(D19-$E$5)^2)) -> 0.099941505 | H19: =IF(E19="","",IF(E19>$I$5,"OUTLIER","")) | I19: =IF(F19="","",IF(F19>$I$5,"OUTLIER","")) | J19: =IF(G19="","",IF(G19>$I$5,"OUTLIER","")) | K19: =IF(C19="","MISSING","") | M19: =IF(D19="","",ABS(D19-G$5)) -> 0.0018684086
B20: 43846 | C20: 3316.81 | D20: =IF(OR(C20="",C19=""),"",LN(C20/C19)) -> 0.0083317416 | E20: =IF(D20="","",ABS(D20-$E$5)/$F$5) -> 0.45222259 | F20: =IF(D20="","",ABS(D20-$G$5)/$H$5) -> 0.87683283 | G20: =IF(D20="","",ABS(D20-$E$5)/SQRT(0.9*(IF(G19="",($F$5)^2,(ABS(D19-$E$5)/MAX(G19,0.0000000001))^2))+0.1*(D20-$E$5)^2)) -> 0.70927302 | H20: =IF(E20="","",IF(E20>$I$5,"OUTLIER","")) | I20: =IF(F20="","",IF(F20>$I$5,"OUTLIER","")) | J20: =IF(G20="","",IF(G20>$I$5,"OUTLIER","")) | K20: =IF(C20="","MISSING","") | M20: =IF(D20="","",ABS(D20-G$5)) -> 0.0083317416
B21: 43847 | C21: 3329.62 | D21: =IF(OR(C21="",C20=""),"",LN(C21/C20)) -> 0.0038547057 | E21: =IF(D21="","",ABS(D21-$E$5)/$F$5) -> 0.18431683 | F21: =IF(D21="","",ABS(D21-$G$5)/$H$5) -> 0.40566939 | G21: =IF(D21="","",ABS(D21-$E$5)/SQRT(0.9*(IF(G20="",($F$5)^2,(ABS(D20-$E$5)/MAX(G20,0.0000000001))^2))+0.1*(D21-$E$5)^2)) -> 0.3033178 | H21: =IF(E21="","",IF(E21>$I$5,"OUTLIER","")) | I21: =IF(F21="","",IF(F21>$I$5,"OUTLIER","")) | J21: =IF(G21="","",IF(G21>$I$5,"OUTLIER","")) | K21: =IF(C21="","MISSING","") | M21: =IF(D21="","",ABS(D21-G$5)) -> 0.0038547057
B22: 43850 | D22: =IF(OR(C22="",C21=""),"",LN(C22/C21)) | E22: =IF(D22="","",ABS(D22-$E$5)/$F$5) | F22: =IF(D22="","",ABS(D22-$G$5)/$H$5) | G22: =IF(D22="","",ABS(D22-$E$5)/SQRT(0.9*(IF(G21="",($F$5)^2,(ABS(D21-$E$5)/MAX(G21,0.0000000001))^2))+0.1*(D22-$E$5)^2)) | H22: =IF(E22="","",IF(E22>$I$5,"OUTLIER","")) | I22: =IF(F22="","",IF(F22>$I$5,"OUTLIER","")) | J22: =IF(G22="","",IF(G22>$I$5,"OUTLIER","")) | K22: =IF(C22="","MISSING","") -> MISSING | M22: =IF(D22="","",ABS(D22-G$5))
B23: 43851 | C23: 3320.79 | D23: =IF(OR(C23="",C22=""),"",LN(C23/C22)) | E23: =IF(D23="","",ABS(D23-$E$5)/$F$5) | F23: =IF(D23="","",ABS(D23-$G$5)/$H$5) | G23: =IF(D23="","",ABS(D23-$E$5)/SQRT(0.9*(IF(G22="",($F$5)^2,(ABS(D22-$E$5)/MAX(G22,0.0000000001))^2))+0.1*(D23-$E$5)^2)) | H23: =IF(E23="","",IF(E23>$I$5,"OUTLIER","")) | I23: =IF(F23="","",IF(F23>$I$5,"OUTLIER","")) | J23: =IF(G23="","",IF(G23>$I$5,"OUTLIER","")) | K23: =IF(C23="","MISSING","") | M23: =IF(D23="","",ABS(D23-G$5))
B24: 43852 | C24: 3321.75 | D24: =IF(OR(C24="",C23=""),"",LN(C24/C23)) -> 0.00028904606 | E24: =IF(D24="","",ABS(D24-$E$5)/$F$5) -> 0.02905218 | F24: =IF(D24="","",ABS(D24-$G$5)/$H$5) -> 0.030419219 | G24: =IF(D24="","",ABS(D24-$E$5)/SQRT(0.9*(IF(G23="",($F$5)^2,(ABS(D23-$E$5)/MAX(G23,0.0000000001))^2))+0.1*(D24-$E$5)^2)) -> 0.030622251 | H24: =IF(E24="","",IF(E24>$I$5,"OUTLIER","")) | I24: =IF(F24="","",IF(F24>$I$5,"OUTLIER","")) | J24: =IF(G24="","",IF(G24>$I$5,"OUTLIER","")) | K24: =IF(C24="","MISSING","") | M24: =IF(D24="","",ABS(D24-G$5)) -> 0.00028904606
B25: 43853 | C25: 3325.54 | D25: =IF(OR(C25="",C24=""),"",LN(C25/C24)) -> 0.0011403144 | E25: =IF(D25="","",ABS(D25-$E$5)/$F$5) -> 0.021887706 | F25: =IF(D25="","",ABS(D25-$G$5)/$H$5) -> 0.12000674 | G25: =IF(D25="","",ABS(D25-$E$5)/SQRT(0.9*(IF(G24="",($F$5)^2,(ABS(D24-$E$5)/MAX(G24,0.0000000001))^2))+0.1*(D25-$E$5)^2)) -> 0.024317814 | H25: =IF(E25="","",IF(E25>$I$5,"OUTLIER","")) | I25: =IF(F25="","",IF(F25>$I$5,"OUTLIER","")) | J25: =IF(G25="","",IF(G25>$I$5,"OUTLIER","")) | K25: =IF(C25="","MISSING","") | M25: =IF(D25="","",ABS(D25-G$5)) -> 0.0011403144
B26: 43854 | C26: 3295.47 | D26: =IF(OR(C26="",C25=""),"",LN(C26/C25)) -> -0.0090832688 | E26: =IF(D26="","",ABS(D26-$E$5)/$F$5) -> 0.58989134 | F26: =IF(D26="","",ABS(D26-$G$5)/$H$5) -> 0.95592358 | G26: =IF(D26="","",ABS(D26-$E$5)/SQRT(0.9*(IF(G25="",($F$5)^2,(ABS(D25-$E$5)/MAX(G25,0.0000000001))^2))+0.1*(D26-$E$5)^2)) -> 0.67491846 | H26: =IF(E26="","",IF(E26>$I$5,"OUTLIER","")) | I26: =IF(F26="","",IF(F26>$I$5,"OUTLIER","")) | J26: =IF(G26="","",IF(G26>$I$5,"OUTLIER","")) | K26: =IF(C26="","MISSING","") | M26: =IF(D26="","",ABS(D26-G$5)) -> 0.0090832688
B27: 43857 | C27: 3243.63 | D27: =IF(OR(C27="",C26=""),"",LN(C27/C26)) -> -0.015855725 | E27: =IF(D27="","",ABS(D27-$E$5)/$F$5) -> 0.99515502 | F27: =IF(D27="","",ABS(D27-$G$5)/$H$5) -> 1.6686572 | G27: =IF(D27="","",ABS(D27-$E$5)/SQRT(0.9*(IF(G26="",($F$5)^2,(ABS(D26-$E$5)/MAX(G26,0.0000000001))^2))+0.1*(D27-$E$5)^2)) -> 1.1220889 | H27: =IF(E27="","",IF(E27>$I$5,"OUTLIER","")) | I27: =IF(F27="","",IF(F27>$I$5,"OUTLIER","")) | J27: =IF(G27="","",IF(G27>$I$5,"OUTLIER","")) | K27: =IF(C27="","MISSING","") | M27: =IF(D27="","",ABS(D27-G$5)) -> 0.015855725
B28: 43858 | C28: 3276.24 | D28: =IF(OR(C28="",C27=""),"",LN(C28/C27)) -> 0.01000335 | E28: =IF(D28="","",ABS(D28-$E$5)/$F$5) -> 0.55225163 | F28: =IF(D28="","",ABS(D28-$G$5)/$H$5) -> 1.052753 | G28: =IF(D28="","",ABS(D28-$E$5)/SQRT(0.9*(IF(G27="",($F$5)^2,(ABS(D27-$E$5)/MAX(G27,0.0000000001))^2))+0.1*(D28-$E$5)^2)) -> 0.64267715 | H28: =IF(E28="","",IF(E28>$I$5,"OUTLIER","")) | I28: =IF(F28="","",IF(F28>$I$5,"OUTLIER","")) | J28: =IF(G28="","",IF(G28>$I$5,"OUTLIER","")) | K28: =IF(C28="","MISSING","") | M28: =IF(D28="","",ABS(D28-G$5)) -> 0.01000335
B29: 43859 | C29: 3310.11 | D29: =IF(OR(C29="",C28=""),"",LN(C29/C28)) -> 0.010284998 | E29: =IF(D29="","",ABS(D29-$E$5)/$F$5) -> 0.56910542 | F29: =IF(D29="","",ABS(D29-$G$5)/$H$5) -> 1.0823936 | G29: =IF(D29="","",ABS(D29-$E$5)/SQRT(0.9*(IF(G28="",($F$5)^2,(ABS(D28-$E$5)/MAX(G28,0.0000000001))^2))+0.1*(D29-$E$5)^2)) -> 0.68170131 | H29: =IF(E29="","",IF(E29>$I$5,"OUTLIER","")) | I29: =IF(F29="","",IF(F29>$I$5,"OUTLIER","")) | J29: =IF(G29="","",IF(G29>$I$5,"OUTLIER","")) | K29: =IF(C29="","MISSING","") | M29: =IF(D29="","",ABS(D29-G$5)) -> 0.010284998
B30: 43860 | C30: 3283.66 | D30: =IF(OR(C30="",C29=""),"",LN(C30/C29)) -> -0.0080227675 | E30: =IF(D30="","",ABS(D30-$E$5)/$F$5) -> 0.52643097 | F30: =IF(D30="","",ABS(D30-$G$5)/$H$5) -> 0.84431638 | G30: =IF(D30="","",ABS(D30-$E$5)/SQRT(0.9*(IF(G29="",($F$5)^2,(ABS(D29-$E$5)/MAX(G29,0.0000000001))^2))+0.1*(D30-$E$5)^2)) -> 0.65047936 | H30: =IF(E30="","",IF(E30>$I$5,"OUTLIER","")) | I30: =IF(F30="","",IF(F30>$I$5,"OUTLIER","")) | J30: =IF(G30="","",IF(G30>$I$5,"OUTLIER","")) | K30: =IF(C30="","MISSING","") | M30: =IF(D30="","",ABS(D30-G$5)) -> 0.0080227675
B31: 43861 | C31: 3225.52 | D31: =IF(OR(C31="",C30=""),"",LN(C31/C30)) -> -0.017864476 | E31: =IF(D31="","",ABS(D31-$E$5)/$F$5) -> 1.1153587 | F31: =IF(D31="","",ABS(D31-$G$5)/$H$5) -> 1.8800582 | G31: =IF(D31="","",ABS(D31-$E$5)/SQRT(0.9*(IF(G30="",($F$5)^2,(ABS(D30-$E$5)/MAX(G30,0.0000000001))^2))+0.1*(D31-$E$5)^2)) -> 1.3200963 | H31: =IF(E31="","",IF(E31>$I$5,"OUTLIER","")) | I31: =IF(F31="","",IF(F31>$I$5,"OUTLIER","")) | J31: =IF(G31="","",IF(G31>$I$5,"OUTLIER","")) | K31: =IF(C31="","MISSING","") | M31: =IF(D31="","",ABS(D31-G$5)) -> 0.017864476
B32: 43864 | C32: 3248.92 | D32: =IF(OR(C32="",C31=""),"",LN(C32/C31)) -> 0.0072284559 | E32: =IF(D32="","",ABS(D32-$E$5)/$F$5) -> 0.38620199 | F32: =IF(D32="","",ABS(D32-$G$5)/$H$5) -> 0.76072299 | G32: =IF(D32="","",ABS(D32-$E$5)/SQRT(0.9*(IF(G31="",($F$5)^2,(ABS(D31-$E$5)/MAX(G31,0.0000000001))^2))+0.1*(D32-$E$5)^2)) -> 0.47632226 | H32: =IF(E32="","",IF(E32>$I$5,"OUTLIER","")) | I32: =IF(F32="","",IF(F32>$I$5,"OUTLIER","")) | J32: =IF(G32="","",IF(G32>$I$5,"OUTLIER","")) | K32: =IF(C32="","MISSING","") | M32: =IF(D32="","",ABS(D32-G$5)) -> 0.0072284559
B33: 43865 | C33: 3297.59 | D33: =IF(OR(C33="",C32=""),"",LN(C33/C32)) -> 0.014869265 | E33: =IF(D33="","",ABS(D33-$E$5)/$F$5) -> 0.84342789 | F33: =IF(D33="","",ABS(D33-$G$5)/$H$5) -> 1.5648421 | G33: =IF(D33="","",ABS(D33-$E$5)/SQRT(0.9*(IF(G32="",($F$5)^2,(ABS(D32-$E$5)/MAX(G32,0.0000000001))^2))+0.1*(D33-$E$5)^2)) -> 1.0359976 | H33: =IF(E33="","",IF(E33>$I$5,"OUTLIER","")) | I33: =IF(F33="","",IF(F33>$I$5,"OUTLIER","")) | J33: =IF(G33="","",IF(G33>$I$5,"OUTLIER","")) | K33: =IF(C33="","MISSING","") | M33: =IF(D33="","",ABS(D33-G$5)) -> 0.014869265
B34: 43866 | C34: 3334.69 | D34: =IF(OR(C34="",C33=""),"",LN(C34/C33)) -> 0.011187823 | E34: =IF(D34="","",ABS(D34-$E$5)/$F$5) -> 0.62313044 | F34: =IF(D34="","",ABS(D34-$G$5)/$H$5) -> 1.1774069 | G34: =IF(D34="","",ABS(D34-$E$5)/SQRT(0.9*(IF(G33="",($F$5)^2,(ABS(D33-$E$5)/MAX(G33,0.0000000001))^2))+0.1*(D34-$E$5)^2)) -> 0.7817622 | H34: =IF(E34="","",IF(E34>$I$5,"OUTLIER","")) | I34: =IF(F34="","",IF(F34>$I$5,"OUTLIER","")) | J34: =IF(G34="","",IF(G34>$I$5,"OUTLIER","")) | K34: =IF(C34="","MISSING","") | M34: =IF(D34="","",ABS(D34-G$5)) -> 0.011187823
... B182: 44078 | C182: 3426.96 | D182: =IF(OR(C182="",C181=""),"",LN(C182/C181)) -> -0.0081662524 | E182: =IF(D182="","",ABS(D182-$E$5)/$F$5) -> 0.5350171 | F182: =IF(D182="","",ABS(D182-$G$5)/$H$5) -> 0.85941674 | G182: =IF(D182="","",ABS(D182-$E$5)/SQRT(0.9*(IF(G181="",($F$5)^2,(ABS(D181-$E$5)/MAX(G181,0.0000000001))^2))+0.1*(D182-$E$5)^2)) -> 0.68337123 | H182: =IF(E182="","",IF(E182>$I$5,"OUTLIER","")) | I182: =IF(F182="","",IF(F182>$I$5,"OUTLIER","")) | J182: =IF(G182="","",IF(G182>$I$5,"OUTLIER","")) | K182: =IF(C182="","MISSING","") | M182: =IF(D182="","",ABS(D182-G$5)) -> 0.0081662524
B183: 44081 | D183: =IF(OR(C183="",C182=""),"",LN(C183/C182)) | E183: =IF(D183="","",ABS(D183-$E$5)/$F$5) | F183: =IF(D183="","",ABS(D183-$G$5)/$H$5) | G183: =IF(D183="","",ABS(D183-$E$5)/SQRT(0.9*(IF(G182="",($F$5)^2,(ABS(D182-$E$5)/MAX(G182,0.0000000001))^2))+0.1*(D183-$E$5)^2)) | H183: =IF(E183="","",IF(E183>$I$5,"OUTLIER","")) | I183: =IF(F183="","",IF(F183>$I$5,"OUTLIER","")) | J183: =IF(G183="","",IF(G183>$I$5,"OUTLIER","")) | K183: =IF(C183="","MISSING","") -> MISSING | M183: =IF(D183="","",ABS(D183-G$5))
B184: 44082 | C184: 3331.84 | D184: =IF(OR(C184="",C183=""),"",LN(C184/C183)) | E184: =IF(D184="","",ABS(D184-$E$5)/$F$5) | F184: =IF(D184="","",ABS(D184-$G$5)/$H$5) | G184: =IF(D184="","",ABS(D184-$E$5)/SQRT(0.9*(IF(G183="",($F$5)^2,(ABS(D183-$E$5)/MAX(G183,0.0000000001))^2))+0.1*(D184-$E$5)^2)) | H184: =IF(E184="","",IF(E184>$I$5,"OUTLIER","")) | I184: =IF(F184="","",IF(F184>$I$5,"OUTLIER","")) | J184: =IF(G184="","",IF(G184>$I$5,"OUTLIER","")) | K184: =IF(C184="","MISSING","") | M184: =IF(D184="","",ABS(D184-G$5))
B185: 44083 | C185: 3398.96 | D185: =IF(OR(C185="",C184=""),"",LN(C185/C184)) -> 0.019944799 | E185: =IF(D185="","",ABS(D185-$E$5)/$F$5) -> 1.1471477 | F185: =IF(D185="","",ABS(D185-$G$5)/$H$5) -> 2.0989914 | G185: =IF(D185="","",ABS(D185-$E$5)/SQRT(0.9*(IF(G184="",($F$5)^2,(ABS(D184-$E$5)/MAX(G184,0.0000000001))^2))+0.1*(D185-$E$5)^2)) -> 1.1294442 | H185: =IF(E185="","",IF(E185>$I$5,"OUTLIER","")) | I185: =IF(F185="","",IF(F185>$I$5,"OUTLIER","")) | J185: =IF(G185="","",IF(G185>$I$5,"OUTLIER","")) | K185: =IF(C185="","MISSING","") | M185: =IF(D185="","",ABS(D185-G$5)) -> 0.019944799
B186: 44084 | C186: 3339.19 | D186: =IF(OR(C186="",C185=""),"",LN(C186/C185)) -> -0.01774124 | E186: =IF(D186="","",ABS(D186-$E$5)/$F$5) -> 1.1079842 | F186: =IF(D186="","",ABS(D186-$G$5)/$H$5) -> 1.8670888 | G186: =IF(D186="","",ABS(D186-$E$5)/SQRT(0.9*(IF(G185="",($F$5)^2,(ABS(D185-$E$5)/MAX(G185,0.0000000001))^2))+0.1*(D186-$E$5)^2)) -> 1.0806654 | H186: =IF(E186="","",IF(E186>$I$5,"OUTLIER","")) | I186: =IF(F186="","",IF(F186>$I$5,"OUTLIER","")) | J186: =IF(G186="","",IF(G186>$I$5,"OUTLIER","")) | K186: =IF(C186="","MISSING","") | M186: =IF(D186="","",ABS(D186-G$5)) -> 0.01774124
B187: 44085 | C187: 3340.97 | D187: =IF(OR(C187="",C186=""),"",LN(C187/C186)) -> 0.00053292138 | E187: =IF(D187="","",ABS(D187-$E$5)/$F$5) -> 0.014458685 | F187: =IF(D187="","",ABS(D187-$G$5)/$H$5) -> 0.056084668 | G187: =IF(D187="","",ABS(D187-$E$5)/SQRT(0.9*(IF(G186="",($F$5)^2,(ABS(D186-$E$5)/MAX(G186,0.0000000001))^2))+0.1*(D187-$E$5)^2)) -> 0.014864847 | H187: =IF(E187="","",IF(E187>$I$5,"OUTLIER","")) | I187: =IF(F187="","",IF(F187>$I$5,"OUTLIER","")) | J187: =IF(G187="","",IF(G187>$I$5,"OUTLIER","")) | K187: =IF(C187="","MISSING","") | M187: =IF(D187="","",ABS(D187-G$5)) -> 0.00053292138
B188: 44088 | C188: 3383.54 | D188: =IF(OR(C188="",C187=""),"",LN(C188/C187)) -> 0.012661315 | E188: =IF(D188="","",ABS(D188-$E$5)/$F$5) -> 0.71130417 | F188: =IF(D188="","",ABS(D188-$G$5)/$H$5) -> 1.3324773 | G188: =IF(D188="","",ABS(D188-$E$5)/SQRT(0.9*(IF(G187="",($F$5)^2,(ABS(D187-$E$5)/MAX(G187,0.0000000001))^2))+0.1*(D188-$E$5)^2)) -> 0.74891355 | H188: =IF(E188="","",IF(E188>$I$5,"OUTLIER","")) | I188: =IF(F188="","",IF(F188>$I$5,"OUTLIER","")) | J188: =IF(G188="","",IF(G188>$I$5,"OUTLIER","")) | K188: =IF(C188="","MISSING","") | M188: =IF(D188="","",ABS(D188-G$5)) -> 0.012661315
B189: 44089 | C189: 3401.2 | D189: =IF(OR(C189="",C188=""),"",LN(C189/C188)) -> 0.0052058118 | E189: =IF(D189="","",ABS(D189-$E$5)/$F$5) -> 0.265167 | F189: =IF(D189="","",ABS(D189-$G$5)/$H$5) -> 0.54785985 | G189: =IF(D189="","",ABS(D189-$E$5)/SQRT(0.9*(IF(G188="",($F$5)^2,(ABS(D188-$E$5)/MAX(G188,0.0000000001))^2))+0.1*(D189-$E$5)^2)) -> 0.29302321 | H189: =IF(E189="","",IF(E189>$I$5,"OUTLIER","")) | I189: =IF(F189="","",IF(F189>$I$5,"OUTLIER","")) | J189: =IF(G189="","",IF(G189>$I$5,"OUTLIER","")) | K189: =IF(C189="","MISSING","") | M189: =IF(D189="","",ABS(D189-G$5)) -> 0.0052058118
...

Sheet RF3 EURUSD
B1: RF3: EUR/USD FX Rate
B2: Return Type: Log Returns | Z-Score Threshold: 3.0 | EWMA Parameters: N=30, λ=0.9
B4: GLOBAL STATISTICS (Full Series) | E4: Mean Return | F4: Std Dev (σ) | G4: Median Return | H4: Scaled MAD (σ̂) | I4: Cutoff (c) | M4: MAD Helper (|r - median|)
E5: =AVERAGE(D10:D264,D269:D522,D529:D785) -> 0.00013786845 | F5: =STDEV(D10:D264,D269:D522,D529:D785) -> 0.0050448712 | G5: =MEDIAN(D10:D264,D269:D522,D529:D785) -> 0 | H5: =_xlfn.AGGREGATE(16,6,M9:M785,0.5)/0.6745 -> 0.0029904432 | I5: 3
B7: ="YEAR 2020 | Observations: "&COUNTA(C10:C264)&" | Missing: "&COUNTIF(K10:K264,"MISSING")&" | Stale: "&COUNTIF(L10:L264,"STALE")&" | Z>3 Outliers: "&COUNTIF(H10:H264,"OUTLIER")&" | Robust Z>3: "&COUNTIF(I10:I264,"OUTLIER") -> YEAR 2020 | Observations: 248 | Missing: 7 | Stale: 5 | Z>3 Outliers: 3 | Robust Z>3: 20
B8: Date | C8: Level | D8: Return | E8: Z-Score | F8: Robust Z | G8: EWMA Z | H8: Z>3 Flag | I8: RobZ>3 | J8: EWMA>3 | K8: Missing? | L8: Stale? | M8: |r - median|
B9: 43831 | K9: =IF(C9="","MISSING","") -> MISSING | M9: =IF(D9="","",ABS(D9-G$5))
B10: 43832 | C10: 1.1166 | D10: =IF(OR(C10="",C9=""),"",LN(C10/C9)) | E10: =IF(D10="","",ABS(D10-$E$5)/$F$5) | F10: =IF(D10="","",ABS(D10-$G$5)/$H$5) | G10: =IF(D10="","",ABS(D10-$E$5)/SQRT(0.9*(IF(G9="",$F$5^2,(ABS(D9-$E$5)/MAX(G9,0.0000000001))^2))+0.1*(D10-$E$5)^2)) | H10: =IF(E10="","",IF(E10>$I$5,"OUTLIER","")) | I10: =IF(F10="","",IF(F10>$I$5,"OUTLIER","")) | J10: =IF(G10="","",IF(G10>$I$5,"OUTLIER","")) | K10: =IF(C10="","MISSING","") | L10: =IF(AND(C10<>"",C9<>"",C10=C9),"STALE","") | M10: =IF(D10="","",ABS(D10-G$5))
B11: 43833 | C11: 1.1173 | D11: =IF(OR(C11="",C10=""),"",LN(C11/C10)) -> 0.00062670668 | E11: =IF(D11="","",ABS(D11-$E$5)/$F$5) -> 0.096898059 | F11: =IF(D11="","",ABS(D11-$G$5)/$H$5) -> 0.20956983 | G11: =IF(D11="","",ABS(D11-$E$5)/SQRT(0.9*(IF(G10="",$F$5^2,(ABS(D10-$E$5)/MAX(G10,0.0000000001))^2))+0.1*(D11-$E$5)^2)) -> 0.10208629 | H11: =IF(E11="","",IF(E11>$I$5,"OUTLIER","")) | I11: =IF(F11="","",IF(F11>$I$5,"OUTLIER","")) | J11: =IF(G11="","",IF(G11>$I$5,"OUTLIER","")) | K11: =IF(C11="","MISSING","") | L11: =IF(AND(C11<>"",C10<>"",C11=C10),"STALE","") | M11: =IF(D11="","",ABS(D11-G$5)) -> 0.00062670668
B12: 43836 | C12: 1.1187 | D12: =IF(OR(C12="",C11=""),"",LN(C12/C11)) -> 0.0012522363 | E12: =IF(D12="","",ABS(D12-$E$5)/$F$5) -> 0.22089124 | F12: =IF(D12="","",ABS(D12-$G$5)/$H$5) -> 0.41874605 | G12: =IF(D12="","",ABS(D12-$E$5)/SQRT(0.9*(IF(G11="",$F$5^2,(ABS(D11-$E$5)/MAX(G11,0.0000000001))^2))+0.1*(D12-$E$5)^2)) -> 0.24457203 | H12: =IF(E12="","",IF(E12>$I$5,"OUTLIER","")) | I12: =IF(F12="","",IF(F12>$I$5,"OUTLIER","")) | J12: =IF(G12="","",IF(G12>$I$5,"OUTLIER","")) | K12: =IF(C12="","MISSING","") | L12: =IF(AND(C12<>"",C11<>"",C12=C11),"STALE","") | M12: =IF(D12="","",ABS(D12-G$5)) -> 0.0012522363
B13: 43837 | C13: 1.1138 | D13: =IF(OR(C13="",C12=""),"",LN(C13/C12)) -> -0.0043897047 | E13: =IF(D13="","",ABS(D13-$E$5)/$F$5) -> 0.8974606 | F13: =IF(D13="","",ABS(D13-$G$5)/$H$5) -> 1.4679111 | G13: =IF(D13="","",ABS(D13-$E$5)/SQRT(0.9*(IF(G12="",$F$5^2,(ABS(D12-$E$5)/MAX(G12,0.0000000001))^2))+0.1*(D13-$E$5)^2)) -> 0.99430071 | H13: =IF(E13="","",IF(E13>$I$5,"OUTLIER","")) | I13: =IF(F13="","",IF(F13>$I$5,"OUTLIER","")) | J13: =IF(G13="","",IF(G13>$I$5,"OUTLIER","")) | K13: =IF(C13="","MISSING","") | L13: =IF(AND(C13<>"",C12<>"",C13=C12),"STALE","") | M13: =IF(D13="","",ABS(D13-G$5)) -> 0.0043897047
B14: 43838 | C14: 1.1117 | D14: =IF(OR(C14="",C13=""),"",LN(C14/C13)) -> -0.0018872169 | E14: =IF(D14="","",ABS(D14-$E$5)/$F$5) -> 0.40141468 | F14: =IF(D14="","",ABS(D14-$G$5)/$H$5) -> 0.63108268 | G14: =IF(D14="","",ABS(D14-$E$5)/SQRT(0.9*(IF(G13="",$F$5^2,(ABS(D13-$E$5)/MAX(G13,0.0000000001))^2))+0.1*(D14-$E$5)^2)) -> 0.46371805 | H14: =IF(E14="","",IF(E14>$I$5,"OUTLIER","")) | I14: =IF(F14="","",IF(F14>$I$5,"OUTLIER","")) | J14: =IF(G14="","",IF(G14>$I$5,"OUTLIER","")) | K14: =IF(C14="","MISSING","") | L14: =IF(AND(C14<>"",C13<>"",C14=C13),"STALE","") | M14: =IF(D14="","",ABS(D14-G$5)) -> 0.0018872169
B15: 43839 | C15: 1.1117 | D15: =IF(OR(C15="",C14=""),"",LN(C15/C14)) -> 0 | E15: =IF(D15="","",ABS(D15-$E$5)/$F$5) -> 0.027328438 | F15: =IF(D15="","",ABS(D15-$G$5)/$H$5) -> 0 | G15: =IF(D15="","",ABS(D15-$E$5)/SQRT(0.9*(IF(G14="",$F$5^2,(ABS(D14-$E$5)/MAX(G14,0.0000000001))^2))+0.1*(D15-$E$5)^2)) -> 0.033275935 | H15: =IF(E15="","",IF(E15>$I$5,"OUTLIER","")) | I15: =IF(F15="","",IF(F15>$I$5,"OUTLIER","")) | J15: =IF(G15="","",IF(G15>$I$5,"OUTLIER","")) | K15: =IF(C15="","MISSING","") | L15: =IF(AND(C15<>"",C14<>"",C15=C14),"STALE","") -> STALE | M15: =IF(D15="","",ABS(D15-G$5)) -> 0
B16: 43840 | C16: 1.1114 | D16: =IF(OR(C16="",C15=""),"",LN(C16/C15)) -> -0.00026989339 | E16: =IF(D16="","",ABS(D16-$E$5)/$F$5) -> 0.080827008 | F16: =IF(D16="","",ABS(D16-$G$5)/$H$5) -> 0.090251971 | G16: =IF(D16="","",ABS(D16-$E$5)/SQRT(0.9*(IF(G15="",$F$5^2,(ABS(D15-$E$5)/MAX(G15,0.0000000001))^2))+0.1*(D16-$E$5)^2)) -> 0.10368529 | H16: =IF(E16="","",IF(E16>$I$5,"OUTLIER","")) | I16: =IF(F16="","",IF(F16>$I$5,"OUTLIER","")) | J16: =IF(G16="","",IF(G16>$I$5,"OUTLIER","")) | K16: =IF(C16="","MISSING","") | L16: =IF(AND(C16<>"",C15<>"",C16=C15),"STALE","") | M16: =IF(D16="","",ABS(D16-G$5)) -> 0.00026989339
B17: 43843 | C17: 1.1148 | D17: =IF(OR(C17="",C16=""),"",LN(C17/C16)) -> 0.0030545348 | E17: =IF(D17="","",ABS(D17-$E$5)/$F$5) -> 0.57814485 | F17: =IF(D17="","",ABS(D17-$G$5)/$H$5) -> 1.0214321 | G17: =IF(D17="","",ABS(D17-$E$5)/SQRT(0.9*(IF(G16="",$F$5^2,(ABS(D16-$E$5)/MAX(G16,0.0000000001))^2))+0.1*(D17-$E$5)^2)) -> 0.7589177 | H17: =IF(E17="","",IF(E17>$I$5,"OUTLIER","")) | I17: =IF(F17="","",IF(F17>$I$5,"OUTLIER","")) | J17: =IF(G17="","",IF(G17>$I$5,"OUTLIER","")) | K17: =IF(C17="","MISSING","") | L17: =IF(AND(C17<>"",C16<>"",C17=C16),"STALE","") | M17: =IF(D17="","",ABS(D17-G$5)) -> 0.0030545348
B18: 43844 | C18: 1.1113 | D18: =IF(OR(C18="",C17=""),"",LN(C18/C17)) -> -0.0031445154 | E18: =IF(D18="","",ABS(D18-$E$5)/$F$5) -> 0.65063779 | F18: =IF(D18="","",ABS(D18-$G$5)/$H$5) -> 1.0515215 | G18: =IF(D18="","",ABS(D18-$E$5)/SQRT(0.9*(IF(G17="",$F$5^2,(ABS(D17-$E$5)/MAX(G17,0.0000000001))^2))+0.1*(D18-$E$5)^2)) -> 0.865871 | H18: =IF(E18="","",IF(E18>$I$5,"OUTLIER","")) | I18: =IF(F18="","",IF(F18>$I$5,"OUTLIER","")) | J18: =IF(G18="","",IF(G18>$I$5,"OUTLIER","")) | K18: =IF(C18="","MISSING","") | L18: =IF(AND(C18<>"",C17<>"",C18=C17),"STALE","") | M18: =IF(D18="","",ABS(D18-G$5)) -> 0.0031445154
B19: 43845 | C19: 1.1155 | D19: =IF(OR(C19="",C18=""),"",LN(C19/C18)) -> 0.0037722337 | E19: =IF(D19="","",ABS(D19-$E$5)/$F$5) -> 0.72040793 | F19: =IF(D19="","",ABS(D19-$G$5)/$H$5) -> 1.2614296 | G19: =IF(D19="","",ABS(D19-$E$5)/SQRT(0.9*(IF(G18="",$F$5^2,(ABS(D18-$E$5)/MAX(G18,0.0000000001))^2))+0.1*(D19-$E$5)^2)) -> 0.9626208 | H19: =IF(E19="","",IF(E19>$I$5,"OUTLIER","")) | I19: =IF(F19="","",IF(F19>$I$5,"OUTLIER","")) | J19: =IF(G19="","",IF(G19>$I$5,"OUTLIER","")) | K19: =IF(C19="","MISSING","") | L19: =IF(AND(C19<>"",C18<>"",C19=C18),"STALE","") | M19: =IF(D19="","",ABS(D19-G$5)) -> 0.0037722337
B20: 43846 | C20: 1.115 | D20: =IF(OR(C20="",C19=""),"",LN(C20/C19)) -> -0.00044832998 | E20: =IF(D20="","",ABS(D20-$E$5)/$F$5) -> 0.11619691 | F20: =IF(D20="","",ABS(D20-$G$5)/$H$5) -> 0.14992091 | G20: =IF(D20="","",ABS(D20-$E$5)/SQRT(0.9*(IF(G19="",$F$5^2,(ABS(D19-$E$5)/MAX(G19,0.0000000001))^2))+0.1*(D20-$E$5)^2)) -> 0.16344408 | H20: =IF(E20="","",IF(E20>$I$5,"OUTLIER","")) | I20: =IF(F20="","",IF(F20>$I$5,"OUTLIER","")) | J20: =IF(G20="","",IF(G20>$I$5,"OUTLIER","")) | K20: =IF(C20="","MISSING","") | L20: =IF(AND(C20<>"",C19<>"",C20=C19),"STALE","") | M20: =IF(D20="","",ABS(D20-G$5)) -> 0.00044832998
B21: 43847 | C21: 1.109 | D21: =IF(OR(C21="",C20=""),"",LN(C21/C20)) -> -0.0053956965 | E21: =IF(D21="","",ABS(D21-$E$5)/$F$5) -> 1.0968694 | F21: =IF(D21="","",ABS(D21-$G$5)/$H$5) -> 1.8043133 | G21: =IF(D21="","",ABS(D21-$E$5)/SQRT(0.9*(IF(G20="",$F$5^2,(ABS(D20-$E$5)/MAX(G20,0.0000000001))^2))+0.1*(D21-$E$5)^2)) -> 1.4462716 | H21: =IF(E21="","",IF(E21>$I$5,"OUTLIER","")) | I21: =IF(F21="","",IF(F21>$I$5,"OUTLIER","")) | J21: =IF(G21="","",IF(G21>$I$5,"OUTLIER","")) | K21: =IF(C21="","MISSING","") | L21: =IF(AND(C21<>"",C20<>"",C21=C20),"STALE","") | M21: =IF(D21="","",ABS(D21-G$5)) -> 0.0053956965
B22: 43850 | D22: =IF(OR(C22="",C21=""),"",LN(C22/C21)) | E22: =IF(D22="","",ABS(D22-$E$5)/$F$5) | F22: =IF(D22="","",ABS(D22-$G$5)/$H$5) | G22: =IF(D22="","",ABS(D22-$E$5)/SQRT(0.9*(IF(G21="",$F$5^2,(ABS(D21-$E$5)/MAX(G21,0.0000000001))^2))+0.1*(D22-$E$5)^2)) | H22: =IF(E22="","",IF(E22>$I$5,"OUTLIER","")) | I22: =IF(F22="","",IF(F22>$I$5,"OUTLIER","")) | J22: =IF(G22="","",IF(G22>$I$5,"OUTLIER","")) | K22: =IF(C22="","MISSING","") -> MISSING | L22: =IF(AND(C22<>"",C21<>"",C22=C21),"STALE","") | M22: =IF(D22="","",ABS(D22-G$5))
B23: 43851 | C23: 1.1089 | D23: =IF(OR(C23="",C22=""),"",LN(C23/C22)) | E23: =IF(D23="","",ABS(D23-$E$5)/$F$5) | F23: =IF(D23="","",ABS(D23-$G$5)/$H$5) | G23: =IF(D23="","",ABS(D23-$E$5)/SQRT(0.9*(IF(G22="",$F$5^2,(ABS(D22-$E$5)/MAX(G22,0.0000000001))^2))+0.1*(D23-$E$5)^2)) | H23: =IF(E23="","",IF(E23>$I$5,"OUTLIER","")) | I23: =IF(F23="","",IF(F23>$I$5,"OUTLIER","")) | J23: =IF(G23="","",IF(G23>$I$5,"OUTLIER","")) | K23: =IF(C23="","MISSING","") | L23: =IF(AND(C23<>"",C22<>"",C23=C22),"STALE","") | M23: =IF(D23="","",ABS(D23-G$5))
