Workbook

Sheet TestingPnL
A1: COB | B1: global_position_id | C1: bu risk_system | D1: book | E1: ticket | F1: asset class | G1: measure name | H1: measure usd | I1: mrd mark | J1: measure mark | K1: term of measure | L1: expiration date | M1: ccvar term | N1: rf curve name | O1: index sector | P1: index_region | Q1: index_family | R1: ccvar tenor bucket 4 | S1: ccvar tenor bucket 2 | T1: ccc_product line | U1: baac_pl_rpt_region | V1: pnL | W1: index_subsector
A2: 45306 | B2: 2122287473 | C2: EQUITY_NY.ADEELQ | D2: EXOTICS NAM adeelq | E2: [NULL] | F2: ir | G2: asset_pv01spread | H2: -146.5032 | I2: [NULL] | J2: [NULL] | K2: 1792 | L2: 1 | M2: 1792 | N2: ig41v1 | O2: IG | P2: NA | Q2: CDX | R2: 3-10 | S2: 0-5 | T2: EXOTIC PRODUCTS | U2: NORTH AMERICA | V2: 0 | W2: .
A3: 45306 | B3: 2117362004 | C3: EQUITY_NY.PAlNEMlC3SO | D3: EXOTICS NAM painemic | E3: [NULL] | F3: ir | G3: asset_pv01spread | H3: -109.10121 | I3: [NULL] | J3: [NULL] | K3: 0 | L3: 1 | M3: 0 | N3: ig41v1 | O3: IG | P3: NA | Q3: CDX | R3: 0-1 | S3: 0-5 | T3: EXOTIC PRODUCTS | U3: NORTH AMERICA | V3: 0 | W3: .
A4: 45306 | B4: 2119679880 | C4: EQUITY_NY.ADEELQ | D4: EXOTICS NAM adeelq | E4: [NULL] | F4: ir | G4: asset_pv01spread | H4: -43.367568 | I4: [NULL] | J4: [NULL] | K4: 1609 | L4: 1 | M4: 1609 | N4: ig40v1 | O4: IG | P4: NA | Q4: CDX | R4: 3-10 | S4: 0-5 | T4: EXOTIC PRODUCTS | U4: NORTH AMERICA | V4: 0 | W4: .
A5: 45306 | B5: 2118770188 | C5: EQUITY_NY.ADEELQ | D5: EXOTICS NAM adeelq | E5: [NULL] | F5: ir | G5: asset_pv01spread | H5: -43.00736 | I5: [NULL] | J5: [NULL] | K5: 0 | L5: 1 | M5: 0 | N5: ig41v1 | O5: IG | P5: NA | Q5: CDX | R5: 0-1 | S5: 0-5 | T5: EXOTIC PRODUCTS | U5: NORTH AMERICA | V5: 0 | W5: .
A6: 45306 | B6: 2122280819 | C6: EQUITY_LN.ISSAMC | D6: CONVERTIBLES NAM murmic | E6: [NULL] | F6: ir | G6: asset_pv01spread | H6: -36.458521 | I6: [NULL] | J6: [NULL] | K6: 1061 | L6: 1 | M6: 1061 | N6: itrx36_eur | O6: IG | P6: EU | Q6: ITRAXX-European | R6: 1-3 | S6: 0-5 | T6: CONVERTIBLE PRODUCTS | U6: NORTH AMERICA | V6: -30.625158 | W6: .
A7: 45306 | B7: 2123457722 | C7: EQUITY_LN.BOUTAOMA | D7: EXOTICS EUR boutaoma | E7: [NULL] | F7: ir | G7: asset_pv01spread | H7: -31.673077 | I7: [NULL] | J7: [NULL] | K7: 1778 | L7: 1 | M7: 1778 | N7: hy41v2 | O7: HY | P7: NA | Q7: CDX | R7: 3-10 | S7: 0-5 | T7: EXOTIC PRODUCTS | U7: EUROPE | V7: 0 | W7: .
A8: 45306 | B8: 2122891849 | C8: EQUITY_LN.ANOUARK | D8: EXOTICS EUR anouark | E8: [NULL] | F8: ir | G8: asset_pv01spread | H8: -25.953275 | I8: [NULL] | J8: [NULL] | K8: 625 | L8: 1 | M8: 625 | N8: hy41v2 | O8: HY | P8: NA | Q8: CDX | R8: 1-3 | S8: 0-5 | T8: EXOTIC PRODUCTS | U8: EUROPE | V8: 0 | W8: .
A9: 45306 | B9: 507elzc | C9: C1_ LN.TRACER | D9: EQETC | E9: 507elzc | F9: ir | G9: pv01sprd comp | H9: -23.716067 | I9: 181.12961 | J9: 181.12961 | K9: 1059 | L9: 1 | M9: 1059 | N9: itrx36 _xo2 | O9: CO | P9: EU | Q9: ITRAXX-European | R9: 1-3 | S9: 0-5 | T9: CONVERTIBLE PRODUCTS | U9: EUROPE | V9: -190.67718 | W9: .
A10: 45306 | B10: 54ftedh | C10: C1_ LN.TRACER | D10: EQETC | E10: 54ftedh | F10: ir | G10: pv01sprd comp | H10: -21.958534 | I10: 203.66252 | J10: 203.62258 | K10: 1240 | L10: 1 | M10: 1240 | N10: itrx37 _xo2 | O10: CO | P10: EU | Q10: ITRAXX-European | R10: 3-10 | S10: 0-5 | T10: CONVERTIBLE PRODUCTS | U10: EUROPE | V10: -176.54661 | W10: .
A11: 45306 | B11: 507epfd | C11: C1_ LN.TRACER | D11: EQETC | E11: 507epfd | F11: ir | G11: pv01sprd comp | H11: -20.553924 | I11: 181.12961 | J11: 181.12961 | K11: 1059 | L11: 1 | M11: 1059 | N11: itrx36 _xo2 | O11: CO | P11: EU | Q11: ITRAxx-European | R11: 1-3 | S11: 0-5 | T11: CONVERTIBLE PRODUCTS | U11: EUROPE | V11: -165.25355 | W11: .
A12: 45306 | B12: 2122435341 | C12: EQUITY_NY.ADEELQ | D12: EXOTICS NAM adeelq | E12: [NULL] | F12: ir | G12: asset_pv01spread | H12: -20.523548 | I12: [NULL] | J12: [NULL] | K12: 1792 | L12: 1 | M12: 1792 | N12: ig41v1 | O12: IG | P12: NA | Q12: CDX | R12: 3-10 | S12: 0-5 | T12: EXOTIC PRODUCTS | U12: NORTH AMERICA | V12: 0 | W12: .
A13: 45306 | B13: 2121956220 | C13: EQUITY_NY.ADEELQ | D13: EXOTICS NAM adeelq | E13: [NULL] | F13: ir | G13: asset_pv01spread | H13: -19.89338 | I13: [NULL] | J13: [NULL] | K13: 1609 | L13: 1 | M13: 1609 | N13: ig40v1 | O13: IG | P13: NA | Q13: CDX | R13: 3-10 | S13: 0-5 | T13: EXOTIC PRODUCTS | U13: NORTH AMERICA | V13: 0 | W13: .
A14: 45306 | B14: 2123457227 | C14: EQUITY_LN.ISSAMC | D14: EXOTICS EUR issamc | E14: [NULL] | F14: ir | G14: asset_pv01spread | H14: -19.631408 | I14: [NULL] | J14: [NULL] | K14: 625 | L14: 1 | M14: 625 | N14: hy41v2 | O14: HY | P14: NA | Q14: CDX | R14: 1-3 | S14: 0-5 | T14: EXOTIC PRODUCTS | U14: EUROPE | V14: 0 | W14: .
A15: 45306 | B15: 2116682530 | C15: EQUITY_LN.ISSAMC | D15: EXOTICS EUR issamc | E15: [NULL] | F15: ir | G15: asset_pv01spread | H15: -19.559163 | I15: [NULL] | J15: [NULL] | K15: 1243 | L15: 1 | M15: 1243 | N15: ig38v1 | O15: IG | P15: NA | Q15: CDX | R15: 3-10 | S15: 0-5 | T15: EXOTIC PRODUCTS | U15: EUROPE | V15: 0 | W15: .
A16: 45306 | B16: 2121116022 | C16: EQUITY_NY.MURMIC | D16: CONVERTIBLES NAM murmic | E16: [NULL] | F16: ir | G16: asset_pv01spread | H16: -16.069766 | I16: [NULL] | J16: [NULL] | K16: 1426 | L16: 1 | M16: 1426 | N16: hy39v3 | O16: HY | P16: NA | Q16: CDX | R16: 3-10 | S16: 0-5 | T16: CONVERTIBLE PRODUCTS | U16: NORTH AMERICA | V16: 0 | W16: .
A17: 45306 | B17: 2122287272 | C17: EQUITY_NY.ADEELQ | D17: EXOTICS NAM adeelq | E17: [NULL] | F17: ir | G17: asset_pv01spread | H17: -14.846822 | I17: [NULL] | J17: [NULL] | K17: 1792 | L17: 1 | M17: 1792 | N17: ig41v1 | O17: IG | P17: NA | Q17: CDX | R17: 3-10 | S17: 0-5 | T17: EXOTIC PRODUCTS | U17: NORTH AMERICA | V17: 0 | W17: .
A18: 45306 | B18: 2118937042 | C18: EQUITY_NY.ADEELQ | D18: EXOTICS NAM adeelq | E18: [NULL] | F18: ir | G18: asset_pv01spread | H18: -14.445735 | I18: [NULL] | J18: [NULL] | K18: 1426 | L18: 1 | M18: 1426 | N18: ig39v1 | O18: IG | P18: NA | Q18: CDX | R18: 3-10 | S18: 0-5 | T18: EXOTIC PRODUCTS | U18: NORTH AMERICA | V18: 0 | W18: .
A19: 45306 | B19: 2124173755 | C19: EQUITY_NY.ADEELQ | D19: EXOTICS NAM adeelq | E19: [NULL] | F19: ir | G19: asset_pv01spread | H19: -14.410151 | I19: [NULL] | J19: [NULL] | K19: 1792 | L19: 1 | M19: 1792 | N19: ig41v1 | O19: IG | P19: NA | Q19: CDX | R19: 3-10 | S19: 0-5 | T19: EXOTIC PRODUCTS | U19: NORTH AMERICA | V19: 0 | W19: .
A20: 45306 | B20: 2122542214 | C20: EQUITY_LN.ISSAMC | D20: EXOTICS EUR issamc | E20: [NULL] | F20: ir | G20: asset_pv01spread | H20: -13.994548 | I20: [NULL] | J20: [NULL] | K20: 1792 | L20: 1 | M20: 1792 | N20: ig41v1 | O20: IG | P20: NA | Q20: CDX | R20: 3-10 | S20: 0-5 | T20: EXOTIC PRODUCTS | U20: EUROPE | V20: 0 | W20: .
A21: 45306 | B21: 2122893484 | C21: EQUITY_LN.BOUTAOMA | D21: EXOTICS EUR boutaoma | E21: [NULL] | F21: ir | G21: asset_pv01spread | H21: -13.724138 | I21: [NULL] | J21: [NULL] | K21: 1742 | L21: 1 | M21: 0 | N21: ig41v1 | O21: IG | P21: NA | Q21: CDX | R21: 3-10 | S21: 0-5 | T21: EXOTIC PRODUCTS | U21: EUROPE | V21: 0 | W21: .
A22: 45306 | B22: 54fx7h8 | C22: C1_ LN.TRACER | D22: EQCOP | E22: 54fx7h8 | F22: ir | G22: pv01sprd comp | H22: -13.67009 | I22: 325.32086 | J22: 325.32082 | K22: 1787 | L22: 1 | M22: 1787 | N22: itrx40_xo | O22: CO | P22: EU | Q22: ITRAXX-European | R22: 3-10 | S22: 0-5 | T22: CORPORATE EQUITY PRODUCTS | U22: EUROPE | V22: -109.90752 | W22: .
A23: 45306 | B23: 2122015535 | C23: EQUITY NY.ADEELQ_ | D23: EXOTICS NAM adeelq | E23: [NULL] | F23: ir | G23: asset_pv01spread | H23: -13.527498 | I23: [NULL] | J23: [NULL] | K23: 1609 | L23: 1 | M23: 1609 | N23: ig40v1 | O23: IG | P23: NA | Q23: CDX | R23: 3-10 | S23: 0-5 | T23: EXOTIC PRODUCTS | U23: NORTH AMERICA | V23: 0 | W23: .
A24: 45306 | B24: 2122542210 | C24: EQUITY LN.ISSAMC_ | D24: EXOTICS EUR issamc | E24: [NULL] | F24: ir | G24: asset_pv01spread | H24: -13.300264 | I24: [NULL] | J24: [NULL] | K24: 1792 | L24: 1 | M24: 1792 | N24: itrx40_eur | O24: IG | P24: EU | Q24: ITRAXX-European | R24: 3-10 | S24: 0-5 | T24: EXOTIC PRODUCTS | U24: EUROPE | V24: -11.172222 | W24: .
A25: 45306 | B25: 2114902387 | C25: EQUITY LN.ISSAMC_ | D25: EXOTICS EUR issamc | E25: [NULL] | F25: ir | G25: asset_pv01spread | H25: -12.768633 | I25: [NULL] | J25: [NULL] | K25: 2887 | L25: 1 | M25: 2887 | N25: ig37v1 | O25: IG | P25: NA | Q25: CDX | R25: 3-10 | S25: 5+ | T25: EXOTIC PRODUCTS | U25: EUROPE | V25: 0 | W25: .
A26: 45306 | B26: 2123984227 | C26: EQUITY LN.ISSAMC_ | D26: EXOTICS EUR issamc | E26: [NULL] | F26: ir | G26: asset_pv01spread | H26: -12.766484 | I26: [NULL] | J26: [NULL] | K26: 1792 | L26: 1 | M26: 1792 | N26: hy41v2 | O26: HY | P26: NA | Q26: CDX | R26: 3-10 | S26: 0-5 | T26: EXOTIC PRODUCTS | U26: EUROPE | V26: 0 | W26: .
A27: 45306 | B27: 2119096050 | C27: EQUITY_NY.MURMIC | D27: CONVERTIBLES NAM murmic | E27: [NULL] | F27: ir | G27: asset_pv01spread | H27: -12.727713 | I27: [NULLI | J27: [NULL] | K27: 1061 | L27: 1 | M27: 1061 | N27: hy37v4 | O27: HY | P27: NA | Q27: CDX | R27: 1-3 | S27: 0-5 | T27: CONVERTIBLE PRODUCTS | U27: NORTH_AMERICA | V27: 0 | W27: .
A28: 45306 | B28: 218726570 | C28: EQUITY_LN.ISSAMC | D28: EXOTICS EUR issamc | E28: [NULL] | F28: ir | G28: asset_pv01spread | H28: -12.533436 | I28: [NULLI | J28: [NULL] | K28: 0 | L28: 1 | M28: 0 | N28: ig41v1 | O28: IG | P28: NA | Q28: CDX | R28: 0-1 | S28: 0-5 | T28: EXOTIC PRODUCTS | U28: EUROPE | V28: 0 | W28: .
A29: 45306 | B29: 2122382254 | C29: EQUITY_NY.MURMIC | D29: CONVERTIBLES NAM murmic | E29: [NULL] | F29: ir | G29: asset_pv01spread | H29: -12.480352 | I29: [NULL] | J29: [NULL] | K29: 1609 | L29: 1 | M29: 1609 | N29: hy40v2 | O29: HY | P29: NA | Q29: CDX | R29: 3-10 | S29: 0-5 | T29: CONVERTIBLE PRODUCTS | U29: NORTH_AMERICA | V29: 0 | W29: .
A30: 45306 | B30: 2122893482 | C30: EQUITY_LN.BOUTAOMA | D30: EXOTICS EUR boutaoma | E30: [NULL] | F30: ir | G30: asset_pv01spread | H30: -12.227057 | I30: [NULLI | J30: [NULL] | K30: 1742 | L30: 1 | M30: 1742 | N30: itrx40_eur | O30: IG | P30: EU | Q30: ITRAXX-European | R30: 3-10 | S30: 0-5 | T30: EXOTIC PRODUCTS | U30: EUROPE | V30: -10.270728 | W30: .
A31: 45306 | B31: 216229993 | C31: EQUITY_LN.BOUTAOMA | D31: EXOTICS EUR boutaoma | E31: [NULL] | F31: ir | G31: asset_pv01spread | H31: -12.324176 | I31: [NULLI | J31: [NULL] | K31: 484 | L31: 1 | M31: 484 | N31: itrx40_eur | O31: IG | P31: EU | Q31: ITRAXX-European | R31: 1-3 | S31: 0-5 | T31: EXOTIC PRODUCTS | U31: EUROPE | V31: -10.352308 | W31: .
A32: 45306 | B32: 2114902381 | C32: EQUITY_LN.ISSAMC | D32: EXOTICS EUR issamc | E32: [NULL] | F32: ir | G32: asset_pv01spread | H32: -12.234236 | I32: [NULLI | J32: [NULL] | K32: 1061 | L32: 1 | M32: 1061 | N32: ig37v1 | O32: IG | P32: NA | Q32: CDX | R32: 1-3 | S32: 0-5 | T32: EXOTIC PRODUCTS | U32: EUROPE | V32: 0 | W32: .
A33: 45306 | B33: 216229991 | C33: EQUITY_LN.BOUTAOMA | D33: EXOTICS EUR boutaoma | E33: [NULL] | F33: ir | G33: asset_pv01spread | H33: -11.956849 | I33: [NULL] | J33: [NULL] | K33: 484 | L33: 1 | M33: 484 | N33: ig41v1 | O33: IG | P33: NA | Q33: CDX | R33: 1-3 | S33: 0-5 | T33: EXOTIC PRODUCTS | U33: EUROPE | V33: 0 | W33: .
A34: 45306 | B34: 2119702862 | C34: EQUITY_NY.PAlNEMlC.2 | D34: EXOTICS NAM painemic | E34: [NULL] | F34: ir | G34: asset_pv01spread | H34: -11.558622 | I34: [NULLI | J34: [NULL] | K34: 0 | L34: 1 | M34: 0 | N34: ig41v1 | O34: IG | P34: NA | Q34: CDX | R34: 0-1 | S34: 0-5 | T34: EXOTIC PRODUCTS | U34: NORTH_AMERICA | V34: 0 | W34: .
... A37: 45306 | B37: 2122557228 | C37: EQUITY_NY.ADEELQ | D37: EXOTICS NAM adeelq | E37: [NULL] | F37: ir | G37: asset_pv01spread | H37: -10.916781 | I37: [NULL] | J37: [NULL] | K37: 1792 | L37: 1 | M37: 1792 | N37: ig41v1 | O37: IG | P37: NA | Q37: CDX | R37: 3-10 | S37: 0-5 | T37: EXOTIC PRODUCTS | U37: NORTH_AMERICA | V37: 0 | W37: .
A38: 45306 | B38: p65tf | C38: C1_LN.TRACER | D38: EQETC | E38: p65tf | F38: ir | G38: pv01sprd comp | H38: -10.852645 | I38: 32.773441 | J38: 32.773441 | K38: 1059 | L38: 1 | M38: 1059 | N38: itrx36_eur | O38: IG | P38: EU | Q38: ITRAXX-European | R38: 1-3 | S38: 0-5 | T38: CONVERTIBLE PRODUCTS | U38: EUROPE | V38: -9.1162218 | W38: .
A39: 45306 | B39: 218707351 | C39: EQUITY_LN.ISSAMC | D39: EXOTICS EUR issamc | E39: [NULL] | F39: ir | G39: asset_pv01spread | H39: -10.676226 | I39: [NULLI | J39: [NULL] | K39: 0 | L39: 1 | M39: 0 | N39: itrx40_eur | O39: IG | P39: EU | Q39: ITRAXX-European | R39: 0-1 | S39: 0-5 | T39: EXOTIC PRODUCTS | U39: EUROPE | V39: -8.9680298 | W39: .
A40: 45306 | B40: 219938036 | C40: EQUITY_LN.BOUTAOMA | D40: EXOTICS EUR boutaoma | E40: [NULL] | F40: ir | G40: asset_pv01spread | H40: -10.437324 | I40: [NULLI | J40: [NULL] | K40: 0 | L40: 1 | M40: 0 | N40: itrx40_eur | O40: IG | P40: EU | Q40: ITRAXX-European | R40: 0-1 | S40: 0-5 | T40: EXOTIC PRODUCTS | U40: EUROPE | V40: -8.7673522 | W40: .
A41: 45306 | B41: 2120161046 | C41: EQUITY_LN.ISSAMC | D41: EXOTICS EUR issamc | E41: [NULL] | F41: ir | G41: asset_pv01spread | H41: -10.417903 | I41: [NULL] | J41: [NULL] | K41: 3253 | L41: 1 | M41: 3253 | N41: ig39v1 | O41: IG | P41: NA | Q41: CDX | R41: 3-10 | S41: 5+ | T41: EXOTIC PRODUCTS | U41: EUROPE | V41: 0 | W41: .
A42: 45306 | B42: 2123595875 | C42: EQUITY_NY.ADEELQ | D42: EXOTICS NAM adeelq | E42: [NULL] | F42: ir | G42: asset_pv01spread | H42: -10.261774 | I42: [NULLI | J42: [NULL] | K42: 1792 | L42: 1 | M42: 1792 | N42: ig41v1 | O42: IG | P42: NA | Q42: CDX | R42: 3-10 | S42: 0-5 | T42: EXOTIC PRODUCTS | U42: NORTH_AMERICA | V42: 0 | W42: .
...

Sheet Mapping
A1: index_family | B1: index_region | C1: index_sector | D1: index_subsector | E1: Index | F1: Year | G1: LH
A2: CDX | B2: NA | C2: HY | D2: B | E2: INDEX_SPREAD_CDX_HY_OTR | F2: 05Y | G2: 60
A3: ITRAXX-LEVX | B3: LN | C3: CI | D3: SUB | E3: INDEX_SPREAD_ITRX_XO_OTR | F3: 05Y | G3: 60
A4: TRACX-ASIA | B4: JP | C4: IG | D4: * | E4: INDEX_SPREAD_CDX_IG_OTR | F4: 05Y | G4: 40
A5: CDX | B5: NA | C5: HY | D5: BB | E5: INDEX_SPREAD_CDX_HY_OTR | F5: 05Y | G5: 60
A6: ITRAXX-ASIAN | B6: JP | C6: IG | D6: * | E6: INDEX_SPREAD_CDX_IG_OTR | F6: 05Y | G6: 40
A7: LCDX | B7: NA | C7: * | D7: * | E7: INDEX_SPREAD_CDX_HY_OTR | F7: 05Y | G7: 60
A8: ITRAXX-EUROPEAN | B8: EU | C8: IG | D8: NONFIN | E8: INDEX_SPREAD_ITRX_IG_OTR | F8: 05Y | G8: 40
A9: ITRAXX-EUROPEAN | B9: EU | C9: IG | D9: CONS_CYC | E9: INDEX_SPREAD_ITRX_IG_OTR | F9: 05Y | G9: 40
A10: ITRAXX-LEVX | B10: LN | C10: CI | D10: SEN | E10: INDEX_SPREAD_ITRX_XO_OTR | F10: 05Y | G10: 60
A11: ITRAXX-ASIAN | B11: KO | C11: IG | D11: * | E11: INDEX_SPREAD_ITRX_IG_OTR | F11: 05Y | G11: 40
A12: ITRAXX-LEVX | B12: LN | C12: LL | D12: SENIOR | E12: INDEX_SPREAD_ITRX_XO_OTR | F12: 05Y | G12: 60
A13: CDX | B13: NA | C13: XO | D13: * | E13: INDEX_SPREAD_CDX_HY_OTR | F13: 05Y | G13: 60
... A52: ITRAXX SOVX | B52: WE | C52: * | D52: * | E52: INDEX_SPREAD_ITRX_IG_OTR | F52: 05Y | G52: 40

Sheet TimeSeries
A1: timeSeriesld | B1: date | C1: Index Values
A2: INDEX_SPREAD_CDX_EM_OTR | B2: 45292 | C2: 166.85439
A3: INDEX_SPREAD_CDX_HY_OTR | B3: 45292 | C3: 357
A4: INDEX_SPREAD_CDX_IG_OTR | B4: 45292 | C4: 56.75
A5: INDEX_SPREAD_ITRX_XO_OTR | B5: 45292 | C5: 310.375
A6: INDEX_SPREAD_ITRX_IG_OTR | B6: 45292 | C6: 58.28
A7: INDEX_SPREAD_ITRX_IG_FINSB_OTR | B7: 45292 | C7: 122.65
A8: INDEX_SPREAD_ITRX_IG_FINSN_OTR | B8: 45292 | C8: 67.12
A9: INDEX_SPREAD_CDX_EM_OTR | B9: 45293 | C9: 175.86862
A10: INDEX_SPREAD_CDX_HY_OTR | B10: 45293 | C10: 364.5
A11: INDEX_SPREAD_CDX_IG_OTR | B11: 45293 | C11: 58.5
A12: INDEX_SPREAD_ITRX_XO_OTR | B12: 45293 | C12: 325.24
A13: INDEX_SPREAD_ITRX_IG_OTR | B13: 45293 | C13: 61
... A120: INDEX_SPREAD_ITRX_IG_FINSN_OTR | B120: 45314 | C120: 69.89

Sheet DataDictionary
A1: TestingPnL
A2: Field | B2: Description | C2: Sample value
A3: COB | B3: Close of business date | C3: 45306
A4: global_position_id | B4: Unique position identifier | C4: 2122287473
A5: bu risk_system | B5: Business unit risk system | C5: EQUITY_NY.ADEELQ
A6: book | B6: business unit trading book | C6: EXOTICS NAM adeelq
A7: ticket | B7: position ticket name | C7: [NULL]
A8: asset class | B8: position asset class | C8: ir
A9: measure name | B9: name of the risk measure | C9: asset_pv01spread
A10: measure usd | B10: value of the risk measure | C10: -146.5032
A11: mrd mark | B11: measure mark / 100 | C11: [NULL]
A12: measure mark | B12: position benchmark mark for relative return convertion | C12: [NULL]
A13: term of measure | B13: time to maturity in days | C13: 1792
A14: expiration date | B14: expiration date for the position | C14: 1
A15: ccvar term | B15: time to maturity in days | C15: 1792
A16: rf curve name | B16: name of the risk factor curve | C16: ig41v1
A17: index sector | B17: economic sector of the position | C17: IG
A18: index_region | B18: economic region of the position | C18: NA
A19: index_family | B19: index family of the position | C19: CDX
A20: ccvar tenor bucket 4 | B20: bucket for tenor | C20: 3-10
A21: ccvar tenor bucket 2 | B21: bucket for tenor | C21: 0-5
A22: ccc_product line | B22: this is the trading desk | C22: EXOTIC PRODUCTS
A23: baac_pl_rpt_region | B23: business reporting region | C23: NORTH AMERICA
A24: pnL | B24: PnL value on COB | C24: 0
A30: Mapping | B30: Sample Value
A31: index_family | B31: The CDS index family. The family should be CDX or iTraxx | C31: CDX
A32: index_region | B32: The CDS index region. North America, EMEA and asia pacific | C32: NA
A33: index_sector | B33: The CDS index sector, can be HY/IG for NA and XO and something else for iTraxx | C33: HY
A34: index_subsector | B34: The CDS index subsector. Not all index have subsector. Most granular level | C34: B
A35: Index | B35: This is the unique identifier of index, combination of all four fields above as applicable | C35: INDEX_SPREAD_CDX_HY_OTR
A36: Year | B36: The tenor of the index | C36: 05Y
A37: LH | B37: Liquidity horizon. Not relevant for VaR but for FRTB ES | C37: 60
A44: TimeSeries
A45: timeSeriesld | B45: The unique identifier of the index | C45: INDEX_SPREAD_CDX_EM_OTR
A46: date | B46: The COB date | C46: 45292
A47: Index Values | B47: The value of the index on the COB date | C47: 166.85439

Sheet Risk Report
A1: CDS Trading Desk — Daily Risk Report
A2: Prepared by: Desk Risk Manager
A3: Report Date: | B3: =TODAY() -> 46124
A4: Confidential | For Internal Use Only
A5: INPUTS
A6: CoB Jan 15 | B6: 45306
A7: CoB Jan 16 | B7: 45307
A9: TIME SERIES PIVOT (SUMIFS from TimeSeries tab)
A10: Date | B10: CDX_IG_OTR | C10: CDX_HY_OTR | D10: CDX_EM_OTR | E10: ITRX_IG_OTR | F10: ITRX_XO_OTR | G10: ITRX_FINSB_OTR | H10: ITRX_FINSN_OTR
A11: 45292 | B11: =IFERROR(SUMIFS(TimeSeries!$C:$C,TimeSeries!$A:$A,"INDEX_SPREAD_CDX_IG_OTR",TimeSeries!$B:$B,$A11),0) -> 56.75 | C11: =IFERROR(SUMIFS(TimeSeries!$C:$C,TimeSeries!$A:$A,"INDEX_SPREAD_CDX_HY_OTR",TimeSeries!$B:$B,$A11),0) -> 357 | D11: =IFERROR(SUMIFS(TimeSeries!$C:$C,TimeSeries!$A:$A,"INDEX_SPREAD_CDX_EM_OTR",TimeSeries!$B:$B,$A11),0) -> 166.85439 | E11: =IFERROR(SUMIFS(TimeSeries!$C:$C,TimeSeries!$A:$A,"INDEX_SPREAD_ITRX_IG_OTR",TimeSeries!$B:$B,$A11),0) -> 58.28 | F11: =IFERROR(SUMIFS(TimeSeries!$C:$C,TimeSeries!$A:$A,"INDEX_SPREAD_ITRX_XO_OTR",TimeSeries!$B:$B,$A11),0) -> 310.375 | G11: =IFERROR(SUMIFS(TimeSeries!$C:$C,TimeSeries!$A:$A,"INDEX_SPREAD_ITRX_IG_FINSB_OTR",TimeSeries!$B:$B,$A11),0) -> 122.65 | H11: =IFERROR(SUMIFS(TimeSeries!$C:$C,TimeSeries!$A:$A,"INDEX_SPREAD_ITRX_IG_FINSN_OTR",TimeSeries!$B:$B,$A11),0) -> 67.12
A12: 45293 | B12: =IFERROR(SUMIFS(TimeSeries!$C:$C,TimeSeries!$A:$A,"INDEX_SPREAD_CDX_IG_OTR",TimeSeries!$B:$B,$A12),0) -> 58.5 | C12: =IFERROR(SUMIFS(TimeSeries!$C:$C,TimeSeries!$A:$A,"INDEX_SPREAD_CDX_HY_OTR",TimeSeries!$B:$B,$A12),0) -> 364.5 | D12: =IFERROR(SUMIFS(TimeSeries!$C:$C,TimeSeries!$A:$A,"INDEX_SPREAD_CDX_EM_OTR",TimeSeries!$B:$B,$A12),0) -> 175.86862 | E12: =IFERROR(SUMIFS(TimeSeries!$C:$C,TimeSeries!$A:$A,"INDEX_SPREAD_ITRX_IG_OTR",TimeSeries!$B:$B,$A12),0) -> 61 | F12: =IFERROR(SUMIFS(TimeSeries!$C:$C,TimeSeries!$A:$A,"INDEX_SPREAD_ITRX_XO_OTR",TimeSeries!$B:$B,$A12),0) -> 325.24 | G12: =IFERROR(SUMIFS(TimeSeries!$C:$C,TimeSeries!$A:$A,"INDEX_SPREAD_ITRX_IG_FINSB_OTR",TimeSeries!$B:$B,$A12),0) -> 130.72 | H12: =IFERROR(SUMIFS(TimeSeries!$C:$C,TimeSeries!$A:$A,"INDEX_SPREAD_ITRX_IG_FINSN_OTR",TimeSeries!$B:$B,$A12),0) -> 71.11
A13: 45294 | B13: =IFERROR(SUMIFS(TimeSeries!$C:$C,TimeSeries!$A:$A,"INDEX_SPREAD_CDX_IG_OTR",TimeSeries!$B:$B,$A13),0) -> 60.5 | C13: =IFERROR(SUMIFS(TimeSeries!$C:$C,TimeSeries!$A:$A,"INDEX_SPREAD_CDX_HY_OTR",TimeSeries!$B:$B,$A13),0) -> 375 | D13: =IFERROR(SUMIFS(TimeSeries!$C:$C,TimeSeries!$A:$A,"INDEX_SPREAD_CDX_EM_OTR",TimeSeries!$B:$B,$A13),0) -> 181.49359 | E13: =IFERROR(SUMIFS(TimeSeries!$C:$C,TimeSeries!$A:$A,"INDEX_SPREAD_ITRX_IG_OTR",TimeSeries!$B:$B,$A13),0) -> 64.3 | F13: =IFERROR(SUMIFS(TimeSeries!$C:$C,TimeSeries!$A:$A,"INDEX_SPREAD_ITRX_XO_OTR",TimeSeries!$B:$B,$A13),0) -> 343.09 | G13: =IFERROR(SUMIFS(TimeSeries!$C:$C,TimeSeries!$A:$A,"INDEX_SPREAD_ITRX_IG_FINSB_OTR",TimeSeries!$B:$B,$A13),0) -> 136.75 | H13: =IFERROR(SUMIFS(TimeSeries!$C:$C,TimeSeries!$A:$A,"INDEX_SPREAD_ITRX_IG_FINSN_OTR",TimeSeries!$B:$B,$A13),0) -> 74.42
A14: 45295 | B14: =IFERROR(SUMIFS(TimeSeries!$C:$C,TimeSeries!$A:$A,"INDEX_SPREAD_CDX_IG_OTR",TimeSeries!$B:$B,$A14),0) -> 60 | C14: =IFERROR(SUMIFS(TimeSeries!$C:$C,TimeSeries!$A:$A,"INDEX_SPREAD_CDX_HY_OTR",TimeSeries!$B:$B,$A14),0) -> 376 | D14: =IFERROR(SUMIFS(TimeSeries!$C:$C,TimeSeries!$A:$A,"INDEX_SPREAD_CDX_EM_OTR",TimeSeries!$B:$B,$A14),0) -> 184.6419 | E14: =IFERROR(SUMIFS(TimeSeries!$C:$C,TimeSeries!$A:$A,"INDEX_SPREAD_ITRX_IG_OTR",TimeSeries!$B:$B,$A14),0) -> 63.57 | F14: =IFERROR(SUMIFS(TimeSeries!$C:$C,TimeSeries!$A:$A,"INDEX_SPREAD_ITRX_XO_OTR",TimeSeries!$B:$B,$A14),0) -> 339.87 | G14: =IFERROR(SUMIFS(TimeSeries!$C:$C,TimeSeries!$A:$A,"INDEX_SPREAD_ITRX_IG_FINSB_OTR",TimeSeries!$B:$B,$A14),0) -> 134.34 | H14: =IFERROR(SUMIFS(TimeSeries!$C:$C,TimeSeries!$A:$A,"INDEX_SPREAD_ITRX_IG_FINSN_OTR",TimeSeries!$B:$B,$A14),0) -> 73.18
A15: 45296 | B15: =IFERROR(SUMIFS(TimeSeries!$C:$C,TimeSeries!$A:$A,"INDEX_SPREAD_CDX_IG_OTR",TimeSeries!$B:$B,$A15),0) -> 59.35 | C15: =IFERROR(SUMIFS(TimeSeries!$C:$C,TimeSeries!$A:$A,"INDEX_SPREAD_CDX_HY_OTR",TimeSeries!$B:$B,$A15),0) -> 371 | D15: =IFERROR(SUMIFS(TimeSeries!$C:$C,TimeSeries!$A:$A,"INDEX_SPREAD_CDX_EM_OTR",TimeSeries!$B:$B,$A15),0) -> 181.49182 | E15: =IFERROR(SUMIFS(TimeSeries!$C:$C,TimeSeries!$A:$A,"INDEX_SPREAD_ITRX_IG_OTR",TimeSeries!$B:$B,$A15),0) -> 63.7 | F15: =IFERROR(SUMIFS(TimeSeries!$C:$C,TimeSeries!$A:$A,"INDEX_SPREAD_ITRX_XO_OTR",TimeSeries!$B:$B,$A15),0) -> 338.98 | G15: =IFERROR(SUMIFS(TimeSeries!$C:$C,TimeSeries!$A:$A,"INDEX_SPREAD_ITRX_IG_FINSB_OTR",TimeSeries!$B:$B,$A15),0) -> 134.11 | H15: =IFERROR(SUMIFS(TimeSeries!$C:$C,TimeSeries!$A:$A,"INDEX_SPREAD_ITRX_IG_FINSN_OTR",TimeSeries!$B:$B,$A15),0) -> 73.2
A16: 45299 | B16: =IFERROR(SUMIFS(TimeSeries!$C:$C,TimeSeries!$A:$A,"INDEX_SPREAD_CDX_IG_OTR",TimeSeries!$B:$B,$A16),0) -> 56.9 | C16: =IFERROR(SUMIFS(TimeSeries!$C:$C,TimeSeries!$A:$A,"INDEX_SPREAD_CDX_HY_OTR",TimeSeries!$B:$B,$A16),0) -> 359 | D16: =IFERROR(SUMIFS(TimeSeries!$C:$C,TimeSeries!$A:$A,"INDEX_SPREAD_CDX_EM_OTR",TimeSeries!$B:$B,$A16),0) -> 180.72035 | E16: =IFERROR(SUMIFS(TimeSeries!$C:$C,TimeSeries!$A:$A,"INDEX_SPREAD_ITRX_IG_OTR",TimeSeries!$B:$B,$A16),0) -> 62.59 | F16: =IFERROR(SUMIFS(TimeSeries!$C:$C,TimeSeries!$A:$A,"INDEX_SPREAD_ITRX_XO_OTR",TimeSeries!$B:$B,$A16),0) -> 333.89 | G16: =IFERROR(SUMIFS(TimeSeries!$C:$C,TimeSeries!$A:$A,"INDEX_SPREAD_ITRX_IG_FINSB_OTR",TimeSeries!$B:$B,$A16),0) -> 132.01 | H16: =IFERROR(SUMIFS(TimeSeries!$C:$C,TimeSeries!$A:$A,"INDEX_SPREAD_ITRX_IG_FINSN_OTR",TimeSeries!$B:$B,$A16),0) -> 71.95
A17: 45300 | B17: =IFERROR(SUMIFS(TimeSeries!$C:$C,TimeSeries!$A:$A,"INDEX_SPREAD_CDX_IG_OTR",TimeSeries!$B:$B,$A17),0) -> 56.45 | C17: =IFERROR(SUMIFS(TimeSeries!$C:$C,TimeSeries!$A:$A,"INDEX_SPREAD_CDX_HY_OTR",TimeSeries!$B:$B,$A17),0) -> 359 | D17: =IFERROR(SUMIFS(TimeSeries!$C:$C,TimeSeries!$A:$A,"INDEX_SPREAD_CDX_EM_OTR",TimeSeries!$B:$B,$A17),0) -> 180.7311 | E17: =IFERROR(SUMIFS(TimeSeries!$C:$C,TimeSeries!$A:$A,"INDEX_SPREAD_ITRX_IG_OTR",TimeSeries!$B:$B,$A17),0) -> 61.5 | F17: =IFERROR(SUMIFS(TimeSeries!$C:$C,TimeSeries!$A:$A,"INDEX_SPREAD_ITRX_XO_OTR",TimeSeries!$B:$B,$A17),0) -> 329.86 | G17: =IFERROR(SUMIFS(TimeSeries!$C:$C,TimeSeries!$A:$A,"INDEX_SPREAD_ITRX_IG_FINSB_OTR",TimeSeries!$B:$B,$A17),0) -> 130.86 | H17: =IFERROR(SUMIFS(TimeSeries!$C:$C,TimeSeries!$A:$A,"INDEX_SPREAD_ITRX_IG_FINSN_OTR",TimeSeries!$B:$B,$A17),0) -> 71.1
A18: 45301 | B18: =IFERROR(SUMIFS(TimeSeries!$C:$C,TimeSeries!$A:$A,"INDEX_SPREAD_CDX_IG_OTR",TimeSeries!$B:$B,$A18),0) -> 55.3 | C18: =IFERROR(SUMIFS(TimeSeries!$C:$C,TimeSeries!$A:$A,"INDEX_SPREAD_CDX_HY_OTR",TimeSeries!$B:$B,$A18),0) -> 353.5 | D18: =IFERROR(SUMIFS(TimeSeries!$C:$C,TimeSeries!$A:$A,"INDEX_SPREAD_CDX_EM_OTR",TimeSeries!$B:$B,$A18),0) -> 175.95631 | E18: =IFERROR(SUMIFS(TimeSeries!$C:$C,TimeSeries!$A:$A,"INDEX_SPREAD_ITRX_IG_OTR",TimeSeries!$B:$B,$A18),0) -> 59.54 | F18: =IFERROR(SUMIFS(TimeSeries!$C:$C,TimeSeries!$A:$A,"INDEX_SPREAD_ITRX_XO_OTR",TimeSeries!$B:$B,$A18),0) -> 319.05 | G18: =IFERROR(SUMIFS(TimeSeries!$C:$C,TimeSeries!$A:$A,"INDEX_SPREAD_ITRX_IG_FINSB_OTR",TimeSeries!$B:$B,$A18),0) -> 125.04 | H18: =IFERROR(SUMIFS(TimeSeries!$C:$C,TimeSeries!$A:$A,"INDEX_SPREAD_ITRX_IG_FINSN_OTR",TimeSeries!$B:$B,$A18),0) -> 68.61
A19: 45302 | B19: =IFERROR(SUMIFS(TimeSeries!$C:$C,TimeSeries!$A:$A,"INDEX_SPREAD_CDX_IG_OTR",TimeSeries!$B:$B,$A19),0) -> 54.5 | C19: =IFERROR(SUMIFS(TimeSeries!$C:$C,TimeSeries!$A:$A,"INDEX_SPREAD_CDX_HY_OTR",TimeSeries!$B:$B,$A19),0) -> 350.5 | D19: =IFERROR(SUMIFS(TimeSeries!$C:$C,TimeSeries!$A:$A,"INDEX_SPREAD_CDX_EM_OTR",TimeSeries!$B:$B,$A19),0) -> 174.33105 | E19: =IFERROR(SUMIFS(TimeSeries!$C:$C,TimeSeries!$A:$A,"INDEX_SPREAD_ITRX_IG_OTR",TimeSeries!$B:$B,$A19),0) -> 60.44 | F19: =IFERROR(SUMIFS(TimeSeries!$C:$C,TimeSeries!$A:$A,"INDEX_SPREAD_ITRX_XO_OTR",TimeSeries!$B:$B,$A19),0) -> 325.06 | G19: =IFERROR(SUMIFS(TimeSeries!$C:$C,TimeSeries!$A:$A,"INDEX_SPREAD_ITRX_IG_FINSB_OTR",TimeSeries!$B:$B,$A19),0) -> 128.48 | H19: =IFERROR(SUMIFS(TimeSeries!$C:$C,TimeSeries!$A:$A,"INDEX_SPREAD_ITRX_IG_FINSN_OTR",TimeSeries!$B:$B,$A19),0) -> 70.13
A20: 45303 | B20: =IFERROR(SUMIFS(TimeSeries!$C:$C,TimeSeries!$A:$A,"INDEX_SPREAD_CDX_IG_OTR",TimeSeries!$B:$B,$A20),0) -> 54.75 | C20: =IFERROR(SUMIFS(TimeSeries!$C:$C,TimeSeries!$A:$A,"INDEX_SPREAD_CDX_HY_OTR",TimeSeries!$B:$B,$A20),0) -> 353 | D20: =IFERROR(SUMIFS(TimeSeries!$C:$C,TimeSeries!$A:$A,"INDEX_SPREAD_CDX_EM_OTR",TimeSeries!$B:$B,$A20),0) -> 173.9481 | E20: =IFERROR(SUMIFS(TimeSeries!$C:$C,TimeSeries!$A:$A,"INDEX_SPREAD_ITRX_IG_OTR",TimeSeries!$B:$B,$A20),0) -> 60.04 | F20: =IFERROR(SUMIFS(TimeSeries!$C:$C,TimeSeries!$A:$A,"INDEX_SPREAD_ITRX_XO_OTR",TimeSeries!$B:$B,$A20),0) -> 321.49 | G20: =IFERROR(SUMIFS(TimeSeries!$C:$C,TimeSeries!$A:$A,"INDEX_SPREAD_ITRX_IG_FINSB_OTR",TimeSeries!$B:$B,$A20),0) -> 129.37 | H20: =IFERROR(SUMIFS(TimeSeries!$C:$C,TimeSeries!$A:$A,"INDEX_SPREAD_ITRX_IG_FINSN_OTR",TimeSeries!$B:$B,$A20),0) -> 70.28
A21: 45306 | B21: =IFERROR(SUMIFS(TimeSeries!$C:$C,TimeSeries!$A:$A,"INDEX_SPREAD_CDX_IG_OTR",TimeSeries!$B:$B,$A21),0) -> 54.75 | C21: =IFERROR(SUMIFS(TimeSeries!$C:$C,TimeSeries!$A:$A,"INDEX_SPREAD_CDX_HY_OTR",TimeSeries!$B:$B,$A21),0) -> 353 | D21: =IFERROR(SUMIFS(TimeSeries!$C:$C,TimeSeries!$A:$A,"INDEX_SPREAD_CDX_EM_OTR",TimeSeries!$B:$B,$A21),0) -> 173.94553 | E21: =IFERROR(SUMIFS(TimeSeries!$C:$C,TimeSeries!$A:$A,"INDEX_SPREAD_ITRX_IG_OTR",TimeSeries!$B:$B,$A21),0) -> 60.88 | F21: =IFERROR(SUMIFS(TimeSeries!$C:$C,TimeSeries!$A:$A,"INDEX_SPREAD_ITRX_XO_OTR",TimeSeries!$B:$B,$A21),0) -> 329.53 | G21: =IFERROR(SUMIFS(TimeSeries!$C:$C,TimeSeries!$A:$A,"INDEX_SPREAD_ITRX_IG_FINSB_OTR",TimeSeries!$B:$B,$A21),0) -> 131.9 | H21: =IFERROR(SUMIFS(TimeSeries!$C:$C,TimeSeries!$A:$A,"INDEX_SPREAD_ITRX_IG_FINSN_OTR",TimeSeries!$B:$B,$A21),0) -> 71.27
A22: 45307 | B22: =IFERROR(SUMIFS(TimeSeries!$C:$C,TimeSeries!$A:$A,"INDEX_SPREAD_CDX_IG_OTR",TimeSeries!$B:$B,$A22),0) -> 55.9 | C22: =IFERROR(SUMIFS(TimeSeries!$C:$C,TimeSeries!$A:$A,"INDEX_SPREAD_CDX_HY_OTR",TimeSeries!$B:$B,$A22),0) -> 360 | D22: =IFERROR(SUMIFS(TimeSeries!$C:$C,TimeSeries!$A:$A,"INDEX_SPREAD_CDX_EM_OTR",TimeSeries!$B:$B,$A22),0) -> 178.75261 | E22: =IFERROR(SUMIFS(TimeSeries!$C:$C,TimeSeries!$A:$A,"INDEX_SPREAD_ITRX_IG_OTR",TimeSeries!$B:$B,$A22),0) -> 60.8 | F22: =IFERROR(SUMIFS(TimeSeries!$C:$C,TimeSeries!$A:$A,"INDEX_SPREAD_ITRX_XO_OTR",TimeSeries!$B:$B,$A22),0) -> 331.18 | G22: =IFERROR(SUMIFS(TimeSeries!$C:$C,TimeSeries!$A:$A,"INDEX_SPREAD_ITRX_IG_FINSB_OTR",TimeSeries!$B:$B,$A22),0) -> 131.6 | H22: =IFERROR(SUMIFS(TimeSeries!$C:$C,TimeSeries!$A:$A,"INDEX_SPREAD_ITRX_IG_FINSN_OTR",TimeSeries!$B:$B,$A22),0) -> 70.98
... A27: 45314 | B27: =IFERROR(SUMIFS(TimeSeries!$C:$C,TimeSeries!$A:$A,"INDEX_SPREAD_CDX_IG_OTR",TimeSeries!$B:$B,$A27),0) -> 55.5 | C27: =IFERROR(SUMIFS(TimeSeries!$C:$C,TimeSeries!$A:$A,"INDEX_SPREAD_CDX_HY_OTR",TimeSeries!$B:$B,$A27),0) -> 356 | D27: =IFERROR(SUMIFS(TimeSeries!$C:$C,TimeSeries!$A:$A,"INDEX_SPREAD_CDX_EM_OTR",TimeSeries!$B:$B,$A27),0) -> 181.12445 | E27: =IFERROR(SUMIFS(TimeSeries!$C:$C,TimeSeries!$A:$A,"INDEX_SPREAD_ITRX_IG_OTR",TimeSeries!$B:$B,$A27),0) -> 60.44 | F27: =IFERROR(SUMIFS(TimeSeries!$C:$C,TimeSeries!$A:$A,"INDEX_SPREAD_ITRX_XO_OTR",TimeSeries!$B:$B,$A27),0) -> 329.65 | G27: =IFERROR(SUMIFS(TimeSeries!$C:$C,TimeSeries!$A:$A,"INDEX_SPREAD_ITRX_IG_FINSB_OTR",TimeSeries!$B:$B,$A27),0) -> 129.64 | H27: =IFERROR(SUMIFS(TimeSeries!$C:$C,TimeSeries!$A:$A,"INDEX_SPREAD_ITRX_IG_FINSN_OTR",TimeSeries!$B:$B,$A27),0) -> 69.89
A29: SHOCKS (bps, day-over-day change in index spread)
A30: Scenario Date | B30: Shock_CDX_IG | C30: Shock_CDX_HY | D30: Shock_CDX_EM | E30: Shock_ITRX_IG | F30: Shock_ITRX_XO | G30: Shock_ITRX_FINSB | H30: Shock_ITRX_FINSN | I30: Portfolio_PnL_Jan15 | J30: Portfolio_PnL_Jan16
A31: =$A12 -> 45293 | B31: =B12-B11 -> 1.75 | C31: =C12-C11 -> 7.5 | D31: =D12-D11 -> 9.01423 | E31: =E12-E11 -> 2.72 | F31: =F12-F11 -> 14.865 | G31: =G12-G11 -> 8.07 | H31: =H12-H11 -> 3.99 | I31: =SUMIFS(TestingPnL!$H:$H,TestingPnL!$A:$A,$B$6,TestingPnL!$P:$P,"NA",TestingPnL!$O:$O,"IG")*B31+SUMIFS(TestingPnL!$H:$H,TestingPnL!$A:$A,$B$6,TestingPnL!$P:$P,"NA",TestingPnL!$O:$O,"HY")*C31+SUMIFS(TestingPnL!$H:$H,TestingPnL!$A:$A,$B$6,TestingPnL!$P:$P,"NA",TestingPnL!$O:$O,"CO")*C31+SUMIFS(TestingPnL!$H:$H,TestingPnL!$A:$A,$B$6,TestingPnL!$P:$P,"EU",TestingPnL!$O:$O,"IG")*E31+SUMIFS(TestingPnL!$H:$H,TestingPnL!$A:$A,$B$6,TestingPnL!$P:$P,"EU",TestingPnL!$O:$O,"CO")*F31 -> -3785.5511 | J31: =SUMIFS(TestingPnL!$H:$H,TestingPnL!$A:$A,$B$7,TestingPnL!$P:$P,"NA",TestingPnL!$O:$O,"IG")*B31+SUMIFS(TestingPnL!$H:$H,TestingPnL!$A:$A,$B$7,TestingPnL!$P:$P,"NA",TestingPnL!$O:$O,"HY")*C31+SUMIFS(TestingPnL!$H:$H,TestingPnL!$A:$A,$B$7,TestingPnL!$P:$P,"NA",TestingPnL!$O:$O,"CO")*C31+SUMIFS(TestingPnL!$H:$H,TestingPnL!$A:$A,$B$7,TestingPnL!$P:$P,"EU",TestingPnL!$O:$O,"IG")*E31+SUMIFS(TestingPnL!$H:$H,TestingPnL!$A:$A,$B$7,TestingPnL!$P:$P,"EU",TestingPnL!$O:$O,"CO")*F31 -> -1521.6653
A32: =$A13 -> 45294 | B32: =B13-B12 -> 2 | C32: =C13-C12 -> 10.5 | D32: =D13-D12 -> 5.62497 | E32: =E13-E12 -> 3.3 | F32: =F13-F12 -> 17.85 | G32: =G13-G12 -> 6.03 | H32: =H13-H12 -> 3.31 | I32: =SUMIFS(TestingPnL!$H:$H,TestingPnL!$A:$A,$B$6,TestingPnL!$P:$P,"NA",TestingPnL!$O:$O,"IG")*B32+SUMIFS(TestingPnL!$H:$H,TestingPnL!$A:$A,$B$6,TestingPnL!$P:$P,"NA",TestingPnL!$O:$O,"HY")*C32+SUMIFS(TestingPnL!$H:$H,TestingPnL!$A:$A,$B$6,TestingPnL!$P:$P,"NA",TestingPnL!$O:$O,"CO")*C32+SUMIFS(TestingPnL!$H:$H,TestingPnL!$A:$A,$B$6,TestingPnL!$P:$P,"EU",TestingPnL!$O:$O,"IG")*E32+SUMIFS(TestingPnL!$H:$H,TestingPnL!$A:$A,$B$6,TestingPnL!$P:$P,"EU",TestingPnL!$O:$O,"CO")*F32 -> -4710.2952 | J32: =SUMIFS(TestingPnL!$H:$H,TestingPnL!$A:$A,$B$7,TestingPnL!$P:$P,"NA",TestingPnL!$O:$O,"IG")*B32+SUMIFS(TestingPnL!$H:$H,TestingPnL!$A:$A,$B$7,TestingPnL!$P:$P,"NA",TestingPnL!$O:$O,"HY")*C32+SUMIFS(TestingPnL!$H:$H,TestingPnL!$A:$A,$B$7,TestingPnL!$P:$P,"NA",TestingPnL!$O:$O,"CO")*C32+SUMIFS(TestingPnL!$H:$H,TestingPnL!$A:$A,$B$7,TestingPnL!$P:$P,"EU",TestingPnL!$O:$O,"IG")*E32+SUMIFS(TestingPnL!$H:$H,TestingPnL!$A:$A,$B$7,TestingPnL!$P:$P,"EU",TestingPnL!$O:$O,"CO")*F32 -> -1848.8801
A33: =$A14 -> 45295 | B33: =B14-B13 -> -0.5 | C33: =C14-C13 -> 1 | D33: =D14-D13 -> 3.14831 | E33: =E14-E13 -> -0.73 | F33: =F14-F13 -> -3.22 | G33: =G14-G13 -> -2.41 | H33: =H14-H13 -> -1.24 | I33: =SUMIFS(TestingPnL!$H:$H,TestingPnL!$A:$A,$B$6,TestingPnL!$P:$P,"NA",TestingPnL!$O:$O,"IG")*B33+SUMIFS(TestingPnL!$H:$H,TestingPnL!$A:$A,$B$6,TestingPnL!$P:$P,"NA",TestingPnL!$O:$O,"HY")*C33+SUMIFS(TestingPnL!$H:$H,TestingPnL!$A:$A,$B$6,TestingPnL!$P:$P,"NA",TestingPnL!$O:$O,"CO")*C33+SUMIFS(TestingPnL!$H:$H,TestingPnL!$A:$A,$B$6,TestingPnL!$P:$P,"EU",TestingPnL!$O:$O,"IG")*E33+SUMIFS(TestingPnL!$H:$H,TestingPnL!$A:$A,$B$6,TestingPnL!$P:$P,"EU",TestingPnL!$O:$O,"CO")*F33 -> 519.48946 | J33: =SUMIFS(TestingPnL!$H:$H,TestingPnL!$A:$A,$B$7,TestingPnL!$P:$P,"NA",TestingPnL!$O:$O,"IG")*B33+SUMIFS(TestingPnL!$H:$H,TestingPnL!$A:$A,$B$7,TestingPnL!$P:$P,"NA",TestingPnL!$O:$O,"HY")*C33+SUMIFS(TestingPnL!$H:$H,TestingPnL!$A:$A,$B$7,TestingPnL!$P:$P,"NA",TestingPnL!$O:$O,"CO")*C33+SUMIFS(TestingPnL!$H:$H,TestingPnL!$A:$A,$B$7,TestingPnL!$P:$P,"EU",TestingPnL!$O:$O,"IG")*E33+SUMIFS(TestingPnL!$H:$H,TestingPnL!$A:$A,$B$7,TestingPnL!$P:$P,"EU",TestingPnL!$O:$O,"CO")*F33 -> 290.81813
A34: =$A15 -> 45296 | B34: =B15-B14 -> -0.65 | C34: =C15-C14 -> -5 | D34: =D15-D14 -> -3.15008 | E34: =E15-E14 -> 0.13 | F34: =F15-F14 -> -0.89 | G34: =G15-G14 -> -0.23 | H34: =H15-H14 -> 0.02 | I34: =SUMIFS(TestingPnL!$H:$H,TestingPnL!$A:$A,$B$6,TestingPnL!$P:$P,"NA",TestingPnL!$O:$O,"IG")*B34+SUMIFS(TestingPnL!$H:$H,TestingPnL!$A:$A,$B$6,TestingPnL!$P:$P,"NA",TestingPnL!$O:$O,"HY")*C34+SUMIFS(TestingPnL!$H:$H,TestingPnL!$A:$A,$B$6,TestingPnL!$P:$P,"NA",TestingPnL!$O:$O,"CO")*C34+SUMIFS(TestingPnL!$H:$H,TestingPnL!$A:$A,$B$6,TestingPnL!$P:$P,"EU",TestingPnL!$O:$O,"IG")*E34+SUMIFS(TestingPnL!$H:$H,TestingPnL!$A:$A,$B$6,TestingPnL!$P:$P,"EU",TestingPnL!$O:$O,"CO")*F34 -> 1225.7504 | J34: =SUMIFS(TestingPnL!$H:$H,TestingPnL!$A:$A,$B$7,TestingPnL!$P:$P,"NA",TestingPnL!$O:$O,"IG")*B34+SUMIFS(TestingPnL!$H:$H,TestingPnL!$A:$A,$B$7,TestingPnL!$P:$P,"NA",TestingPnL!$O:$O,"HY")*C34+SUMIFS(TestingPnL!$H:$H,TestingPnL!$A:$A,$B$7,TestingPnL!$P:$P,"NA",TestingPnL!$O:$O,"CO")*C34+SUMIFS(TestingPnL!$H:$H,TestingPnL!$A:$A,$B$7,TestingPnL!$P:$P,"EU",TestingPnL!$O:$O,"IG")*E34+SUMIFS(TestingPnL!$H:$H,TestingPnL!$A:$A,$B$7,TestingPnL!$P:$P,"EU",TestingPnL!$O:$O,"CO")*F34 -> 332.86
A35: =$A16 -> 45299 | B35: =B16-B15 -> -2.45 | C35: =C16-C15 -> -12 | D35: =D16-D15 -> -0.77147 | E35: =E16-E15 -> -1.11 | F35: =F16-F15 -> -5.09 | G35: =G16-G15 -> -2.1 | H35: =H16-H15 -> -1.25 | I35: =SUMIFS(TestingPnL!$H:$H,TestingPnL!$A:$A,$B$6,TestingPnL!$P:$P,"NA",TestingPnL!$O:$O,"IG")*B35+SUMIFS(TestingPnL!$H:$H,TestingPnL!$A:$A,$B$6,TestingPnL!$P:$P,"NA",TestingPnL!$O:$O,"HY")*C35+SUMIFS(TestingPnL!$H:$H,TestingPnL!$A:$A,$B$6,TestingPnL!$P:$P,"NA",TestingPnL!$O:$O,"CO")*C35+SUMIFS(TestingPnL!$H:$H,TestingPnL!$A:$A,$B$6,TestingPnL!$P:$P,"EU",TestingPnL!$O:$O,"IG")*E35+SUMIFS(TestingPnL!$H:$H,TestingPnL!$A:$A,$B$6,TestingPnL!$P:$P,"EU",TestingPnL!$O:$O,"CO")*F35 -> 3928.5709 | J35: =SUMIFS(TestingPnL!$H:$H,TestingPnL!$A:$A,$B$7,TestingPnL!$P:$P,"NA",TestingPnL!$O:$O,"IG")*B35+SUMIFS(TestingPnL!$H:$H,TestingPnL!$A:$A,$B$7,TestingPnL!$P:$P,"NA",TestingPnL!$O:$O,"HY")*C35+SUMIFS(TestingPnL!$H:$H,TestingPnL!$A:$A,$B$7,TestingPnL!$P:$P,"NA",TestingPnL!$O:$O,"CO")*C35+SUMIFS(TestingPnL!$H:$H,TestingPnL!$A:$A,$B$7,TestingPnL!$P:$P,"EU",TestingPnL!$O:$O,"IG")*E35+SUMIFS(TestingPnL!$H:$H,TestingPnL!$A:$A,$B$7,TestingPnL!$P:$P,"EU",TestingPnL!$O:$O,"CO")*F35 -> 1241.4928
A36: =$A17 -> 45300 | B36: =B17-B16 -> -0.45 | C36: =C17-C16 -> 0 | D36: =D17-D16 -> 0.01075 | E36: =E17-E16 -> -1.09 | F36: =F17-F16 -> -4.03 | G36: =G17-G16 -> -1.15 | H36: =H17-H16 -> -0.85 | I36: =SUMIFS(TestingPnL!$H:$H,TestingPnL!$A:$A,$B$6,TestingPnL!$P:$P,"NA",TestingPnL!$O:$O,"IG")*B36+SUMIFS(TestingPnL!$H:$H,TestingPnL!$A:$A,$B$6,TestingPnL!$P:$P,"NA",TestingPnL!$O:$O,"HY")*C36+SUMIFS(TestingPnL!$H:$H,TestingPnL!$A:$A,$B$6,TestingPnL!$P:$P,"NA",TestingPnL!$O:$O,"CO")*C36+SUMIFS(TestingPnL!$H:$H,TestingPnL!$A:$A,$B$6,TestingPnL!$P:$P,"EU",TestingPnL!$O:$O,"IG")*E36+SUMIFS(TestingPnL!$H:$H,TestingPnL!$A:$A,$B$6,TestingPnL!$P:$P,"EU",TestingPnL!$O:$O,"CO")*F36 -> 748.52716 | J36: =SUMIFS(TestingPnL!$H:$H,TestingPnL!$A:$A,$B$7,TestingPnL!$P:$P,"NA",TestingPnL!$O:$O,"IG")*B36+SUMIFS(TestingPnL!$H:$H,TestingPnL!$A:$A,$B$7,TestingPnL!$P:$P,"NA",TestingPnL!$O:$O,"HY")*C36+SUMIFS(TestingPnL!$H:$H,TestingPnL!$A:$A,$B$7,TestingPnL!$P:$P,"NA",TestingPnL!$O:$O,"CO")*C36+SUMIFS(TestingPnL!$H:$H,TestingPnL!$A:$A,$B$7,TestingPnL!$P:$P,"EU",TestingPnL!$O:$O,"IG")*E36+SUMIFS(TestingPnL!$H:$H,TestingPnL!$A:$A,$B$7,TestingPnL!$P:$P,"EU",TestingPnL!$O:$O,"CO")*F36 -> 370.1492
A37: =$A18 -> 45301 | B37: =B18-B17 -> -1.15 | C37: =C18-C17 -> -5.5 | D37: =D18-D17 -> -4.77479 | E37: =E18-E17 -> -1.96 | F37: =F18-F17 -> -10.81 | G37: =G18-G17 -> -5.82 | H37: =H18-H17 -> -2.49 | I37: =SUMIFS(TestingPnL!$H:$H,TestingPnL!$A:$A,$B$6,TestingPnL!$P:$P,"NA",TestingPnL!$O:$O,"IG")*B37+SUMIFS(TestingPnL!$H:$H,TestingPnL!$A:$A,$B$6,TestingPnL!$P:$P,"NA",TestingPnL!$O:$O,"HY")*C37+SUMIFS(TestingPnL!$H:$H,TestingPnL!$A:$A,$B$6,TestingPnL!$P:$P,"NA",TestingPnL!$O:$O,"CO")*C37+SUMIFS(TestingPnL!$H:$H,TestingPnL!$A:$A,$B$6,TestingPnL!$P:$P,"EU",TestingPnL!$O:$O,"IG")*E37+SUMIFS(TestingPnL!$H:$H,TestingPnL!$A:$A,$B$6,TestingPnL!$P:$P,"EU",TestingPnL!$O:$O,"CO")*F37 -> 2678.8966 | J37: =SUMIFS(TestingPnL!$H:$H,TestingPnL!$A:$A,$B$7,TestingPnL!$P:$P,"NA",TestingPnL!$O:$O,"IG")*B37+SUMIFS(TestingPnL!$H:$H,TestingPnL!$A:$A,$B$7,TestingPnL!$P:$P,"NA",TestingPnL!$O:$O,"HY")*C37+SUMIFS(TestingPnL!$H:$H,TestingPnL!$A:$A,$B$7,TestingPnL!$P:$P,"NA",TestingPnL!$O:$O,"CO")*C37+SUMIFS(TestingPnL!$H:$H,TestingPnL!$A:$A,$B$7,TestingPnL!$P:$P,"EU",TestingPnL!$O:$O,"IG")*E37+SUMIFS(TestingPnL!$H:$H,TestingPnL!$A:$A,$B$7,TestingPnL!$P:$P,"EU",TestingPnL!$O:$O,"CO")*F37 -> 1077.9184
A38: =$A19 -> 45302 | B38: =B19-B18 -> -0.8 | C38: =C19-C18 -> -3 | D38: =D19-D18 -> -1.62526 | E38: =E19-E18 -> 0.9 | F38: =F19-F18 -> 6.01 | G38: =G19-G18 -> 3.44 | H38: =H19-H18 -> 1.52 | I38: =SUMIFS(TestingPnL!$H:$H,TestingPnL!$A:$A,$B$6,TestingPnL!$P:$P,"NA",TestingPnL!$O:$O,"IG")*B38+SUMIFS(TestingPnL!$H:$H,TestingPnL!$A:$A,$B$6,TestingPnL!$P:$P,"NA",TestingPnL!$O:$O,"HY")*C38+SUMIFS(TestingPnL!$H:$H,TestingPnL!$A:$A,$B$6,TestingPnL!$P:$P,"NA",TestingPnL!$O:$O,"CO")*C38+SUMIFS(TestingPnL!$H:$H,TestingPnL!$A:$A,$B$6,TestingPnL!$P:$P,"EU",TestingPnL!$O:$O,"IG")*E38+SUMIFS(TestingPnL!$H:$H,TestingPnL!$A:$A,$B$6,TestingPnL!$P:$P,"EU",TestingPnL!$O:$O,"CO")*F38 -> 371.55283 | J38: =SUMIFS(TestingPnL!$H:$H,TestingPnL!$A:$A,$B$7,TestingPnL!$P:$P,"NA",TestingPnL!$O:$O,"IG")*B38+SUMIFS(TestingPnL!$H:$H,TestingPnL!$A:$A,$B$7,TestingPnL!$P:$P,"NA",TestingPnL!$O:$O,"HY")*C38+SUMIFS(TestingPnL!$H:$H,TestingPnL!$A:$A,$B$7,TestingPnL!$P:$P,"NA",TestingPnL!$O:$O,"CO")*C38+SUMIFS(TestingPnL!$H:$H,TestingPnL!$A:$A,$B$7,TestingPnL!$P:$P,"EU",TestingPnL!$O:$O,"IG")*E38+SUMIFS(TestingPnL!$H:$H,TestingPnL!$A:$A,$B$7,TestingPnL!$P:$P,"EU",TestingPnL!$O:$O,"CO")*F38 -> -72.840937
A39: =$A20 -> 45303 | B39: =B20-B19 -> 0.25 | C39: =C20-C19 -> 2.5 | D39: =D20-D19 -> -0.38295 | E39: =E20-E19 -> -0.4 | F39: =F20-F19 -> -3.57 | G39: =G20-G19 -> 0.89 | H39: =H20-H19 -> 0.15 | I39: =SUMIFS(TestingPnL!$H:$H,TestingPnL!$A:$A,$B$6,TestingPnL!$P:$P,"NA",TestingPnL!$O:$O,"IG")*B39+SUMIFS(TestingPnL!$H:$H,TestingPnL!$A:$A,$B$6,TestingPnL!$P:$P,"NA",TestingPnL!$O:$O,"HY")*C39+SUMIFS(TestingPnL!$H:$H,TestingPnL!$A:$A,$B$6,TestingPnL!$P:$P,"NA",TestingPnL!$O:$O,"CO")*C39+SUMIFS(TestingPnL!$H:$H,TestingPnL!$A:$A,$B$6,TestingPnL!$P:$P,"EU",TestingPnL!$O:$O,"IG")*E39+SUMIFS(TestingPnL!$H:$H,TestingPnL!$A:$A,$B$6,TestingPnL!$P:$P,"EU",TestingPnL!$O:$O,"CO")*F39 -> -201.59201 | J39: =SUMIFS(TestingPnL!$H:$H,TestingPnL!$A:$A,$B$7,TestingPnL!$P:$P,"NA",TestingPnL!$O:$O,"IG")*B39+SUMIFS(TestingPnL!$H:$H,TestingPnL!$A:$A,$B$7,TestingPnL!$P:$P,"NA",TestingPnL!$O:$O,"HY")*C39+SUMIFS(TestingPnL!$H:$H,TestingPnL!$A:$A,$B$7,TestingPnL!$P:$P,"NA",TestingPnL!$O:$O,"CO")*C39+SUMIFS(TestingPnL!$H:$H,TestingPnL!$A:$A,$B$7,TestingPnL!$P:$P,"EU",TestingPnL!$O:$O,"IG")*E39+SUMIFS(TestingPnL!$H:$H,TestingPnL!$A:$A,$B$7,TestingPnL!$P:$P,"EU",TestingPnL!$O:$O,"CO")*F39 -> 66.858924
A40: =$A21 -> 45306 | B40: =B21-B20 -> 0 | C40: =C21-C20 -> 0 | D40: =D21-D20 -> -0.00257 | E40: =E21-E20 -> 0.84 | F40: =F21-F20 -> 8.04 | G40: =G21-G20 -> 2.53 | H40: =H21-H20 -> 0.99 | I40: =SUMIFS(TestingPnL!$H:$H,TestingPnL!$A:$A,$B$6,TestingPnL!$P:$P,"NA",TestingPnL!$O:$O,"IG")*B40+SUMIFS(TestingPnL!$H:$H,TestingPnL!$A:$A,$B$6,TestingPnL!$P:$P,"NA",TestingPnL!$O:$O,"HY")*C40+SUMIFS(TestingPnL!$H:$H,TestingPnL!$A:$A,$B$6,TestingPnL!$P:$P,"NA",TestingPnL!$O:$O,"CO")*C40+SUMIFS(TestingPnL!$H:$H,TestingPnL!$A:$A,$B$6,TestingPnL!$P:$P,"EU",TestingPnL!$O:$O,"IG")*E40+SUMIFS(TestingPnL!$H:$H,TestingPnL!$A:$A,$B$6,TestingPnL!$P:$P,"EU",TestingPnL!$O:$O,"CO")*F40 -> -748.66836 | J40: =SUMIFS(TestingPnL!$H:$H,TestingPnL!$A:$A,$B$7,TestingPnL!$P:$P,"NA",TestingPnL!$O:$O,"IG")*B40+SUMIFS(TestingPnL!$H:$H,TestingPnL!$A:$A,$B$7,TestingPnL!$P:$P,"NA",TestingPnL!$O:$O,"HY")*C40+SUMIFS(TestingPnL!$H:$H,TestingPnL!$A:$A,$B$7,TestingPnL!$P:$P,"NA",TestingPnL!$O:$O,"CO")*C40+SUMIFS(TestingPnL!$H:$H,TestingPnL!$A:$A,$B$7,TestingPnL!$P:$P,"EU",TestingPnL!$O:$O,"IG")*E40+SUMIFS(TestingPnL!$H:$H,TestingPnL!$A:$A,$B$7,TestingPnL!$P:$P,"EU",TestingPnL!$O:$O,"CO")*F40 -> -442.56922
A42: VAR SUMMARY (99% Confidence, 1-Day, Historical Simulation)
A43: CoB Date | B43: 99% 1-Day VaR (USD)
A44: Jan 15 VaR | B44: =-PERCENTILE(I31:I39,0.01) -> 4636.3157
A45: Jan 16 VaR | B45: =-PERCENTILE(J31:J40,0.01) -> 1819.4308
A47: SECTOR RISK SUMMARY
A48: Index Sector | B48: COB | C48: Total PV01 Spread (USD) | D48: Total PnL (USD)
...

Sheet PnL Vectors
A1: PER-POSITION PnL VECTORS - HISTORICAL SIMULATION | CDS Trading Desk
A2: Each PnL cell = PV01 Spread ($/bp) × historical spread shock (bps). Total PnL = sum across all scenarios. Shocks sourced from TimeSeries tab (same as Risk Report).
A4: CoB: January 15, 2025 | 49 Positions | 9 Historical Scenarios
A5: Position ID | B5: Book | C5: Sector | D5: Region | E5: Mapped TS | F5: PV01 ($) | G5: 45293 | H5: 45294 | I5: 45295 | J5: 45296 | K5: 45299 | L5: 45300 | M5: 45301 | N5: 45302 | O5: 45303 | P5: Total PnL ($)
A6: 2122287473 | B6: EXOTICS NAM adeelq | C6: IG | D6: NA | E6: CDX_IG | F6: -146.5032 | G6: =$F$6*'Risk Report'!$B$31 -> -256.3806 | H6: =$F$6*'Risk Report'!$B$32 -> -293.0064 | I6: =$F$6*'Risk Report'!$B$33 -> 73.251599 | J6: =$F$6*'Risk Report'!$B$34 -> 95.227079 | K6: =$F$6*'Risk Report'!$B$35 -> 358.93284 | L6: =$F$6*'Risk Report'!$B$36 -> 65.926439 | M6: =$F$6*'Risk Report'!$B$37 -> 168.47868 | N6: =$F$6*'Risk Report'!$B$38 -> 117.20256 | O6: =$F$6*'Risk Report'!$B$39 -> -36.625799 | P6: =SUM(G6:O6) -> 293.0064
A7: 2117362004 | B7: EXOTICS NAM painemic | C7: IG | D7: NA | E7: CDX_IG | F7: -109.10121 | G7: =$F$7*'Risk Report'!$B$31 -> -190.92711 | H7: =$F$7*'Risk Report'!$B$32 -> -218.20242 | I7: =$F$7*'Risk Report'!$B$33 -> 54.550604 | J7: =$F$7*'Risk Report'!$B$34 -> 70.915785 | K7: =$F$7*'Risk Report'!$B$35 -> 267.29796 | L7: =$F$7*'Risk Report'!$B$36 -> 49.095544 | M7: =$F$7*'Risk Report'!$B$37 -> 125.46639 | N7: =$F$7*'Risk Report'!$B$38 -> 87.280966 | O7: =$F$7*'Risk Report'!$B$39 -> -27.275302 | P7: =SUM(G7:O7) -> 218.20242
A8: 2119679880 | B8: EXOTICS NAM adeelq | C8: IG | D8: NA | E8: CDX_IG | F8: -43.367568 | G8: =$F$8*'Risk Report'!$B$31 -> -75.893244 | H8: =$F$8*'Risk Report'!$B$32 -> -86.735136 | I8: =$F$8*'Risk Report'!$B$33 -> 21.683784 | J8: =$F$8*'Risk Report'!$B$34 -> 28.188919 | K8: =$F$8*'Risk Report'!$B$35 -> 106.25054 | L8: =$F$8*'Risk Report'!$B$36 -> 19.515406 | M8: =$F$8*'Risk Report'!$B$37 -> 49.872703 | N8: =$F$8*'Risk Report'!$B$38 -> 34.694054 | O8: =$F$8*'Risk Report'!$B$39 -> -10.841892 | P8: =SUM(G8:O8) -> 86.735136
A9: 2118770188 | B9: EXOTICS NAM adeelq | C9: IG | D9: NA | E9: CDX_IG | F9: -43.00736 | G9: =$F$9*'Risk Report'!$B$31 -> -75.26288 | H9: =$F$9*'Risk Report'!$B$32 -> -86.01472 | I9: =$F$9*'Risk Report'!$B$33 -> 21.50368 | J9: =$F$9*'Risk Report'!$B$34 -> 27.954784 | K9: =$F$9*'Risk Report'!$B$35 -> 105.36803 | L9: =$F$9*'Risk Report'!$B$36 -> 19.353312 | M9: =$F$9*'Risk Report'!$B$37 -> 49.458464 | N9: =$F$9*'Risk Report'!$B$38 -> 34.405888 | O9: =$F$9*'Risk Report'!$B$39 -> -10.75184 | P9: =SUM(G9:O9) -> 86.01472
A10: 2122280819 | B10: CONV NAM murmic | C10: IG | D10: EU | E10: ITRX_IG | F10: -36.458521 | G10: =$F$10*'Risk Report'!$E$31 -> -99.167177 | H10: =$F$10*'Risk Report'!$E$32 -> -120.31312 | I10: =$F$10*'Risk Report'!$E$33 -> 26.61472 | J10: =$F$10*'Risk Report'!$E$34 -> -4.7396077 | K10: =$F$10*'Risk Report'!$E$35 -> 40.468958 | L10: =$F$10*'Risk Report'!$E$36 -> 39.739788 | M10: =$F$10*'Risk Report'!$E$37 -> 71.458701 | N10: =$F$10*'Risk Report'!$E$38 -> -32.812669 | O10: =$F$10*'Risk Report'!$E$39 -> 14.583408 | P10: =SUM(G10:O10) -> -64.166997
A11: 2123457722 | B11: EXOTICS EUR boutaoma | C11: HY | D11: NA | E11: CDX_HY | F11: -31.673077 | G11: =$F$11*'Risk Report'!$C$31 -> -237.54808 | H11: =$F$11*'Risk Report'!$C$32 -> -332.56731 | I11: =$F$11*'Risk Report'!$C$33 -> -31.673077 | J11: =$F$11*'Risk Report'!$C$34 -> 158.36539 | K11: =$F$11*'Risk Report'!$C$35 -> 380.07692 | L11: =$F$11*'Risk Report'!$C$36 -> 0 | M11: =$F$11*'Risk Report'!$C$37 -> 174.20192 | N11: =$F$11*'Risk Report'!$C$38 -> 95.019231 | O11: =$F$11*'Risk Report'!$C$39 -> -79.182693 | P11: =SUM(G11:O11) -> 126.69231
A12: 2122891849 | B12: EXOTICS EUR anouark | C12: HY | D12: NA | E12: CDX_HY | F12: -25.953275 | G12: =$F$12*'Risk Report'!$C$31 -> -194.64956 | H12: =$F$12*'Risk Report'!$C$32 -> -272.50939 | I12: =$F$12*'Risk Report'!$C$33 -> -25.953275 | J12: =$F$12*'Risk Report'!$C$34 -> 129.76638 | K12: =$F$12*'Risk Report'!$C$35 -> 311.4393 | L12: =$F$12*'Risk Report'!$C$36 -> 0 | M12: =$F$12*'Risk Report'!$C$37 -> 142.74301 | N12: =$F$12*'Risk Report'!$C$38 -> 77.859825 | O12: =$F$12*'Risk Report'!$C$39 -> -64.883188 | P12: =SUM(G12:O12) -> 103.8131
A13: 507elzc | B13: EQETC | C13: CO | D13: EU | E13: ITRX_XO | F13: -23.716067 | G13: =$F$13*'Risk Report'!$F$31 -> -352.53934 | H13: =$F$13*'Risk Report'!$F$32 -> -423.3318 | I13: =$F$13*'Risk Report'!$F$33 -> 76.365736 | J13: =$F$13*'Risk Report'!$F$34 -> 21.1073 | K13: =$F$13*'Risk Report'!$F$35 -> 120.71478 | L13: =$F$13*'Risk Report'!$F$36 -> 95.57575 | M13: =$F$13*'Risk Report'!$F$37 -> 256.37068 | N13: =$F$13*'Risk Report'!$F$38 -> -142.53356 | O13: =$F$13*'Risk Report'!$F$39 -> 84.666359 | P13: =SUM(G13:O13) -> -263.60408
A14: 54ftedh | B14: EQETC | C14: CO | D14: EU | E14: ITRX_XO | F14: -21.958534 | G14: =$F$14*'Risk Report'!$F$31 -> -326.41361 | H14: =$F$14*'Risk Report'!$F$32 -> -391.95983 | I14: =$F$14*'Risk Report'!$F$33 -> 70.706479 | J14: =$F$14*'Risk Report'!$F$34 -> 19.543095 | K14: =$F$14*'Risk Report'!$F$35 -> 111.76894 | L14: =$F$14*'Risk Report'!$F$36 -> 88.492892 | M14: =$F$14*'Risk Report'!$F$37 -> 237.37175 | N14: =$F$14*'Risk Report'!$F$38 -> -131.97079 | O14: =$F$14*'Risk Report'!$F$39 -> 78.391966 | P14: =SUM(G14:O14) -> -244.06911
A15: 507epfd | B15: EQETC | C15: CO | D15: EU | E15: ITRX_XO | F15: -20.553924 | G15: =$F$15*'Risk Report'!$F$31 -> -305.53408 | H15: =$F$15*'Risk Report'!$F$32 -> -366.88754 | I15: =$F$15*'Risk Report'!$F$33 -> 66.183635 | J15: =$F$15*'Risk Report'!$F$34 -> 18.292992 | K15: =$F$15*'Risk Report'!$F$35 -> 104.61947 | L15: =$F$15*'Risk Report'!$F$36 -> 82.832314 | M15: =$F$15*'Risk Report'!$F$37 -> 222.18792 | N15: =$F$15*'Risk Report'!$F$38 -> -123.52908 | O15: =$F$15*'Risk Report'!$F$39 -> 73.377509 | P15: =SUM(G15:O15) -> -228.45687
A16: 2122435341 | B16: EXOTICS NAM adeelq | C16: IG | D16: NA | E16: CDX_IG | F16: -20.523548 | G16: =$F$16*'Risk Report'!$B$31 -> -35.916209 | H16: =$F$16*'Risk Report'!$B$32 -> -41.047096 | I16: =$F$16*'Risk Report'!$B$33 -> 10.261774 | J16: =$F$16*'Risk Report'!$B$34 -> 13.340306 | K16: =$F$16*'Risk Report'!$B$35 -> 50.282693 | L16: =$F$16*'Risk Report'!$B$36 -> 9.2355966 | M16: =$F$16*'Risk Report'!$B$37 -> 23.60208 | N16: =$F$16*'Risk Report'!$B$38 -> 16.418838 | O16: =$F$16*'Risk Report'!$B$39 -> -5.130887 | P16: =SUM(G16:O16) -> 41.047096
A17: 2121956220 | B17: EXOTICS NAM adeelq | C17: IG | D17: NA | E17: CDX_IG | F17: -19.89338 | G17: =$F$17*'Risk Report'!$B$31 -> -34.813415 | H17: =$F$17*'Risk Report'!$B$32 -> -39.78676 | I17: =$F$17*'Risk Report'!$B$33 -> 9.94669 | J17: =$F$17*'Risk Report'!$B$34 -> 12.930697 | K17: =$F$17*'Risk Report'!$B$35 -> 48.738781 | L17: =$F$17*'Risk Report'!$B$36 -> 8.952021 | M17: =$F$17*'Risk Report'!$B$37 -> 22.877387 | N17: =$F$17*'Risk Report'!$B$38 -> 15.914704 | O17: =$F$17*'Risk Report'!$B$39 -> -4.973345 | P17: =SUM(G17:O17) -> 39.78676
A18: 2123457227 | B18: EXOTICS EUR issamc | C18: HY | D18: NA | E18: CDX_HY | F18: -19.631408 | G18: =$F$18*'Risk Report'!$C$31 -> -147.23556 | H18: =$F$18*'Risk Report'!$C$32 -> -206.12978 | I18: =$F$18*'Risk Report'!$C$33 -> -19.631408 | J18: =$F$18*'Risk Report'!$C$34 -> 98.15704 | K18: =$F$18*'Risk Report'!$C$35 -> 235.5769 | L18: =$F$18*'Risk Report'!$C$36 -> 0 | M18: =$F$18*'Risk Report'!$C$37 -> 107.97274 | N18: =$F$18*'Risk Report'!$C$38 -> 58.894224 | O18: =$F$18*'Risk Report'!$C$39 -> -49.07852 | P18: =SUM(G18:O18) -> 78.525632
A19: 2116682530 | B19: EXOTICS EUR issamc | C19: IG | D19: NA | E19: CDX_IG | F19: -19.559163 | G19: =$F$19*'Risk Report'!$B$31 -> -34.228535 | H19: =$F$19*'Risk Report'!$B$32 -> -39.118326 | I19: =$F$19*'Risk Report'!$B$33 -> 9.7795815 | J19: =$F$19*'Risk Report'!$B$34 -> 12.713456 | K19: =$F$19*'Risk Report'!$B$35 -> 47.919949 | L19: =$F$19*'Risk Report'!$B$36 -> 8.8016233 | M19: =$F$19*'Risk Report'!$B$37 -> 22.493037 | N19: =$F$19*'Risk Report'!$B$38 -> 15.64733 | O19: =$F$19*'Risk Report'!$B$39 -> -4.8897908 | P19: =SUM(G19:O19) -> 39.118326
A20: 2121116022 | B20: CONV NAM murmic | C20: HY | D20: NA | E20: CDX_HY | F20: -16.069766 | G20: =$F$20*'Risk Report'!$C$31 -> -120.52325 | H20: =$F$20*'Risk Report'!$C$32 -> -168.73254 | I20: =$F$20*'Risk Report'!$C$33 -> -16.069766 | J20: =$F$20*'Risk Report'!$C$34 -> 80.34883 | K20: =$F$20*'Risk Report'!$C$35 -> 192.83719 | L20: =$F$20*'Risk Report'!$C$36 -> 0 | M20: =$F$20*'Risk Report'!$C$37 -> 88.383713 | N20: =$F$20*'Risk Report'!$C$38 -> 48.209298 | O20: =$F$20*'Risk Report'!$C$39 -> -40.174415 | P20: =SUM(G20:O20) -> 64.279064
A21: 2122287272 | B21: EXOTICS NAM adeelq | C21: IG | D21: NA | E21: CDX_IG | F21: -14.846822 | G21: =$F$21*'Risk Report'!$B$31 -> -25.981938 | H21: =$F$21*'Risk Report'!$B$32 -> -29.693644 | I21: =$F$21*'Risk Report'!$B$33 -> 7.423411 | J21: =$F$21*'Risk Report'!$B$34 -> 9.6504343 | K21: =$F$21*'Risk Report'!$B$35 -> 36.374714 | L21: =$F$21*'Risk Report'!$B$36 -> 6.6810699 | M21: =$F$21*'Risk Report'!$B$37 -> 17.073845 | N21: =$F$21*'Risk Report'!$B$38 -> 11.877458 | O21: =$F$21*'Risk Report'!$B$39 -> -3.7117055 | P21: =SUM(G21:O21) -> 29.693644
A22: 2118937042 | B22: EXOTICS NAM adeelq | C22: IG | D22: NA | E22: CDX_IG | F22: -14.445735 | G22: =$F$22*'Risk Report'!$B$31 -> -25.280036 | H22: =$F$22*'Risk Report'!$B$32 -> -28.89147 | I22: =$F$22*'Risk Report'!$B$33 -> 7.2228675 | J22: =$F$22*'Risk Report'!$B$34 -> 9.3897277 | K22: =$F$22*'Risk Report'!$B$35 -> 35.392051 | L22: =$F$22*'Risk Report'!$B$36 -> 6.5005807 | M22: =$F$22*'Risk Report'!$B$37 -> 16.612595 | N22: =$F$22*'Risk Report'!$B$38 -> 11.556588 | O22: =$F$22*'Risk Report'!$B$39 -> -3.6114338 | P22: =SUM(G22:O22) -> 28.89147
A23: 2124173755 | B23: EXOTICS NAM adeelq | C23: IG | D23: NA | E23: CDX_IG | F23: -14.410151 | G23: =$F$23*'Risk Report'!$B$31 -> -25.217764 | H23: =$F$23*'Risk Report'!$B$32 -> -28.820302 | I23: =$F$23*'Risk Report'!$B$33 -> 7.2050755 | J23: =$F$23*'Risk Report'!$B$34 -> 9.3665981 | K23: =$F$23*'Risk Report'!$B$35 -> 35.30487 | L23: =$F$23*'Risk Report'!$B$36 -> 6.4845679 | M23: =$F$23*'Risk Report'!$B$37 -> 16.571674 | N23: =$F$23*'Risk Report'!$B$38 -> 11.528121 | O23: =$F$23*'Risk Report'!$B$39 -> -3.6025378 | P23: =SUM(G23:O23) -> 28.820302
A24: 2122542214 | B24: EXOTICS EUR issamc | C24: IG | D24: NA | E24: CDX_IG | F24: -13.994548 | G24: =$F$24*'Risk Report'!$B$31 -> -24.490459 | H24: =$F$24*'Risk Report'!$B$32 -> -27.989096 | I24: =$F$24*'Risk Report'!$B$33 -> 6.997274 | J24: =$F$24*'Risk Report'!$B$34 -> 9.0964562 | K24: =$F$24*'Risk Report'!$B$35 -> 34.286643 | L24: =$F$24*'Risk Report'!$B$36 -> 6.2975466 | M24: =$F$24*'Risk Report'!$B$37 -> 16.09373 | N24: =$F$24*'Risk Report'!$B$38 -> 11.195638 | O24: =$F$24*'Risk Report'!$B$39 -> -3.498637 | P24: =SUM(G24:O24) -> 27.989096
A25: 2122893484 | B25: EXOTICS EUR boutaoma | C25: IG | D25: NA | E25: CDX_IG | F25: -13.724138 | G25: =$F$25*'Risk Report'!$B$31 -> -24.017242 | H25: =$F$25*'Risk Report'!$B$32 -> -27.448276 | I25: =$F$25*'Risk Report'!$B$33 -> 6.862069 | J25: =$F$25*'Risk Report'!$B$34 -> 8.9206897 | K25: =$F$25*'Risk Report'!$B$35 -> 33.624138 | L25: =$F$25*'Risk Report'!$B$36 -> 6.1758621 | M25: =$F$25*'Risk Report'!$B$37 -> 15.782759 | N25: =$F$25*'Risk Report'!$B$38 -> 10.97931 | O25: =$F$25*'Risk Report'!$B$39 -> -3.4310345 | P25: =SUM(G25:O25) -> 27.448276
A26: 54fx7h8 | B26: EQCOP | C26: CO | D26: EU | E26: ITRX_XO | F26: -13.67009 | G26: =$F$26*'Risk Report'!$F$31 -> -203.20589 | H26: =$F$26*'Risk Report'!$F$32 -> -244.01111 | I26: =$F$26*'Risk Report'!$F$33 -> 44.01769 | J26: =$F$26*'Risk Report'!$F$34 -> 12.16638 | K26: =$F$26*'Risk Report'!$F$35 -> 69.580758 | L26: =$F$26*'Risk Report'!$F$36 -> 55.090463 | M26: =$F$26*'Risk Report'!$F$37 -> 147.77367 | N26: =$F$26*'Risk Report'!$F$38 -> -82.157241 | O26: =$F$26*'Risk Report'!$F$39 -> 48.802221 | P26: =SUM(G26:O26) -> -151.94305
A27: 2122015535 | B27: EXOTICS NAM adeelq | C27: IG | D27: NA | E27: CDX_IG | F27: -13.527498 | G27: =$F$27*'Risk Report'!$B$31 -> -23.673122 | H27: =$F$27*'Risk Report'!$B$32 -> -27.054996 | I27: =$F$27*'Risk Report'!$B$33 -> 6.763749 | J27: =$F$27*'Risk Report'!$B$34 -> 8.7928737 | K27: =$F$27*'Risk Report'!$B$35 -> 33.14237 | L27: =$F$27*'Risk Report'!$B$36 -> 6.0873741 | M27: =$F$27*'Risk Report'!$B$37 -> 15.556623 | N27: =$F$27*'Risk Report'!$B$38 -> 10.821998 | O27: =$F$27*'Risk Report'!$B$39 -> -3.3818745 | P27: =SUM(G27:O27) -> 27.054996
A28: 2122542210 | B28: EXOTICS EUR issamc | C28: IG | D28: EU | E28: ITRX_IG | F28: -13.300264 | G28: =$F$28*'Risk Report'!$E$31 -> -36.176718 | H28: =$F$28*'Risk Report'!$E$32 -> -43.890871 | I28: =$F$28*'Risk Report'!$E$33 -> 9.7091927 | J28: =$F$28*'Risk Report'!$E$34 -> -1.7290343 | K28: =$F$28*'Risk Report'!$E$35 -> 14.763293 | L28: =$F$28*'Risk Report'!$E$36 -> 14.497288 | M28: =$F$28*'Risk Report'!$E$37 -> 26.068517 | N28: =$F$28*'Risk Report'!$E$38 -> -11.970238 | O28: =$F$28*'Risk Report'!$E$39 -> 5.3201056 | P28: =SUM(G28:O28) -> -23.408465
A29: 2114902387 | B29: EXOTICS EUR issamc | C29: IG | D29: NA | E29: CDX_IG | F29: -12.768633 | G29: =$F$29*'Risk Report'!$B$31 -> -22.345108 | H29: =$F$29*'Risk Report'!$B$32 -> -25.537266 | I29: =$F$29*'Risk Report'!$B$33 -> 6.3843165 | J29: =$F$29*'Risk Report'!$B$34 -> 8.2996114 | K29: =$F$29*'Risk Report'!$B$35 -> 31.283151 | L29: =$F$29*'Risk Report'!$B$36 -> 5.7458848 | M29: =$F$29*'Risk Report'!$B$37 -> 14.683928 | N29: =$F$29*'Risk Report'!$B$38 -> 10.214906 | O29: =$F$29*'Risk Report'!$B$39 -> -3.1921582 | P29: =SUM(G29:O29) -> 25.537266
A30: 2123984227 | B30: EXOTICS EUR issamc | C30: HY | D30: NA | E30: CDX_HY | F30: -12.766484 | G30: =$F$30*'Risk Report'!$C$31 -> -95.74863 | H30: =$F$30*'Risk Report'!$C$32 -> -134.04808 | I30: =$F$30*'Risk Report'!$C$33 -> -12.766484 | J30: =$F$30*'Risk Report'!$C$34 -> 63.83242 | K30: =$F$30*'Risk Report'!$C$35 -> 153.19781 | L30: =$F$30*'Risk Report'!$C$36 -> 0 | M30: =$F$30*'Risk Report'!$C$37 -> 70.215662 | N30: =$F$30*'Risk Report'!$C$38 -> 38.299452 | O30: =$F$30*'Risk Report'!$C$39 -> -31.91621 | P30: =SUM(G30:O30) -> 51.065936
A31: 2119096050 | B31: CONV NAM murmic | C31: HY | D31: NA | E31: CDX_HY | F31: -12.727713 | G31: =$F$31*'Risk Report'!$C$31 -> -95.457847 | H31: =$F$31*'Risk Report'!$C$32 -> -133.64099 | I31: =$F$31*'Risk Report'!$C$33 -> -12.727713 | J31: =$F$31*'Risk Report'!$C$34 -> 63.638565 | K31: =$F$31*'Risk Report'!$C$35 -> 152.73256 | L31: =$F$31*'Risk Report'!$C$36 -> 0 | M31: =$F$31*'Risk Report'!$C$37 -> 70.002421 | N31: =$F$31*'Risk Report'!$C$38 -> 38.183139 | O31: =$F$31*'Risk Report'!$C$39 -> -31.819282 | P31: =SUM(G31:O31) -> 50.910852
A32: 218726570 | B32: EXOTICS EUR issamc | C32: IG | D32: NA | E32: CDX_IG | F32: -12.533436 | G32: =$F$32*'Risk Report'!$B$31 -> -21.933513 | H32: =$F$32*'Risk Report'!$B$32 -> -25.066872 | I32: =$F$32*'Risk Report'!$B$33 -> 6.266718 | J32: =$F$32*'Risk Report'!$B$34 -> 8.1467334 | K32: =$F$32*'Risk Report'!$B$35 -> 30.706918 | L32: =$F$32*'Risk Report'!$B$36 -> 5.6400462 | M32: =$F$32*'Risk Report'!$B$37 -> 14.413451 | N32: =$F$32*'Risk Report'!$B$38 -> 10.026749 | O32: =$F$32*'Risk Report'!$B$39 -> -3.133359 | P32: =SUM(G32:O32) -> 25.066872
A33: 2122382254 | B33: CONV NAM murmic | C33: HY | D33: NA | E33: CDX_HY | F33: -12.480352 | G33: =$F$33*'Risk Report'!$C$31 -> -93.60264 | H33: =$F$33*'Risk Report'!$C$32 -> -131.0437 | I33: =$F$33*'Risk Report'!$C$33 -> -12.480352 | J33: =$F$33*'Risk Report'!$C$34 -> 62.40176 | K33: =$F$33*'Risk Report'!$C$35 -> 149.76422 | L33: =$F$33*'Risk Report'!$C$36 -> 0 | M33: =$F$33*'Risk Report'!$C$37 -> 68.641936 | N33: =$F$33*'Risk Report'!$C$38 -> 37.441056 | O33: =$F$33*'Risk Report'!$C$39 -> -31.20088 | P33: =SUM(G33:O33) -> 49.921408
A34: 2122893482 | B34: EXOTICS EUR boutaoma | C34: IG | D34: EU | E34: ITRX_IG | F34: -12.227057 | G34: =$F$34*'Risk Report'!$E$31 -> -33.257595 | H34: =$F$34*'Risk Report'!$E$32 -> -40.349288 | I34: =$F$34*'Risk Report'!$E$33 -> 8.9257516 | J34: =$F$34*'Risk Report'!$E$34 -> -1.5895174 | K34: =$F$34*'Risk Report'!$E$35 -> 13.572033 | L34: =$F$34*'Risk Report'!$E$36 -> 13.327492 | M34: =$F$34*'Risk Report'!$E$37 -> 23.965032 | N34: =$F$34*'Risk Report'!$E$38 -> -11.004351 | O34: =$F$34*'Risk Report'!$E$39 -> 4.8908228 | P34: =SUM(G34:O34) -> -21.51962
A35: 216229993 | B35: EXOTICS EUR boutaoma | C35: IG | D35: EU | E35: ITRX_IG | F35: -12.324176 | G35: =$F$35*'Risk Report'!$E$31 -> -33.521759 | H35: =$F$35*'Risk Report'!$E$32 -> -40.669781 | I35: =$F$35*'Risk Report'!$E$33 -> 8.9966485 | J35: =$F$35*'Risk Report'!$E$34 -> -1.6021429 | K35: =$F$35*'Risk Report'!$E$35 -> 13.679835 | L35: =$F$35*'Risk Report'!$E$36 -> 13.433352 | M35: =$F$35*'Risk Report'!$E$37 -> 24.155385 | N35: =$F$35*'Risk Report'!$E$38 -> -11.091758 | O35: =$F$35*'Risk Report'!$E$39 -> 4.9296704 | P35: =SUM(G35:O35) -> -21.69055
A36: 2114902381 | B36: EXOTICS EUR issamc | C36: IG | D36: NA | E36: CDX_IG | F36: -12.234236 | G36: =$F$36*'Risk Report'!$B$31 -> -21.409913 | H36: =$F$36*'Risk Report'!$B$32 -> -24.468472 | I36: =$F$36*'Risk Report'!$B$33 -> 6.117118 | J36: =$F$36*'Risk Report'!$B$34 -> 7.9522534 | K36: =$F$36*'Risk Report'!$B$35 -> 29.973878 | L36: =$F$36*'Risk Report'!$B$36 -> 5.5054062 | M36: =$F$36*'Risk Report'!$B$37 -> 14.069371 | N36: =$F$36*'Risk Report'!$B$38 -> 9.7873888 | O36: =$F$36*'Risk Report'!$B$39 -> -3.058559 | P36: =SUM(G36:O36) -> 24.468472
